Workbook

Sheet Sheet1
A1: RA6 | B1: code | C1: Sex | D1: FY | E1: unitid | F1: University | G1: Gender | H1: Sport | I1: VariableRev | J1: RealVariableRev | K1: Covid | L1: SupportStaffSalary | M1: RealSupportStaffSalary
A2: 2 | B2: =IF(ISBLANK(G2),"",VLOOKUP(H2,code!B:C,2,FALSE)) -> 1 | C2: =IF(ISBLANK(G2),"",IF(MID(G2,1,1)="M",0,1)) -> 0 | D2: 2017 | E2: 104179 | F2: Arizona | G2: Male | H2: Baseball | I2: 562609 | J2: =I2/VLOOKUP($D2,CPI!$P$16:$R$22,3,FALSE) -> 694833.06 | K2: =IF(ISBLANK(G2),"",IF(D2=2021,1,0)) -> 0 | L2: 0 | M2: =L2/VLOOKUP($D2,CPI!$P$16:$R$22,3,FALSE) -> 0
A3: 2 | B3: =IF(ISBLANK(G3),"",VLOOKUP(H3,code!B:C,2,FALSE)) -> 2 | C3: =IF(ISBLANK(G3),"",IF(MID(G3,1,1)="M",0,1)) -> 0 | D3: 2017 | E3: 104179 | F3: Arizona | G3: Male | H3: Basketball | I3: 13307798 | J3: =I3/VLOOKUP($D3,CPI!$P$16:$R$22,3,FALSE) -> 16435390 | K3: =IF(ISBLANK(G3),"",IF(D3=2021,1,0)) -> 0 | L3: {=IF($C3=0,INDEX('24&25'!$L:$L,MATCH($D3&$B3&$E3,'24&25'!$B:$B&'24&25'!$A:$A&'24&25'!$C:$C,0)),INDEX('24&25'!$M:$M,MATCH($D3&$B3&$E3,'24&25'!$B:$B&'24&25'!$A:$A&'24&25'!$C:$C,0)))} -> 373154 | M3: =L3/VLOOKUP($D3,CPI!$P$16:$R$22,3,FALSE) -> 460852.45
A4: 2 | B4: =IF(ISBLANK(G4),"",VLOOKUP(H4,code!B:C,2,FALSE)) -> 8 | C4: =IF(ISBLANK(G4),"",IF(MID(G4,1,1)="M",0,1)) -> 0 | D4: 2017 | E4: 104179 | F4: Arizona | G4: Male | H4: Football | I4: 13296917 | J4: =I4/VLOOKUP($D4,CPI!$P$16:$R$22,3,FALSE) -> 16421951 | K4: =IF(ISBLANK(G4),"",IF(D4=2021,1,0)) -> 0 | L4: {=IF($C4=0,INDEX('24&25'!$L:$L,MATCH($D4&$B4&$E4,'24&25'!$B:$B&'24&25'!$A:$A&'24&25'!$C:$C,0)),INDEX('24&25'!$M:$M,MATCH($D4&$B4&$E4,'24&25'!$B:$B&'24&25'!$A:$A&'24&25'!$C:$C,0)))} -> 1309151 | M4: =L4/VLOOKUP($D4,CPI!$P$16:$R$22,3,FALSE) -> 1616827
A5: 2 | B5: =IF(ISBLANK(G5),"",VLOOKUP(H5,code!B:C,2,FALSE)) -> 9 | C5: =IF(ISBLANK(G5),"",IF(MID(G5,1,1)="M",0,1)) -> 0 | D5: 2017 | E5: 104179 | F5: Arizona | G5: Male | H5: Golf | I5: 65850 | J5: =I5/VLOOKUP($D5,CPI!$P$16:$R$22,3,FALSE) -> 81326.032 | K5: =IF(ISBLANK(G5),"",IF(D5=2021,1,0)) -> 0 | L5: {=IF($C5=0,INDEX('24&25'!$L:$L,MATCH($D5&$B5&$E5,'24&25'!$B:$B&'24&25'!$A:$A&'24&25'!$C:$C,0)),INDEX('24&25'!$M:$M,MATCH($D5&$B5&$E5,'24&25'!$B:$B&'24&25'!$A:$A&'24&25'!$C:$C,0)))} -> 0 | M5: =L5/VLOOKUP($D5,CPI!$P$16:$R$22,3,FALSE) -> 0
A6: 2 | B6: =IF(ISBLANK(G6),"",VLOOKUP(H6,code!B:C,2,FALSE)) -> 19 | C6: =IF(ISBLANK(G6),"",IF(MID(G6,1,1)="M",0,1)) -> 0 | D6: 2017 | E6: 104179 | F6: Arizona | G6: Male | H6: Swimming and Diving | I6: 12305 | J6: =I6/VLOOKUP($D6,CPI!$P$16:$R$22,3,FALSE) -> 15196.914 | K6: =IF(ISBLANK(G6),"",IF(D6=2021,1,0)) -> 0 | L6: {=IF($C6=0,INDEX('24&25'!$L:$L,MATCH($D6&$B6&$E6,'24&25'!$B:$B&'24&25'!$A:$A&'24&25'!$C:$C,0)),INDEX('24&25'!$M:$M,MATCH($D6&$B6&$E6,'24&25'!$B:$B&'24&25'!$A:$A&'24&25'!$C:$C,0)))} -> 45379 | M6: =L6/VLOOKUP($D6,CPI!$P$16:$R$22,3,FALSE) -> 56043.948
A7: 2 | B7: =IF(ISBLANK(G7),"",VLOOKUP(H7,code!B:C,2,FALSE)) -> 20 | C7: =IF(ISBLANK(G7),"",IF(MID(G7,1,1)="M",0,1)) -> 0 | D7: 2017 | E7: 104179 | F7: Arizona | G7: Male | H7: Tennis | I7: 4156 | J7: =I7/VLOOKUP($D7,CPI!$P$16:$R$22,3,FALSE) -> 5132.7409 | K7: =IF(ISBLANK(G7),"",IF(D7=2021,1,0)) -> 0 | L7: {=IF($C7=0,INDEX('24&25'!$L:$L,MATCH($D7&$B7&$E7,'24&25'!$B:$B&'24&25'!$A:$A&'24&25'!$C:$C,0)),INDEX('24&25'!$M:$M,MATCH($D7&$B7&$E7,'24&25'!$B:$B&'24&25'!$A:$A&'24&25'!$C:$C,0)))} -> 0 | M7: =L7/VLOOKUP($D7,CPI!$P$16:$R$22,3,FALSE) -> 0
A8: 2 | B8: =IF(ISBLANK(G8),"",VLOOKUP(H8,code!B:C,2,FALSE)) -> 21 | C8: =IF(ISBLANK(G8),"",IF(MID(G8,1,1)="M",0,1)) -> 0 | D8: 2017 | E8: 104179 | F8: Arizona | G8: Male | H8: Track and Field, X-Country | I8: 37079 | J8: =I8/VLOOKUP($D8,CPI!$P$16:$R$22,3,FALSE) -> 45793.287 | K8: =IF(ISBLANK(G8),"",IF(D8=2021,1,0)) -> 0 | L8: {=IF($C8=0,INDEX('24&25'!$L:$L,MATCH($D8&$B8&$E8,'24&25'!$B:$B&'24&25'!$A:$A&'24&25'!$C:$C,0)),INDEX('24&25'!$M:$M,MATCH($D8&$B8&$E8,'24&25'!$B:$B&'24&25'!$A:$A&'24&25'!$C:$C,0)))} -> 41582 | M8: =L8/VLOOKUP($D8,CPI!$P$16:$R$22,3,FALSE) -> 51354.579
A9: 2 | B9: =IF(ISBLANK(G9),"",VLOOKUP(H9,code!B:C,2,FALSE)) -> 2 | C9: =IF(ISBLANK(G9),"",IF(MID(G9,1,1)="M",0,1)) -> 1 | D9: 2017 | E9: 104179 | F9: Arizona | G9: Female | H9: Basketball | I9: 131114 | J9: =I9/VLOOKUP($D9,CPI!$P$16:$R$22,3,FALSE) -> 161928.34 | K9: =IF(ISBLANK(G9),"",IF(D9=2021,1,0)) -> 0 | L9: {=IF($C9=0,INDEX('24&25'!$L:$L,MATCH($D9&$B9&$E9,'24&25'!$B:$B&'24&25'!$A:$A&'24&25'!$C:$C,0)),INDEX('24&25'!$M:$M,MATCH($D9&$B9&$E9,'24&25'!$B:$B&'24&25'!$A:$A&'24&25'!$C:$C,0)))} -> 193255 | M9: =L9/VLOOKUP($D9,CPI!$P$16:$R$22,3,FALSE) -> 238673.69
A10: 2 | B10: =IF(ISBLANK(G10),"",VLOOKUP(H10,code!B:C,2,FALSE)) -> 3 | C10: =IF(ISBLANK(G10),"",IF(MID(G10,1,1)="M",0,1)) -> 1 | D10: 2017 | E10: 104179 | F10: Arizona | G10: Female | H10: Beach Volleyball | I10: 1375 | J10: =I10/VLOOKUP($D10,CPI!$P$16:$R$22,3,FALSE) -> 1698.1518 | K10: =IF(ISBLANK(G10),"",IF(D10=2021,1,0)) -> 0 | L10: {=IF($C10=0,INDEX('24&25'!$L:$L,MATCH($D10&$B10&$E10,'24&25'!$B:$B&'24&25'!$A:$A&'24&25'!$C:$C,0)),INDEX('24&25'!$M:$M,MATCH($D10&$B10&$E10,'24&25'!$B:$B&'24&25'!$A:$A&'24&25'!$C:$C,0)))} -> 0 | M10: =L10/VLOOKUP($D10,CPI!$P$16:$R$22,3,FALSE) -> 0
A11: 2 | B11: =IF(ISBLANK(G11),"",VLOOKUP(H11,code!B:C,2,FALSE)) -> 9 | C11: =IF(ISBLANK(G11),"",IF(MID(G11,1,1)="M",0,1)) -> 1 | D11: 2017 | E11: 104179 | F11: Arizona | G11: Female | H11: Golf | I11: 18619 | J11: =I11/VLOOKUP($D11,CPI!$P$16:$R$22,3,FALSE) -> 22994.827 | K11: =IF(ISBLANK(G11),"",IF(D11=2021,1,0)) -> 0 | L11: {=IF($C11=0,INDEX('24&25'!$L:$L,MATCH($D11&$B11&$E11,'24&25'!$B:$B&'24&25'!$A:$A&'24&25'!$C:$C,0)),INDEX('24&25'!$M:$M,MATCH($D11&$B11&$E11,'24&25'!$B:$B&'24&25'!$A:$A&'24&25'!$C:$C,0)))} -> 0 | M11: =L11/VLOOKUP($D11,CPI!$P$16:$R$22,3,FALSE) -> 0
A12: 2 | B12: =IF(ISBLANK(G12),"",VLOOKUP(H12,code!B:C,2,FALSE)) -> 10 | C12: =IF(ISBLANK(G12),"",IF(MID(G12,1,1)="M",0,1)) -> 1 | D12: 2017 | E12: 104179 | F12: Arizona | G12: Female | H12: Gymnastics | I12: 63685 | J12: =I12/VLOOKUP($D12,CPI!$P$16:$R$22,3,FALSE) -> 78652.214 | K12: =IF(ISBLANK(G12),"",IF(D12=2021,1,0)) -> 0 | L12: {=IF($C12=0,INDEX('24&25'!$L:$L,MATCH($D12&$B12&$E12,'24&25'!$B:$B&'24&25'!$A:$A&'24&25'!$C:$C,0)),INDEX('24&25'!$M:$M,MATCH($D12&$B12&$E12,'24&25'!$B:$B&'24&25'!$A:$A&'24&25'!$C:$C,0)))} -> 0 | M12: =L12/VLOOKUP($D12,CPI!$P$16:$R$22,3,FALSE) -> 0
A13: 2 | B13: =IF(ISBLANK(G13),"",VLOOKUP(H13,code!B:C,2,FALSE)) -> 17 | C13: =IF(ISBLANK(G13),"",IF(MID(G13,1,1)="M",0,1)) -> 1 | D13: 2017 | E13: 104179 | F13: Arizona | G13: Female | H13: Soccer | I13: 46581 | J13: =I13/VLOOKUP($D13,CPI!$P$16:$R$22,3,FALSE) -> 57528.442 | K13: =IF(ISBLANK(G13),"",IF(D13=2021,1,0)) -> 0 | L13: {=IF($C13=0,INDEX('24&25'!$L:$L,MATCH($D13&$B13&$E13,'24&25'!$B:$B&'24&25'!$A:$A&'24&25'!$C:$C,0)),INDEX('24&25'!$M:$M,MATCH($D13&$B13&$E13,'24&25'!$B:$B&'24&25'!$A:$A&'24&25'!$C:$C,0)))} -> 0 | M13: =L13/VLOOKUP($D13,CPI!$P$16:$R$22,3,FALSE) -> 0
A14: 2 | B14: =IF(ISBLANK(G14),"",VLOOKUP(H14,code!B:C,2,FALSE)) -> 18 | C14: =IF(ISBLANK(G14),"",IF(MID(G14,1,1)="M",0,1)) -> 1 | D14: 2017 | E14: 104179 | F14: Arizona | G14: Female | H14: Softball | I14: 439507 | J14: =I14/VLOOKUP($D14,CPI!$P$16:$R$22,3,FALSE) -> 542799.7 | K14: =IF(ISBLANK(G14),"",IF(D14=2021,1,0)) -> 0 | L14: {=IF($C14=0,INDEX('24&25'!$L:$L,MATCH($D14&$B14&$E14,'24&25'!$B:$B&'24&25'!$A:$A&'24&25'!$C:$C,0)),INDEX('24&25'!$M:$M,MATCH($D14&$B14&$E14,'24&25'!$B:$B&'24&25'!$A:$A&'24&25'!$C:$C,0)))} -> 7422 | M14: =L14/VLOOKUP($D14,CPI!$P$16:$R$22,3,FALSE) -> 9166.3144
... A72: 2 | B72: =IF(ISBLANK(G72),"",VLOOKUP(H72,code!B:C,2,FALSE)) -> 8 | C72: =IF(ISBLANK(G72),"",IF(MID(G72,1,1)="M",0,1)) -> 0 | D72: 2021 | E72: 104179 | F72: Arizona | G72: Male | H72: Football | I72: 1391524 | J72: =I72/VLOOKUP($D72,CPI!$P$16:$R$22,3,FALSE) -> 1584718.9 | K72: =IF(ISBLANK(G72),"",IF(D72=2021,1,0)) -> 1 | L72: {=IF($C72=0,INDEX('24&25'!$L:$L,MATCH($D72&$B72&$E72,'24&25'!$B:$B&'24&25'!$A:$A&'24&25'!$C:$C,0)),INDEX('24&25'!$M:$M,MATCH($D72&$B72&$E72,'24&25'!$B:$B&'24&25'!$A:$A&'24&25'!$C:$C,0)))} -> 2372160 | M72: =L72/VLOOKUP($D72,CPI!$P$16:$R$22,3,FALSE) -> 2701503.3
A73: 2 | B73: 9 | C73: =IF(ISBLANK(G73),"",IF(MID(G73,1,1)="M",0,1)) -> 0 | D73: 2021 | E73: 104179 | F73: Arizona | G73: Male | H73: Golf | I73: 88385 | J73: =I73/VLOOKUP($D73,CPI!$P$16:$R$22,3,FALSE) -> 100656.1 | K73: =IF(ISBLANK(G73),"",IF(D73=2021,1,0)) -> 1 | L73: {=IF($C73=0,INDEX('24&25'!$L:$L,MATCH($D73&$B73&$E73,'24&25'!$B:$B&'24&25'!$A:$A&'24&25'!$C:$C,0)),INDEX('24&25'!$M:$M,MATCH($D73&$B73&$E73,'24&25'!$B:$B&'24&25'!$A:$A&'24&25'!$C:$C,0)))} -> 0 | M73: =L73/VLOOKUP($D73,CPI!$P$16:$R$22,3,FALSE) -> 0
A74: 2 | B74: 19 | C74: =IF(ISBLANK(G74),"",IF(MID(G74,1,1)="M",0,1)) -> 0 | D74: 2021 | E74: 104179 | F74: Arizona | G74: Male | H74: Swimming and diving | I74: 11447 | J74: =I74/VLOOKUP($D74,CPI!$P$16:$R$22,3,FALSE) -> 13036.266 | K74: =IF(ISBLANK(G74),"",IF(D74=2021,1,0)) -> 1 | L74: {=IF($C74=0,INDEX('24&25'!$L:$L,MATCH($D74&$B74&$E74,'24&25'!$B:$B&'24&25'!$A:$A&'24&25'!$C:$C,0)),INDEX('24&25'!$M:$M,MATCH($D74&$B74&$E74,'24&25'!$B:$B&'24&25'!$A:$A&'24&25'!$C:$C,0)))} -> 29242 | M74: =L74/VLOOKUP($D74,CPI!$P$16:$R$22,3,FALSE) -> 33301.869
A75: 2 | B75: =IF(ISBLANK(G75),"",VLOOKUP(H75,code!B:C,2,FALSE)) -> 20 | C75: =IF(ISBLANK(G75),"",IF(MID(G75,1,1)="M",0,1)) -> 0 | D75: 2021 | E75: 104179 | F75: Arizona | G75: Male | H75: Tennis | I75: 33682 | J75: =I75/VLOOKUP($D75,CPI!$P$16:$R$22,3,FALSE) -> 38358.305 | K75: =IF(ISBLANK(G75),"",IF(D75=2021,1,0)) -> 1 | L75: {=IF($C75=0,INDEX('24&25'!$L:$L,MATCH($D75&$B75&$E75,'24&25'!$B:$B&'24&25'!$A:$A&'24&25'!$C:$C,0)),INDEX('24&25'!$M:$M,MATCH($D75&$B75&$E75,'24&25'!$B:$B&'24&25'!$A:$A&'24&25'!$C:$C,0)))} -> 0 | M75: =L75/VLOOKUP($D75,CPI!$P$16:$R$22,3,FALSE) -> 0
A76: 2 | B76: 21 | C76: =IF(ISBLANK(G76),"",IF(MID(G76,1,1)="M",0,1)) -> 0 | D76: 2021 | E76: 104179 | F76: Arizona | G76: Male | H76: Track and Field , X country | I76: 79629 | J76: =I76/VLOOKUP($D76,CPI!$P$16:$R$22,3,FALSE) -> 90684.444 | K76: =IF(ISBLANK(G76),"",IF(D76=2021,1,0)) -> 1 | L76: {=IF($C76=0,INDEX('24&25'!$L:$L,MATCH($D76&$B76&$E76,'24&25'!$B:$B&'24&25'!$A:$A&'24&25'!$C:$C,0)),INDEX('24&25'!$M:$M,MATCH($D76&$B76&$E76,'24&25'!$B:$B&'24&25'!$A:$A&'24&25'!$C:$C,0)))} -> 34677 | M76: =L76/VLOOKUP($D76,CPI!$P$16:$R$22,3,FALSE) -> 39491.447
A77: 2 | B77: =IF(ISBLANK(G77),"",VLOOKUP(H77,code!B:C,2,FALSE)) -> 2 | C77: =IF(ISBLANK(G77),"",IF(MID(G77,1,1)="M",0,1)) -> 1 | D77: 2021 | E77: 104179 | F77: Arizona | G77: Women | H77: Basketball | I77: 242848 | J77: =I77/VLOOKUP($D77,CPI!$P$16:$R$22,3,FALSE) -> 276564.26 | K77: =IF(ISBLANK(G77),"",IF(D77=2021,1,0)) -> 1 | L77: {=IF($C77=0,INDEX('24&25'!$L:$L,MATCH($D77&$B77&$E77,'24&25'!$B:$B&'24&25'!$A:$A&'24&25'!$C:$C,0)),INDEX('24&25'!$M:$M,MATCH($D77&$B77&$E77,'24&25'!$B:$B&'24&25'!$A:$A&'24&25'!$C:$C,0)))} -> 304167 | M77: =L77/VLOOKUP($D77,CPI!$P$16:$R$22,3,FALSE) -> 346396.6
A78: 2 | B78: 3 | C78: =IF(ISBLANK(G78),"",IF(MID(G78,1,1)="M",0,1)) -> 1 | D78: 2021 | E78: 104179 | F78: Arizona | G78: Women | H78: Beach Volleyball | I78: 4574 | J78: =I78/VLOOKUP($D78,CPI!$P$16:$R$22,3,FALSE) -> 5209.04 | K78: =IF(ISBLANK(G78),"",IF(D78=2021,1,0)) -> 1 | L78: {=IF($C78=0,INDEX('24&25'!$L:$L,MATCH($D78&$B78&$E78,'24&25'!$B:$B&'24&25'!$A:$A&'24&25'!$C:$C,0)),INDEX('24&25'!$M:$M,MATCH($D78&$B78&$E78,'24&25'!$B:$B&'24&25'!$A:$A&'24&25'!$C:$C,0)))} -> 25758 | M78: =L78/VLOOKUP($D78,CPI!$P$16:$R$22,3,FALSE) -> 29334.161
A79: 2 | B79: 9 | C79: =IF(ISBLANK(G79),"",IF(MID(G79,1,1)="M",0,1)) -> 1 | D79: 2021 | E79: 104179 | F79: Arizona | G79: Women | H79: Golf | I79: 105107 | J79: =I79/VLOOKUP($D79,CPI!$P$16:$R$22,3,FALSE) -> 119699.73 | K79: =IF(ISBLANK(G79),"",IF(D79=2021,1,0)) -> 1 | L79: {=IF($C79=0,INDEX('24&25'!$L:$L,MATCH($D79&$B79&$E79,'24&25'!$B:$B&'24&25'!$A:$A&'24&25'!$C:$C,0)),INDEX('24&25'!$M:$M,MATCH($D79&$B79&$E79,'24&25'!$B:$B&'24&25'!$A:$A&'24&25'!$C:$C,0)))} -> 0 | M79: =L79/VLOOKUP($D79,CPI!$P$16:$R$22,3,FALSE) -> 0
A80: 2 | B80: =IF(ISBLANK(G80),"",VLOOKUP(H80,code!B:C,2,FALSE)) -> 10 | C80: =IF(ISBLANK(G80),"",IF(MID(G80,1,1)="M",0,1)) -> 1 | D80: 2021 | E80: 104179 | F80: Arizona | G80: Women | H80: Gymnastics | I80: 1200 | J80: =I80/VLOOKUP($D80,CPI!$P$16:$R$22,3,FALSE) -> 1366.6043 | K80: =IF(ISBLANK(G80),"",IF(D80=2021,1,0)) -> 1 | L80: {=IF($C80=0,INDEX('24&25'!$L:$L,MATCH($D80&$B80&$E80,'24&25'!$B:$B&'24&25'!$A:$A&'24&25'!$C:$C,0)),INDEX('24&25'!$M:$M,MATCH($D80&$B80&$E80,'24&25'!$B:$B&'24&25'!$A:$A&'24&25'!$C:$C,0)))} -> 33930 | M80: =L80/VLOOKUP($D80,CPI!$P$16:$R$22,3,FALSE) -> 38640.736
A81: 2 | B81: =IF(ISBLANK(G81),"",VLOOKUP(H81,code!B:C,2,FALSE)) -> 17 | C81: =IF(ISBLANK(G81),"",IF(MID(G81,1,1)="M",0,1)) -> 1 | D81: 2021 | E81: 104179 | F81: Arizona | G81: Women | H81: Soccer | I81: 14860 | J81: =I81/VLOOKUP($D81,CPI!$P$16:$R$22,3,FALSE) -> 16923.116 | K81: =IF(ISBLANK(G81),"",IF(D81=2021,1,0)) -> 1 | L81: {=IF($C81=0,INDEX('24&25'!$L:$L,MATCH($D81&$B81&$E81,'24&25'!$B:$B&'24&25'!$A:$A&'24&25'!$C:$C,0)),INDEX('24&25'!$M:$M,MATCH($D81&$B81&$E81,'24&25'!$B:$B&'24&25'!$A:$A&'24&25'!$C:$C,0)))} -> 29999 | M81: =L81/VLOOKUP($D81,CPI!$P$16:$R$22,3,FALSE) -> 34163.968
A82: 2 | B82: =IF(ISBLANK(G82),"",VLOOKUP(H82,code!B:C,2,FALSE)) -> 18 | C82: =IF(ISBLANK(G82),"",IF(MID(G82,1,1)="M",0,1)) -> 1 | D82: 2021 | E82: 104179 | F82: Arizona | G82: Women | H82: Softball | I82: 918737 | J82: =I82/VLOOKUP($D82,CPI!$P$16:$R$22,3,FALSE) -> 1046291.6 | K82: =IF(ISBLANK(G82),"",IF(D82=2021,1,0)) -> 1 | L82: {=IF($C82=0,INDEX('24&25'!$L:$L,MATCH($D82&$B82&$E82,'24&25'!$B:$B&'24&25'!$A:$A&'24&25'!$C:$C,0)),INDEX('24&25'!$M:$M,MATCH($D82&$B82&$E82,'24&25'!$B:$B&'24&25'!$A:$A&'24&25'!$C:$C,0)))} -> 88129 | M82: =L82/VLOOKUP($D82,CPI!$P$16:$R$22,3,FALSE) -> 100364.56
A83: 2 | B83: 19 | C83: =IF(ISBLANK(G83),"",IF(MID(G83,1,1)="M",0,1)) -> 1 | D83: 2021 | E83: 104179 | F83: Arizona | G83: Women | H83: Swimming and diving | I83: 5220 | J83: =I83/VLOOKUP($D83,CPI!$P$16:$R$22,3,FALSE) -> 5944.7286 | K83: =IF(ISBLANK(G83),"",IF(D83=2021,1,0)) -> 1 | L83: {=IF($C83=0,INDEX('24&25'!$L:$L,MATCH($D83&$B83&$E83,'24&25'!$B:$B&'24&25'!$A:$A&'24&25'!$C:$C,0)),INDEX('24&25'!$M:$M,MATCH($D83&$B83&$E83,'24&25'!$B:$B&'24&25'!$A:$A&'24&25'!$C:$C,0)))} -> 29241 | M83: =L83/VLOOKUP($D83,CPI!$P$16:$R$22,3,FALSE) -> 33300.73
A84: 2 | B84: =IF(ISBLANK(G84),"",VLOOKUP(H84,code!B:C,2,FALSE)) -> 20 | C84: =IF(ISBLANK(G84),"",IF(MID(G84,1,1)="M",0,1)) -> 1 | D84: 2021 | E84: 104179 | F84: Arizona | G84: Women | H84: Tennis | I84: 33681 | J84: =I84/VLOOKUP($D84,CPI!$P$16:$R$22,3,FALSE) -> 38357.166 | K84: =IF(ISBLANK(G84),"",IF(D84=2021,1,0)) -> 1 | L84: {=IF($C84=0,INDEX('24&25'!$L:$L,MATCH($D84&$B84&$E84,'24&25'!$B:$B&'24&25'!$A:$A&'24&25'!$C:$C,0)),INDEX('24&25'!$M:$M,MATCH($D84&$B84&$E84,'24&25'!$B:$B&'24&25'!$A:$A&'24&25'!$C:$C,0)))} -> 0 | M84: =L84/VLOOKUP($D84,CPI!$P$16:$R$22,3,FALSE) -> 0
A85: 2 | B85: 21 | C85: =IF(ISBLANK(G85),"",IF(MID(G85,1,1)="M",0,1)) -> 1 | D85: 2021 | E85: 104179 | F85: Arizona | G85: Women | H85: Track and Field , X country | I85: 79649 | J85: =I85/VLOOKUP($D85,CPI!$P$16:$R$22,3,FALSE) -> 90707.22 | K85: =IF(ISBLANK(G85),"",IF(D85=2021,1,0)) -> 1 | L85: {=IF($C85=0,INDEX('24&25'!$L:$L,MATCH($D85&$B85&$E85,'24&25'!$B:$B&'24&25'!$A:$A&'24&25'!$C:$C,0)),INDEX('24&25'!$M:$M,MATCH($D85&$B85&$E85,'24&25'!$B:$B&'24&25'!$A:$A&'24&25'!$C:$C,0)))} -> 34983 | M85: =L85/VLOOKUP($D85,CPI!$P$16:$R$22,3,FALSE) -> 39839.931
A86: 2 | B86: =IF(ISBLANK(G86),"",VLOOKUP(H86,code!B:C,2,FALSE)) -> 23 | C86: =IF(ISBLANK(G86),"",IF(MID(G86,1,1)="M",0,1)) -> 1 | D86: 2021 | E86: 104179 | F86: Arizona | G86: Women | H86: Volleyball | I86: 9461 | J86: =I86/VLOOKUP($D86,CPI!$P$16:$R$22,3,FALSE) -> 10774.536 | K86: =IF(ISBLANK(G86),"",IF(D86=2021,1,0)) -> 1 | L86: {=IF($C86=0,INDEX('24&25'!$L:$L,MATCH($D86&$B86&$E86,'24&25'!$B:$B&'24&25'!$A:$A&'24&25'!$C:$C,0)),INDEX('24&25'!$M:$M,MATCH($D86&$B86&$E86,'24&25'!$B:$B&'24&25'!$A:$A&'24&25'!$C:$C,0)))} -> 25759 | M86: =L86/VLOOKUP($D86,CPI!$P$16:$R$22,3,FALSE) -> 29335.3
A87: 2 | B87: =IF(ISBLANK(G87),"",VLOOKUP(H87,code!B:C,2,FALSE)) -> 1 | C87: =IF(ISBLANK(G87),"",IF(MID(G87,1,1)="M",0,1)) -> 0 | D87: 2022 | E87: 104179 | F87: Arizona | G87: Male | H87: Baseball | I87: 1432993 | J87: =I87/VLOOKUP($D87,CPI!$P$16:$R$22,3,FALSE) -> 1522727.5 | K87: =IF(ISBLANK(G87),"",IF(D87=2021,1,0)) -> 0 | L87: {=IF($C87=0,INDEX('24&25'!$L:$L,MATCH($D87&$B87&$E87,'24&25'!$B:$B&'24&25'!$A:$A&'24&25'!$C:$C,0)),INDEX('24&25'!$M:$M,MATCH($D87&$B87&$E87,'24&25'!$B:$B&'24&25'!$A:$A&'24&25'!$C:$C,0)))} -> 122942 | M87: =L87/VLOOKUP($D87,CPI!$P$16:$R$22,3,FALSE) -> 130640.67
A88: 2 | B88: =IF(ISBLANK(G88),"",VLOOKUP(H88,code!B:C,2,FALSE)) -> 2 | C88: =IF(ISBLANK(G88),"",IF(MID(G88,1,1)="M",0,1)) -> 0 | D88: 2022 | E88: 104179 | F88: Arizona | G88: Male | H88: Basketball | I88: 15504917 | J88: =I88/VLOOKUP($D88,CPI!$P$16:$R$22,3,FALSE) -> 16475840 | K88: =IF(ISBLANK(G88),"",IF(D88=2021,1,0)) -> 0 | L88: {=IF($C88=0,INDEX('24&25'!$L:$L,MATCH($D88&$B88&$E88,'24&25'!$B:$B&'24&25'!$A:$A&'24&25'!$C:$C,0)),INDEX('24&25'!$M:$M,MATCH($D88&$B88&$E88,'24&25'!$B:$B&'24&25'!$A:$A&'24&25'!$C:$C,0)))} -> 604505 | M88: =L88/VLOOKUP($D88,CPI!$P$16:$R$22,3,FALSE) -> 642359.31
A89: 2 | B89: =IF(ISBLANK(G89),"",VLOOKUP(H89,code!B:C,2,FALSE)) -> 8 | C89: =IF(ISBLANK(G89),"",IF(MID(G89,1,1)="M",0,1)) -> 0 | D89: 2022 | E89: 104179 | F89: Arizona | G89: Male | H89: Football | I89: 14652941 | J89: =I89/VLOOKUP($D89,CPI!$P$16:$R$22,3,FALSE) -> 15570513 | K89: =IF(ISBLANK(G89),"",IF(D89=2021,1,0)) -> 0 | L89: {=IF($C89=0,INDEX('24&25'!$L:$L,MATCH($D89&$B89&$E89,'24&25'!$B:$B&'24&25'!$A:$A&'24&25'!$C:$C,0)),INDEX('24&25'!$M:$M,MATCH($D89&$B89&$E89,'24&25'!$B:$B&'24&25'!$A:$A&'24&25'!$C:$C,0)))} -> 2372160 | M89: =L89/VLOOKUP($D89,CPI!$P$16:$R$22,3,FALSE) -> 2520705.5
A90: 2 | B90: =IF(ISBLANK(G90),"",VLOOKUP(H90,code!B:C,2,FALSE)) -> 9 | C90: =IF(ISBLANK(G90),"",IF(MID(G90,1,1)="M",0,1)) -> 0 | D90: 2022 | E90: 104179 | F90: Arizona | G90: Male | H90: Golf | I90: 100202 | J90: =I90/VLOOKUP($D90,CPI!$P$16:$R$22,3,FALSE) -> 106476.68 | K90: =IF(ISBLANK(G90),"",IF(D90=2021,1,0)) -> 0 | L90: {=IF($C90=0,INDEX('24&25'!$L:$L,MATCH($D90&$B90&$E90,'24&25'!$B:$B&'24&25'!$A:$A&'24&25'!$C:$C,0)),INDEX('24&25'!$M:$M,MATCH($D90&$B90&$E90,'24&25'!$B:$B&'24&25'!$A:$A&'24&25'!$C:$C,0)))} -> 0 | M90: =L90/VLOOKUP($D90,CPI!$P$16:$R$22,3,FALSE) -> 0
A91: 2 | B91: =IF(ISBLANK(G91),"",VLOOKUP(H91,code!B:C,2,FALSE)) -> 19 | C91: =IF(ISBLANK(G91),"",IF(MID(G91,1,1)="M",0,1)) -> 0 | D91: 2022 | E91: 104179 | F91: Arizona | G91: Male | H91: Swimming and Diving | I91: 37839 | J91: =I91/VLOOKUP($D91,CPI!$P$16:$R$22,3,FALSE) -> 40208.491 | K91: =IF(ISBLANK(G91),"",IF(D91=2021,1,0)) -> 0 | L91: {=IF($C91=0,INDEX('24&25'!$L:$L,MATCH($D91&$B91&$E91,'24&25'!$B:$B&'24&25'!$A:$A&'24&25'!$C:$C,0)),INDEX('24&25'!$M:$M,MATCH($D91&$B91&$E91,'24&25'!$B:$B&'24&25'!$A:$A&'24&25'!$C:$C,0)))} -> 29242 | M91: =L91/VLOOKUP($D91,CPI!$P$16:$R$22,3,FALSE) -> 31073.144
A92: 2 | B92: =IF(ISBLANK(G92),"",VLOOKUP(H92,code!B:C,2,FALSE)) -> 20 | C92: =IF(ISBLANK(G92),"",IF(MID(G92,1,1)="M",0,1)) -> 0 | D92: 2022 | E92: 104179 | F92: Arizona | G92: Male | H92: Tennis | I92: 11975 | J92: =I92/VLOOKUP($D92,CPI!$P$16:$R$22,3,FALSE) -> 12724.879 | K92: =IF(ISBLANK(G92),"",IF(D92=2021,1,0)) -> 0 | L92: {=IF($C92=0,INDEX('24&25'!$L:$L,MATCH($D92&$B92&$E92,'24&25'!$B:$B&'24&25'!$A:$A&'24&25'!$C:$C,0)),INDEX('24&25'!$M:$M,MATCH($D92&$B92&$E92,'24&25'!$B:$B&'24&25'!$A:$A&'24&25'!$C:$C,0)))} -> 0 | M92: =L92/VLOOKUP($D92,CPI!$P$16:$R$22,3,FALSE) -> 0
A93: 2 | B93: =IF(ISBLANK(G93),"",VLOOKUP(H93,code!B:C,2,FALSE)) -> 21 | C93: =IF(ISBLANK(G93),"",IF(MID(G93,1,1)="M",0,1)) -> 0 | D93: 2022 | E93: 104179 | F93: Arizona | G93: Male | H93: Track and Field, X-Country | I93: 25263 | J93: =I93/VLOOKUP($D93,CPI!$P$16:$R$22,3,FALSE) -> 26844.978 | K93: =IF(ISBLANK(G93),"",IF(D93=2021,1,0)) -> 0 | L93: {=IF($C93=0,INDEX('24&25'!$L:$L,MATCH($D93&$B93&$E93,'24&25'!$B:$B&'24&25'!$A:$A&'24&25'!$C:$C,0)),INDEX('24&25'!$M:$M,MATCH($D93&$B93&$E93,'24&25'!$B:$B&'24&25'!$A:$A&'24&25'!$C:$C,0)))} -> 34677 | M93: =L93/VLOOKUP($D93,CPI!$P$16:$R$22,3,FALSE) -> 36848.485
A94: 2 | B94: =IF(ISBLANK(G94),"",VLOOKUP(H94,code!B:C,2,FALSE)) -> 2 | C94: =IF(ISBLANK(G94),"",IF(MID(G94,1,1)="M",0,1)) -> 1 | D94: 2022 | E94: 104179 | F94: Arizona | G94: Female | H94: Basketball | I94: 1265576 | J94: =I94/VLOOKUP($D94,CPI!$P$16:$R$22,3,FALSE) -> 1344826.8 | K94: =IF(ISBLANK(G94),"",IF(D94=2021,1,0)) -> 0 | L94: {=IF($C94=0,INDEX('24&25'!$L:$L,MATCH($D94&$B94&$E94,'24&25'!$B:$B&'24&25'!$A:$A&'24&25'!$C:$C,0)),INDEX('24&25'!$M:$M,MATCH($D94&$B94&$E94,'24&25'!$B:$B&'24&25'!$A:$A&'24&25'!$C:$C,0)))} -> 304167 | M94: =L94/VLOOKUP($D94,CPI!$P$16:$R$22,3,FALSE) -> 323214.04
A95: 2 | B95: =IF(ISBLANK(G95),"",VLOOKUP(H95,code!B:C,2,FALSE)) -> 3 | C95: =IF(ISBLANK(G95),"",IF(MID(G95,1,1)="M",0,1)) -> 1 | D95: 2022 | E95: 104179 | F95: Arizona | G95: Female | H95: Beach Volleyball | I95: 3494 | J95: =I95/VLOOKUP($D95,CPI!$P$16:$R$22,3,FALSE) -> 3712.7955 | K95: =IF(ISBLANK(G95),"",IF(D95=2021,1,0)) -> 0 | L95: {=IF($C95=0,INDEX('24&25'!$L:$L,MATCH($D95&$B95&$E95,'24&25'!$B:$B&'24&25'!$A:$A&'24&25'!$C:$C,0)),INDEX('24&25'!$M:$M,MATCH($D95&$B95&$E95,'24&25'!$B:$B&'24&25'!$A:$A&'24&25'!$C:$C,0)))} -> 25758 | M95: =L95/VLOOKUP($D95,CPI!$P$16:$R$22,3,FALSE) -> 27370.975
A96: 2 | B96: =IF(ISBLANK(G96),"",VLOOKUP(H96,code!B:C,2,FALSE)) -> 9 | C96: =IF(ISBLANK(G96),"",IF(MID(G96,1,1)="M",0,1)) -> 1 | D96: 2022 | E96: 104179 | F96: Arizona | G96: Female | H96: Golf | I96: 38614 | J96: =I96/VLOOKUP($D96,CPI!$P$16:$R$22,3,FALSE) -> 41032.022 | K96: =IF(ISBLANK(G96),"",IF(D96=2021,1,0)) -> 0 | L96: {=IF($C96=0,INDEX('24&25'!$L:$L,MATCH($D96&$B96&$E96,'24&25'!$B:$B&'24&25'!$A:$A&'24&25'!$C:$C,0)),INDEX('24&25'!$M:$M,MATCH($D96&$B96&$E96,'24&25'!$B:$B&'24&25'!$A:$A&'24&25'!$C:$C,0)))} -> 0 | M96: =L96/VLOOKUP($D96,CPI!$P$16:$R$22,3,FALSE) -> 0
A97: 2 | B97: =IF(ISBLANK(G97),"",VLOOKUP(H97,code!B:C,2,FALSE)) -> 10 | C97: =IF(ISBLANK(G97),"",IF(MID(G97,1,1)="M",0,1)) -> 1 | D97: 2022 | E97: 104179 | F97: Arizona | G97: Female | H97: Gymnastics | I97: 53346 | J97: =I97/VLOOKUP($D97,CPI!$P$16:$R$22,3,FALSE) -> 56686.544 | K97: =IF(ISBLANK(G97),"",IF(D97=2021,1,0)) -> 0 | L97: {=IF($C97=0,INDEX('24&25'!$L:$L,MATCH($D97&$B97&$E97,'24&25'!$B:$B&'24&25'!$A:$A&'24&25'!$C:$C,0)),INDEX('24&25'!$M:$M,MATCH($D97&$B97&$E97,'24&25'!$B:$B&'24&25'!$A:$A&'24&25'!$C:$C,0)))} -> 33930 | M97: =L97/VLOOKUP($D97,CPI!$P$16:$R$22,3,FALSE) -> 36054.708
...

Sheet 24&25
A1: Code | B1: FY | C1: unitid | D1: University | E1: Sport | F1: MSupportSalary1 | G1: MSupportSalary2 | H1: WSupportSalary1 | I1: WSupportSalary2 | J1: NAGSupportSalary1 | K1: NAGSupportSalary2 | L1: MSupportSalary | M1: WSupportSalary
A2: =IF(ISBLANK(E2),"",VLOOKUP(E2,code!B:C,2,FALSE)) -> 2 | B2: 2017 | C2: 104179 | D2: Arizona | E2: Basketball | F2: 373154 | H2: 193255 | L2: =SUM(F2:G2) -> 373154 | M2: =SUM(H2:I2) -> 193255
A3: =IF(ISBLANK(E3),"",VLOOKUP(E3,code!B:C,2,FALSE)) -> 3 | B3: 2017 | C3: 104179 | D3: Arizona | E3: Beach Volleyball | L3: =SUM(F3:G3) -> 0 | M3: =SUM(H3:I3) -> 0
A4: 8 | B4: 2017 | C4: 104179 | D4: Arizona | E4: Football | F4: 1309151 | L4: =SUM(F4:G4) -> 1309151 | M4: =SUM(H4:I4) -> 0
A5: =IF(ISBLANK(E5),"",VLOOKUP(E5,code!B:C,2,FALSE)) -> 9 | B5: 2017 | C5: 104179 | D5: Arizona | E5: Golf | L5: =SUM(F5:G5) -> 0 | M5: =SUM(H5:I5) -> 0
A6: =IF(ISBLANK(E6),"",VLOOKUP(E6,code!B:C,2,FALSE)) -> 10 | B6: 2017 | C6: 104179 | D6: Arizona | E6: Gymnastics | L6: =SUM(F6:G6) -> 0 | M6: =SUM(H6:I6) -> 0
A7: =IF(ISBLANK(E7),"",VLOOKUP(E7,code!B:C,2,FALSE)) -> 17 | B7: 2017 | C7: 104179 | D7: Arizona | E7: Soccer | L7: =SUM(F7:G7) -> 0 | M7: =SUM(H7:I7) -> 0
A8: =IF(ISBLANK(E8),"",VLOOKUP(E8,code!B:C,2,FALSE)) -> 18 | B8: 2017 | C8: 104179 | D8: Arizona | E8: Softball | H8: 7422 | L8: =SUM(F8:G8) -> 0 | M8: =SUM(H8:I8) -> 7422
A9: =IF(ISBLANK(E9),"",VLOOKUP(E9,code!B:C,2,FALSE)) -> 19 | B9: 2017 | C9: 104179 | D9: Arizona | E9: Swimming and Diving | F9: 45379 | H9: 45379 | L9: =SUM(F9:G9) -> 45379 | M9: =SUM(H9:I9) -> 45379
A10: =IF(ISBLANK(E10),"",VLOOKUP(E10,code!B:C,2,FALSE)) -> 20 | B10: 2017 | C10: 104179 | D10: Arizona | E10: Tennis | L10: =SUM(F10:G10) -> 0 | M10: =SUM(H10:I10) -> 0
A11: =IF(ISBLANK(E11),"",VLOOKUP(E11,code!B:C,2,FALSE)) -> 21 | B11: 2017 | C11: 104179 | D11: Arizona | E11: Track and Field, X-Country | F11: 41582 | H11: 40125 | L11: =SUM(F11:G11) -> 41582 | M11: =SUM(H11:I11) -> 40125
A12: =IF(ISBLANK(E12),"",VLOOKUP(E12,code!B:C,2,FALSE)) -> 23 | B12: 2017 | C12: 104179 | D12: Arizona | E12: Volleyball | H12: 64377 | L12: =SUM(F12:G12) -> 0 | M12: =SUM(H12:I12) -> 64377
A13: =IF(ISBLANK(E13),"",VLOOKUP(E13,code!B:C,2,FALSE)) -> 1 | B13: 2018 | C13: 104179 | D13: Arizona | E13: Baseball | F13: 51785 | L13: =SUM(F13:G13) -> 51785 | M13: =SUM(H13:I13) -> 0
A14: =IF(ISBLANK(E14),"",VLOOKUP(E14,code!B:C,2,FALSE)) -> 2 | B14: 2018 | C14: 104179 | D14: Arizona | E14: Basketball | F14: 417443 | H14: 191198 | L14: =SUM(F14:G14) -> 417443 | M14: =SUM(H14:I14) -> 191198
A15: =IF(ISBLANK(E15),"",VLOOKUP(E15,code!B:C,2,FALSE)) -> 8 | B15: 2018 | C15: 104179 | D15: Arizona | E15: Football | F15: 1123651 | L15: =SUM(F15:G15) -> 1123651 | M15: =SUM(H15:I15) -> 0
A16: =IF(ISBLANK(E16),"",VLOOKUP(E16,code!B:C,2,FALSE)) -> 21 | B16: 2018 | C16: 104179 | D16: Arizona | E16: Track and Field, X-Country | F16: 42786 | H16: 42786 | L16: =SUM(F16:G16) -> 42786 | M16: =SUM(H16:I16) -> 42786
A17: =IF(ISBLANK(E17),"",VLOOKUP(E17,code!B:C,2,FALSE)) -> 3 | B17: 2018 | C17: 104179 | D17: Arizona | E17: Beach Volleyball | L17: =SUM(F17:G17) -> 0 | M17: =SUM(H17:I17) -> 0
A18: =IF(ISBLANK(E18),"",VLOOKUP(E18,code!B:C,2,FALSE)) -> 9 | B18: 2018 | C18: 104179 | D18: Arizona | E18: Golf | L18: =SUM(F18:G18) -> 0 | M18: =SUM(H18:I18) -> 0
A19: =IF(ISBLANK(E19),"",VLOOKUP(E19,code!B:C,2,FALSE)) -> 10 | B19: 2018 | C19: 104179 | D19: Arizona | E19: Gymnastics | H19: 8631 | L19: =SUM(F19:G19) -> 0 | M19: =SUM(H19:I19) -> 8631
A20: =IF(ISBLANK(E20),"",VLOOKUP(E20,code!B:C,2,FALSE)) -> 17 | B20: 2018 | C20: 104179 | D20: Arizona | E20: Soccer | H20: 8631 | L20: =SUM(F20:G20) -> 0 | M20: =SUM(H20:I20) -> 8631
A21: =IF(ISBLANK(E21),"",VLOOKUP(E21,code!B:C,2,FALSE)) -> 18 | B21: 2018 | C21: 104179 | D21: Arizona | E21: Softball | H21: 98345 | L21: =SUM(F21:G21) -> 0 | M21: =SUM(H21:I21) -> 98345
A22: =IF(ISBLANK(E22),"",VLOOKUP(E22,code!B:C,2,FALSE)) -> 19 | B22: 2018 | C22: 104179 | D22: Arizona | E22: Swimming and Diving | F22: 36235 | H22: 36235 | L22: =SUM(F22:G22) -> 36235 | M22: =SUM(H22:I22) -> 36235
A23: =IF(ISBLANK(E23),"",VLOOKUP(E23,code!B:C,2,FALSE)) -> 20 | B23: 2018 | C23: 104179 | D23: Arizona | E23: Tennis | L23: =SUM(F23:G23) -> 0 | M23: =SUM(H23:I23) -> 0
A24: =IF(ISBLANK(E24),"",VLOOKUP(E24,code!B:C,2,FALSE)) -> 23 | B24: 2018 | C24: 104179 | D24: Arizona | E24: Volleyball | H24: 63753 | L24: =SUM(F24:G24) -> 0 | M24: =SUM(H24:I24) -> 63753
A25: =IF(ISBLANK(E25),"",VLOOKUP(E25,code!B:C,2,FALSE)) -> 1 | B25: 2019 | C25: 104179 | D25: Arizona | E25: Baseball | F25: 59903 | L25: =SUM(F25:G25) -> 59903 | M25: =SUM(H25:I25) -> 0
A26: =IF(ISBLANK(E26),"",VLOOKUP(E26,code!B:C,2,FALSE)) -> 2 | B26: 2019 | C26: 104179 | D26: Arizona | E26: Basketball | F26: 333115 | H26: 196383 | L26: =SUM(F26:G26) -> 333115 | M26: =SUM(H26:I26) -> 196383
A27: =IF(ISBLANK(E27),"",VLOOKUP(E27,code!B:C,2,FALSE)) -> 8 | B27: 2019 | C27: 104179 | D27: Arizona | E27: Football | F27: 1629077 | L27: =SUM(F27:G27) -> 1629077 | M27: =SUM(H27:I27) -> 0
A28: =IF(ISBLANK(E28),"",VLOOKUP(E28,code!B:C,2,FALSE)) -> 9 | B28: 2019 | C28: 104179 | D28: Arizona | E28: Golf | L28: =SUM(F28:G28) -> 0 | M28: =SUM(H28:I28) -> 0
A29: =IF(ISBLANK(E29),"",VLOOKUP(E29,code!B:C,2,FALSE)) -> 20 | B29: 2019 | C29: 104179 | D29: Arizona | E29: Tennis | L29: =SUM(F29:G29) -> 0 | M29: =SUM(H29:I29) -> 0
A30: =IF(ISBLANK(E30),"",VLOOKUP(E30,code!B:C,2,FALSE)) -> 21 | B30: 2019 | C30: 104179 | D30: Arizona | E30: Track and Field, X-Country | F30: 51705 | H30: 50287 | L30: =SUM(F30:G30) -> 51705 | M30: =SUM(H30:I30) -> 50287
A31: =IF(ISBLANK(E31),"",VLOOKUP(E31,code!B:C,2,FALSE)) -> 3 | B31: 2019 | C31: 104179 | D31: Arizona | E31: Beach Volleyball | L31: =SUM(F31:G31) -> 0 | M31: =SUM(H31:I31) -> 0
A32: =IF(ISBLANK(E32),"",VLOOKUP(E32,code!B:C,2,FALSE)) -> 10 | B32: 2019 | C32: 104179 | D32: Arizona | E32: Gymnastics | H32: 26896 | L32: =SUM(F32:G32) -> 0 | M32: =SUM(H32:I32) -> 26896
A33: =IF(ISBLANK(E33),"",VLOOKUP(E33,code!B:C,2,FALSE)) -> 17 | B33: 2019 | C33: 104179 | D33: Arizona | E33: Soccer | H33: 26896 | L33: =SUM(F33:G33) -> 0 | M33: =SUM(H33:I33) -> 26896
A34: =IF(ISBLANK(E34),"",VLOOKUP(E34,code!B:C,2,FALSE)) -> 18 | B34: 2019 | C34: 104179 | D34: Arizona | E34: Softball | H34: 82453 | L34: =SUM(F34:G34) -> 0 | M34: =SUM(H34:I34) -> 82453
A35: =IF(ISBLANK(E35),"",VLOOKUP(E35,code!B:C,2,FALSE)) -> 19 | B35: 2019 | C35: 104179 | D35: Arizona | E35: Swimming and Diving | F35: 32504 | H35: 32503 | L35: =SUM(F35:G35) -> 32504 | M35: =SUM(H35:I35) -> 32503
A36: =IF(ISBLANK(E36),"",VLOOKUP(E36,code!B:C,2,FALSE)) -> 23 | B36: 2019 | C36: 104179 | D36: Arizona | E36: Volleyball | H36: 59296 | L36: =SUM(F36:G36) -> 0 | M36: =SUM(H36:I36) -> 59296
A37: =IF(ISBLANK(E37),"",VLOOKUP(E37,code!B:C,2,FALSE)) -> 1 | B37: 2020 | C37: 104179 | D37: Arizona | E37: Baseball | F37: 116863 | L37: =SUM(F37:G37) -> 116863 | M37: =SUM(H37:I37) -> 0
A38: =IF(ISBLANK(E38),"",VLOOKUP(E38,code!B:C,2,FALSE)) -> 2 | B38: 2020 | C38: 104179 | D38: Arizona | E38: Basketball | F38: 511905 | H38: 192847 | L38: =SUM(F38:G38) -> 511905 | M38: =SUM(H38:I38) -> 192847
A39: =IF(ISBLANK(E39),"",VLOOKUP(E39,code!B:C,2,FALSE)) -> 8 | B39: 2020 | C39: 104179 | D39: Arizona | E39: Football | F39: 1521384 | L39: =SUM(F39:G39) -> 1521384 | M39: =SUM(H39:I39) -> 0
A40: =IF(ISBLANK(E40),"",VLOOKUP(E40,code!B:C,2,FALSE)) -> 3 | B40: 2020 | C40: 104179 | D40: Arizona | E40: Beach Volleyball | H40: 26280 | L40: =SUM(F40:G40) -> 0 | M40: =SUM(H40:I40) -> 26280
...

Sheet unitid
A1: unitid | B1: Univeristy | C1: unitid
A2: 500002 | B2: Air Force | C2: 500002
A3: 200800 | B3: Akron | C3: 200800
A4: 100751 | B4: Alabama | C4: 100751
A5: 100724 | B5: Alabama State | C5: 100724
A6: 196060 | B6: Albany | C6: 196060
A7: 175342 | B7: Alcorn State | C7: 175342
A8: 197869 | B8: Appalachian State | C8: 197869
A9: 104179 | B9: Arizona | C9: 104179
A10: 104151 | B10: Arizona State | C10: 104151
A11: 106397 | B11: Arkansas | C11: 106397
A12: 106245 | B12: Arkansas Little Rock | C12: 106245
A13: 106412 | B13: Arkansas Pine Bluff | C13: 106412
... A224: 206695 | B224: Youngstown State | C224: 206695

Sheet code
A1: Code | B1: Sport | C1: Code
A2: 1 | B2: Baseball | C2: 1
A3: 2 | B3: Basketball | C3: 2
A4: 3 | B4: Beach Volleyball | C4: 3
A5: 4 | B5: Bowling | C5: 4
A6: 5 | B6: Equestrian | C6: 5
A7: 6 | B7: Fencing | C7: 6
A8: 7 | B8: Field Hockey | C8: 7
A9: 8 | B9: Football | C9: 8
A10: 9 | B10: Golf | C10: 9
A11: 10 | B11: Gymnastics | C11: 10
A12: 11 | B12: Ice Hockey | C12: 11
A13: 12 | B13: Lacrosse | C13: 12
... A39: 21 | B39: Track and Field X- Country | C39: 21

Sheet CPI
A1: Consumer Price Index for All Urban Consumers (CPI-U)
A2: Original Data Value
A4: Series Id: | B4: CUUR0000SA0
A5: Not Seasonally Adjusted
A6: Series Title: | B6: All items in U.S. city average, all urban consumers, not seasonally adjusted
A7: Area: | B7: U.S. city average
A8: Item: | B8: All items
A9: Base Period: | B9: 1982-84=100
A10: Years: | B10: 2014 to 2024
A12: Year | B12: Jan | C12: Feb | D12: Mar | E12: Apr | F12: May | G12: Jun | H12: Jul | I12: Aug | J12: Sep | K12: Oct | L12: Nov | M12: Dec | N12: HALF1 | O12: HALF2
A13: 2014 | B13: 233.916 | C13: 234.781 | D13: 236.293 | E13: 237.072 | F13: 237.9 | G13: 238.343 | H13: 238.25 | I13: 237.852 | J13: 238.031 | K13: 237.433 | L13: 236.151 | M13: 234.812 | N13: 236.384 | O13: 237.088
A14: 2015 | B14: 233.707 | C14: 234.722 | D14: 236.119 | E14: 236.599 | F14: 237.805 | G14: 238.638 | H14: 238.654 | I14: 238.316 | J14: 237.945 | K14: 237.838 | L14: 237.336 | M14: 236.525 | N14: 236.265 | O14: 237.769
A15: 2016 | B15: 236.916 | C15: 237.111 | D15: 238.132 | E15: 239.261 | F15: 240.229 | G15: 241.018 | H15: 240.628 | I15: 240.849 | J15: 241.428 | K15: 241.729 | L15: 241.353 | M15: 241.432 | N15: 238.778 | O15: 241.237
A16: 2017 | B16: 242.839 | C16: 243.603 | D16: 243.801 | E16: 244.524 | F16: 244.733 | G16: 244.955 | H16: 244.786 | I16: 245.519 | J16: 246.819 | K16: 246.663 | L16: 246.669 | M16: 246.524 | N16: 244.076 | O16: 246.163 | P16: 2017 | Q16: =AVERAGE(N16,O15) -> 242.6565 | R16: =Q16/Q$22 -> 0.80970384
A17: 2018 | B17: 247.867 | C17: 248.991 | D17: 249.554 | E17: 250.546 | F17: 251.588 | G17: 251.989 | H17: 252.006 | I17: 252.146 | J17: 252.439 | K17: 252.885 | L17: 252.038 | M17: 251.233 | N17: 250.089 | O17: 252.125 | P17: =P16+1 -> 2018 | Q17: =AVERAGE(N17,O16) -> 248.126 | R17: =Q17/Q$22 -> 0.82795464
A18: 2019 | B18: 251.712 | C18: 252.776 | D18: 254.202 | E18: 255.548 | F18: 256.092 | G18: 256.143 | H18: 256.571 | I18: 256.558 | J18: 256.759 | K18: 257.346 | L18: 257.208 | M18: 256.974 | N18: 254.412 | O18: 256.903 | P18: =P17+1 -> 2019 | Q18: =AVERAGE(N18,O17) -> 253.2685 | R18: =Q18/Q$22 -> 0.84511429
A19: 2020 | B19: 257.971 | C19: 258.678 | D19: 258.115 | E19: 256.389 | F19: 256.394 | G19: 257.797 | H19: 259.101 | I19: 259.918 | J19: 260.28 | K19: 260.388 | L19: 260.229 | M19: 260.474 | N19: 257.557 | O19: 260.065 | P19: =P18+1 -> 2020 | Q19: =AVERAGE(N19,O18) -> 257.23 | R19: =Q19/Q$22 -> 0.85833315
A20: 2021 | B20: 261.582 | C20: 263.014 | D20: 264.877 | E20: 267.054 | F20: 269.195 | G20: 271.696 | H20: 273.003 | I20: 273.567 | J20: 274.31 | K20: 276.589 | L20: 277.948 | M20: 278.802 | N20: 266.236 | O20: 275.703 | P20: =P19+1 -> 2021 | Q20: =AVERAGE(N20,O19) -> 263.1505 | R20: =Q20/Q$22 -> 0.87808886
A21: 2022 | B21: 281.148 | C21: 283.716 | D21: 287.504 | E21: 289.109 | F21: 292.296 | G21: 296.311 | H21: 296.276 | I21: 296.171 | J21: 296.808 | K21: 298.012 | L21: 297.711 | M21: 296.797 | N21: 288.347 | O21: 296.963 | P21: =P20+1 -> 2022 | Q21: =AVERAGE(N21,O20) -> 282.025 | R21: =Q21/Q$22 -> 0.94106989
A22: 2023 | B22: 299.17 | C22: 300.84 | D22: 301.836 | E22: 303.363 | F22: 304.127 | G22: 305.109 | H22: 305.691 | I22: 307.026 | J22: 307.789 | K22: 307.671 | L22: 307.051 | M22: 306.746 | N22: 302.408 | O22: 306.996 | P22: =P21+1 -> 2023 | Q22: =AVERAGE(N22,O21) -> 299.6855 | R22: =Q22/Q$22 -> 1
A23: 2024 | B23: 308.417 | C23: 310.326 | D23: 312.332 | E23: 313.548 | F23: 314.069 | G23: 314.175 | H23: 314.54 | I23: 314.796 | J23: 315.301 | N23: 312.145
