Workbook

Sheet Sheet1
A1: RA6 | B1: University | C1: unitid | D1: FY | E1: TotalConcessions | F1: RealTotalConcessions | G1: TotalAdRev | H1: RealTotalAdRev | I1: TotalAdExp | J1: RealTotalAdExp | K1: TotalAttendance
A2: 2 | B2: Arizona | C2: 104179 | D2: 2017 | E2: 2934038 | F2: =E2/VLOOKUP($D2,CPI!$P$16:$R$22,3,FALSE) -> 3623594 | G2: 9900132 | H2: =G2/VLOOKUP($D2,CPI!$P$16:$R$22,3,FALSE) -> 12226856 | I2: 1469240 | J2: =I2/VLOOKUP($D2,CPI!$P$16:$R$22,3,FALSE) -> 1814540 | K2: =VLOOKUP(C2,Total!A:O,8,FALSE) -> 551769
A3: =IF(ISBLANK(A$2),"",$A$2) -> 2 | B3: =B2 -> Arizona | C3: 104179 | D3: =IF(D2=2023,2017,D2+1) -> 2018 | E3: 2433487 | F3: =E3/VLOOKUP($D3,CPI!$P$16:$R$22,3,FALSE) -> 2939155 | G3: 8865761 | H3: =G3/VLOOKUP($D3,CPI!$P$16:$R$22,3,FALSE) -> 10708027 | I3: 1620431 | J3: =I3/VLOOKUP($D3,CPI!$P$16:$R$22,3,FALSE) -> 1957149.5 | K3: =VLOOKUP(C3,Total!A:O,9,FALSE) -> 455423
A4: =IF(ISBLANK(A$2),"",$A$2) -> 2 | B4: =B3 -> Arizona | C4: 104179 | D4: =IF(D3=2023,2017,D3+1) -> 2019 | E4: 2110407 | F4: =E4/VLOOKUP($D4,CPI!$P$16:$R$22,3,FALSE) -> 2497185.3 | G4: 8763036 | H4: =G4/VLOOKUP($D4,CPI!$P$16:$R$22,3,FALSE) -> 10369054 | I4: 1501762 | J4: =I4/VLOOKUP($D4,CPI!$P$16:$R$22,3,FALSE) -> 1776992.8 | K4: =VLOOKUP(C4,Total!A:O,10,FALSE) -> 522517
A5: =IF(ISBLANK(A$2),"",$A$2) -> 2 | B5: =B4 -> Arizona | C5: 104179 | D5: =IF(D4=2023,2017,D4+1) -> 2020 | E5: 1876754 | F5: =E5/VLOOKUP($D5,CPI!$P$16:$R$22,3,FALSE) -> 2186510 | G5: 8370957 | H5: =G5/VLOOKUP($D5,CPI!$P$16:$R$22,3,FALSE) -> 9752573.3 | I5: 1482270 | J5: =I5/VLOOKUP($D5,CPI!$P$16:$R$22,3,FALSE) -> 1726916.9 | K5: =VLOOKUP(C5,Total!A:O,11,FALSE) -> 441655
A6: =IF(ISBLANK(A$2),"",$A$2) -> 2 | B6: =B5 -> Arizona | C6: 104179 | D6: =IF(D5=2023,2017,D5+1) -> 2021 | E6: 563251 | F6: =E6/VLOOKUP($D6,CPI!$P$16:$R$22,3,FALSE) -> 641451.02 | G6: 6874440 | H6: =G6/VLOOKUP($D6,CPI!$P$16:$R$22,3,FALSE) -> 7828865.9 | I6: 369632 | J6: =I6/VLOOKUP($D6,CPI!$P$16:$R$22,3,FALSE) -> 420950.56 | K6: =VLOOKUP(C6,Total!A:O,12,FALSE) -> 106443
A7: =IF(ISBLANK(A$2),"",$A$2) -> 2 | B7: =B6 -> Arizona | C7: 104179 | D7: =IF(D6=2023,2017,D6+1) -> 2022 | E7: 2456996 | F7: =E7/VLOOKUP($D7,CPI!$P$16:$R$22,3,FALSE) -> 2610853.9 | G7: 9512261 | H7: =G7/VLOOKUP($D7,CPI!$P$16:$R$22,3,FALSE) -> 10107922 | I7: 1608565 | J7: =I7/VLOOKUP($D7,CPI!$P$16:$R$22,3,FALSE) -> 1709293.9 | K7: =VLOOKUP(C7,Total!A:O,13,FALSE) -> 514933
A8: =IF(ISBLANK(A$2),"",$A$2) -> 2 | B8: =B7 -> Arizona | C8: 104179 | D8: =IF(D7=2023,2017,D7+1) -> 2023 | E8: 3656522 | F8: =E8/VLOOKUP($D8,CPI!$P$16:$R$22,3,FALSE) -> 3656522 | G8: 12468828 | H8: =G8/VLOOKUP($D8,CPI!$P$16:$R$22,3,FALSE) -> 12468828 | I8: 1769772 | J8: =I8/VLOOKUP($D8,CPI!$P$16:$R$22,3,FALSE) -> 1769772 | K8: =VLOOKUP(C8,Total!A:O,14,FALSE) -> 515674
A9: =IF(ISBLANK(A$2),"",$A$2) -> 2 | B9: California | C9: 110635 | D9: =IF(D8=2023,2017,D8+1) -> 2017 | E9: 835280 | F9: =E9/VLOOKUP($D9,CPI!$P$16:$R$22,3,FALSE) -> 1031587.1 | G9: 12847555 | H9: =G9/VLOOKUP($D9,CPI!$P$16:$R$22,3,FALSE) -> 15866980 | I9: 4075181 | J9: =I9/VLOOKUP($D9,CPI!$P$16:$R$22,3,FALSE) -> 5032927.8 | K9: =VLOOKUP(C9,Total!A:O,8,FALSE) -> 370402
A10: =IF(ISBLANK(A$2),"",$A$2) -> 2 | B10: =B9 -> California | C10: 110635 | D10: =IF(D9=2023,2017,D9+1) -> 2018 | E10: 662604 | F10: =E10/VLOOKUP($D10,CPI!$P$16:$R$22,3,FALSE) -> 800290.22 | G10: 21490730 | H10: =G10/VLOOKUP($D10,CPI!$P$16:$R$22,3,FALSE) -> 25956410 | I10: 3922991 | J10: =I10/VLOOKUP($D10,CPI!$P$16:$R$22,3,FALSE) -> 4738171.4 | K10: =VLOOKUP(C10,Total!A:O,9,FALSE) -> 303448
A11: =IF(ISBLANK(A$2),"",$A$2) -> 2 | B11: =B10 -> California | C11: 110635 | D11: =IF(D10=2023,2017,D10+1) -> 2019 | E11: 867441 | F11: =E11/VLOOKUP($D11,CPI!$P$16:$R$22,3,FALSE) -> 1026418.6 | G11: 17201102 | H11: =G11/VLOOKUP($D11,CPI!$P$16:$R$22,3,FALSE) -> 20353581 | I11: 4802534 | J11: =I11/VLOOKUP($D11,CPI!$P$16:$R$22,3,FALSE) -> 5682703.5 | K11: =VLOOKUP(C11,Total!A:O,10,FALSE) -> 376515
A12: =IF(ISBLANK(A$2),"",$A$2) -> 2 | B12: =B11 -> California | C12: 110635 | D12: =IF(D11=2023,2017,D11+1) -> 2020 | E12: 812075 | F12: =E12/VLOOKUP($D12,CPI!$P$16:$R$22,3,FALSE) -> 946107 | G12: 17907314 | H12: =G12/VLOOKUP($D12,CPI!$P$16:$R$22,3,FALSE) -> 20862894 | I12: 4446741 | J12: =I12/VLOOKUP($D12,CPI!$P$16:$R$22,3,FALSE) -> 5180670.2 | K12: =VLOOKUP(C12,Total!A:O,11,FALSE) -> 310066
A13: =IF(ISBLANK(A$2),"",$A$2) -> 2 | B13: =B12 -> California | C13: 110635 | D13: =IF(D12=2023,2017,D12+1) -> 2021 | E13: 74025 | F13: =E13/VLOOKUP($D13,CPI!$P$16:$R$22,3,FALSE) -> 84302.402 | G13: 9202835 | H13: =G13/VLOOKUP($D13,CPI!$P$16:$R$22,3,FALSE) -> 10480528 | I13: 1890830 | J13: =I13/VLOOKUP($D13,CPI!$P$16:$R$22,3,FALSE) -> 2153347 | K13: =VLOOKUP(C13,Total!A:O,12,FALSE) -> 21102
A14: =IF(ISBLANK(A$2),"",$A$2) -> 2 | B14: =B13 -> California | C14: 110635 | D14: =IF(D13=2023,2017,D13+1) -> 2022 | E14: 602939 | F14: =E14/VLOOKUP($D14,CPI!$P$16:$R$22,3,FALSE) -> 640695.24 | G14: 13083897 | H14: =G14/VLOOKUP($D14,CPI!$P$16:$R$22,3,FALSE) -> 13903215 | I14: 4244985 | J14: =I14/VLOOKUP($D14,CPI!$P$16:$R$22,3,FALSE) -> 4510807.4 | K14: =VLOOKUP(C14,Total!A:O,13,FALSE) -> 288739
A15: =IF(ISBLANK(A$2),"",$A$2) -> 2 | B15: =B14 -> California | C15: 110635 | D15: =IF(D14=2023,2017,D14+1) -> 2023 | E15: 899070 | F15: =E15/VLOOKUP($D15,CPI!$P$16:$R$22,3,FALSE) -> 899070 | G15: 14449998 | H15: =G15/VLOOKUP($D15,CPI!$P$16:$R$22,3,FALSE) -> 14449998 | I15: 8105193 | J15: =I15/VLOOKUP($D15,CPI!$P$16:$R$22,3,FALSE) -> 8105193 | K15: =VLOOKUP(C15,Total!A:O,14,FALSE) -> 320988
A16: =IF(ISBLANK(A$2),"",$A$2) -> 2 | B16: Colorado | C16: 126614 | D16: =IF(D15=2023,2017,D15+1) -> 2017 | E16: 1617492 | F16: =E16/VLOOKUP($D16,CPI!$P$16:$R$22,3,FALSE) -> 1997634.1 | G16: 6416499 | H16: =G16/VLOOKUP($D16,CPI!$P$16:$R$22,3,FALSE) -> 7924501.1 | I16: 1885874 | J16: =I16/VLOOKUP($D16,CPI!$P$16:$R$22,3,FALSE) -> 2329091.1 | K16: =VLOOKUP(C16,Total!A:O,8,FALSE) -> 351226
A17: =IF(ISBLANK(A$2),"",$A$2) -> 2 | B17: =B16 -> Colorado | C17: 126614 | D17: =IF(D16=2023,2017,D16+1) -> 2018 | E17: 1638587 | F17: =E17/VLOOKUP($D17,CPI!$P$16:$R$22,3,FALSE) -> 1979078.2 | G17: 7281345 | H17: =G17/VLOOKUP($D17,CPI!$P$16:$R$22,3,FALSE) -> 8794376.7 | I17: 1854403 | J17: =I17/VLOOKUP($D17,CPI!$P$16:$R$22,3,FALSE) -> 2239739.9 | K17: =VLOOKUP(C17,Total!A:O,9,FALSE) -> 344020
A18: =IF(ISBLANK(A$2),"",$A$2) -> 2 | B18: =B17 -> Colorado | C18: 126614 | D18: =IF(D17=2023,2017,D17+1) -> 2019 | E18: 2307881 | F18: =E18/VLOOKUP($D18,CPI!$P$16:$R$22,3,FALSE) -> 2730850.7 | G18: 8742848 | H18: =G18/VLOOKUP($D18,CPI!$P$16:$R$22,3,FALSE) -> 10345166 | I18: 1782701 | J18: =I18/VLOOKUP($D18,CPI!$P$16:$R$22,3,FALSE) -> 2109420 | K18: =VLOOKUP(C18,Total!A:O,10,FALSE) -> 339747
A19: =IF(ISBLANK(A$2),"",$A$2) -> 2 | B19: =B18 -> Colorado | C19: 126614 | D19: =IF(D18=2023,2017,D18+1) -> 2020 | E19: 3868507 | F19: =E19/VLOOKUP($D19,CPI!$P$16:$R$22,3,FALSE) -> 4506999.4 | G19: 7105608 | H19: =G19/VLOOKUP($D19,CPI!$P$16:$R$22,3,FALSE) -> 8278380 | I19: 1007477 | J19: =I19/VLOOKUP($D19,CPI!$P$16:$R$22,3,FALSE) -> 1173759.9 | K19: =VLOOKUP(C19,Total!A:O,11,FALSE) -> 359954
A20: =IF(ISBLANK(A$2),"",$A$2) -> 2 | B20: =B19 -> Colorado | C20: 126614 | D20: =IF(D19=2023,2017,D19+1) -> 2021 | E20: 73564 | F20: =E20/VLOOKUP($D20,CPI!$P$16:$R$22,3,FALSE) -> 83777.398 | G20: 7578753 | H20: =G20/VLOOKUP($D20,CPI!$P$16:$R$22,3,FALSE) -> 8630963.6 | I20: 187544 | J20: =I20/VLOOKUP($D20,CPI!$P$16:$R$22,3,FALSE) -> 213582.03 | K20: =VLOOKUP(C20,Total!A:O,12,FALSE) -> 1588
A21: =IF(ISBLANK(A$2),"",$A$2) -> 2 | B21: =B20 -> Colorado | C21: 126614 | D21: =IF(D20=2023,2017,D20+1) -> 2022 | E21: 2722208 | F21: =E21/VLOOKUP($D21,CPI!$P$16:$R$22,3,FALSE) -> 2892673.6 | G21: 5911440 | H21: =G21/VLOOKUP($D21,CPI!$P$16:$R$22,3,FALSE) -> 6281616.4 | I21: 821185 | J21: =I21/VLOOKUP($D21,CPI!$P$16:$R$22,3,FALSE) -> 872607.88 | K21: =VLOOKUP(C21,Total!A:O,13,FALSE) -> 328750
A22: =IF(ISBLANK(A$2),"",$A$2) -> 2 | B22: =B21 -> Colorado | C22: 126614 | D22: =IF(D21=2023,2017,D21+1) -> 2023 | E22: 2249977 | F22: =E22/VLOOKUP($D22,CPI!$P$16:$R$22,3,FALSE) -> 2249977 | G22: 6674982 | H22: =G22/VLOOKUP($D22,CPI!$P$16:$R$22,3,FALSE) -> 6674982 | I22: 1187198 | J22: =I22/VLOOKUP($D22,CPI!$P$16:$R$22,3,FALSE) -> 1187198 | K22: =VLOOKUP(C22,Total!A:O,14,FALSE) -> 315103
A23: =IF(ISBLANK(A$2),"",$A$2) -> 2 | B23: Maryland Baltimore County | C23: 163268 | D23: =IF(D22=2023,2017,D22+1) -> 2017 | E23: 0 | F23: =E23/VLOOKUP($D23,CPI!$P$16:$R$22,3,FALSE) -> 0 | G23: 267785 | H23: =G23/VLOOKUP($D23,CPI!$P$16:$R$22,3,FALSE) -> 330719.69 | I23: 214800 | J23: =I23/VLOOKUP($D23,CPI!$P$16:$R$22,3,FALSE) -> 265282.18 | K23: =VLOOKUP(C23,Total!A:O,8,FALSE) -> 33569
A24: =IF(ISBLANK(A$2),"",$A$2) -> 2 | B24: =B23 -> Maryland Baltimore County | C24: 163268 | D24: =IF(D23=2023,2017,D23+1) -> 2018 | E24: 0 | F24: =E24/VLOOKUP($D24,CPI!$P$16:$R$22,3,FALSE) -> 0 | G24: 10408 | H24: =G24/VLOOKUP($D24,CPI!$P$16:$R$22,3,FALSE) -> 12570.737 | I24: 216275 | J24: =I24/VLOOKUP($D24,CPI!$P$16:$R$22,3,FALSE) -> 261216 | K24: =VLOOKUP(C24,Total!A:O,9,FALSE) -> 37456
A25: =IF(ISBLANK(A$2),"",$A$2) -> 2 | B25: =B24 -> Maryland Baltimore County | C25: 163268 | D25: =IF(D24=2023,2017,D24+1) -> 2019 | E25: 0 | F25: =E25/VLOOKUP($D25,CPI!$P$16:$R$22,3,FALSE) -> 0 | G25: 145623 | H25: =G25/VLOOKUP($D25,CPI!$P$16:$R$22,3,FALSE) -> 172311.6 | I25: 116822 | J25: =I25/VLOOKUP($D25,CPI!$P$16:$R$22,3,FALSE) -> 138232.19 | K25: =VLOOKUP(C25,Total!A:O,10,FALSE) -> 40248
A26: =IF(ISBLANK(A$2),"",$A$2) -> 2 | B26: =B25 -> Maryland Baltimore County | C26: 163268 | D26: =IF(D25=2023,2017,D25+1) -> 2020 | E26: 0 | F26: =E26/VLOOKUP($D26,CPI!$P$16:$R$22,3,FALSE) -> 0 | G26: 85087 | H26: =G26/VLOOKUP($D26,CPI!$P$16:$R$22,3,FALSE) -> 99130.506 | I26: 99303 | J26: =I26/VLOOKUP($D26,CPI!$P$16:$R$22,3,FALSE) -> 115692.84 | K26: =VLOOKUP(C26,Total!A:O,11,FALSE) -> 19692
A27: =IF(ISBLANK(A$2),"",$A$2) -> 2 | B27: =B26 -> Maryland Baltimore County | C27: 163268 | D27: =IF(D26=2023,2017,D26+1) -> 2021 | E27: 0 | F27: =E27/VLOOKUP($D27,CPI!$P$16:$R$22,3,FALSE) -> 0 | G27: 92788 | H27: =G27/VLOOKUP($D27,CPI!$P$16:$R$22,3,FALSE) -> 105670.4 | I27: 17092 | J27: =I27/VLOOKUP($D27,CPI!$P$16:$R$22,3,FALSE) -> 19465 | K27: =VLOOKUP(C27,Total!A:O,12,FALSE) -> 6144
A28: =IF(ISBLANK(A$2),"",$A$2) -> 2 | B28: =B27 -> Maryland Baltimore County | C28: 163268 | D28: =IF(D27=2023,2017,D27+1) -> 2022 | E28: 0 | F28: =E28/VLOOKUP($D28,CPI!$P$16:$R$22,3,FALSE) -> 0 | G28: 146229 | H28: =G28/VLOOKUP($D28,CPI!$P$16:$R$22,3,FALSE) -> 155385.91 | I28: 88199 | J28: =I28/VLOOKUP($D28,CPI!$P$16:$R$22,3,FALSE) -> 93722.051 | K28: =VLOOKUP(C28,Total!A:O,13,FALSE) -> 44218
A29: =IF(ISBLANK(A$2),"",$A$2) -> 2 | B29: =B28 -> Maryland Baltimore County | C29: 163268 | D29: =IF(D28=2023,2017,D28+1) -> 2023 | E29: 0 | F29: =E29/VLOOKUP($D29,CPI!$P$16:$R$22,3,FALSE) -> 0 | G29: 267593 | H29: =G29/VLOOKUP($D29,CPI!$P$16:$R$22,3,FALSE) -> 267593 | I29: 115335 | J29: =I29/VLOOKUP($D29,CPI!$P$16:$R$22,3,FALSE) -> 115335 | K29: =VLOOKUP(C29,Total!A:O,14,FALSE) -> 46741
A30: =IF(ISBLANK(A$2),"",$A$2) -> 2 | B30: North Carolina Wilmington | C30: 199218 | D30: 2017 | E30: 0 | F30: =E30/VLOOKUP($D30,CPI!$P$16:$R$22,3,FALSE) -> 0 | G30: 510225 | H30: =G30/VLOOKUP($D30,CPI!$P$16:$R$22,3,FALSE) -> 630137.8 | I30: 124676 | J30: =I30/VLOOKUP($D30,CPI!$P$16:$R$22,3,FALSE) -> 153977.29 | K30: =VLOOKUP(C30,Total!A:O,8,FALSE) -> 77225
A31: =IF(ISBLANK(A$2),"",$A$2) -> 2 | B31: =B30 -> North Carolina Wilmington | C31: 199218 | D31: =IF(D30=2023,2017,D30+1) -> 2018 | E31: 0 | F31: =E31/VLOOKUP($D31,CPI!$P$16:$R$22,3,FALSE) -> 0 | G31: 568950 | H31: =G31/VLOOKUP($D31,CPI!$P$16:$R$22,3,FALSE) -> 687175.33 | I31: 128120 | J31: =I31/VLOOKUP($D31,CPI!$P$16:$R$22,3,FALSE) -> 154742.78 | K31: =VLOOKUP(C31,Total!A:O,9,FALSE) -> 66942
A32: =IF(ISBLANK(A$2),"",$A$2) -> 2 | B32: =B31 -> North Carolina Wilmington | C32: 199218 | D32: =IF(D31=2023,2017,D31+1) -> 2019 | E32: 0 | F32: =E32/VLOOKUP($D32,CPI!$P$16:$R$22,3,FALSE) -> 0 | G32: 549897 | H32: =G32/VLOOKUP($D32,CPI!$P$16:$R$22,3,FALSE) -> 650677.67 | I32: 113372 | J32: =I32/VLOOKUP($D32,CPI!$P$16:$R$22,3,FALSE) -> 134149.9 | K32: =VLOOKUP(C32,Total!A:O,10,FALSE) -> 45082
A33: =IF(ISBLANK(A$2),"",$A$2) -> 2 | B33: =B32 -> North Carolina Wilmington | C33: 199218 | D33: =IF(D32=2023,2017,D32+1) -> 2020 | E33: 0 | F33: =E33/VLOOKUP($D33,CPI!$P$16:$R$22,3,FALSE) -> 0 | G33: 583414 | H33: =G33/VLOOKUP($D33,CPI!$P$16:$R$22,3,FALSE) -> 679705.77 | I33: 103920 | J33: =I33/VLOOKUP($D33,CPI!$P$16:$R$22,3,FALSE) -> 121071.87 | K33: =VLOOKUP(C33,Total!A:O,11,FALSE) -> 44205
A34: =IF(ISBLANK(A$2),"",$A$2) -> 2 | B34: =B33 -> North Carolina Wilmington | C34: 199218 | D34: =IF(D33=2023,2017,D33+1) -> 2021 | E34: 0 | F34: =E34/VLOOKUP($D34,CPI!$P$16:$R$22,3,FALSE) -> 0 | G34: 309314 | H34: =G34/VLOOKUP($D34,CPI!$P$16:$R$22,3,FALSE) -> 352258.2 | I34: 10578 | J34: =I34/VLOOKUP($D34,CPI!$P$16:$R$22,3,FALSE) -> 12046.617 | K34: =VLOOKUP(C34,Total!A:O,12,FALSE) -> 36711
A35: =IF(ISBLANK(A$2),"",$A$2) -> 2 | B35: =B34 -> North Carolina Wilmington | C35: 199218 | D35: =IF(D34=2023,2017,D34+1) -> 2022 | E35: 0 | F35: =E35/VLOOKUP($D35,CPI!$P$16:$R$22,3,FALSE) -> 0 | G35: 514794 | H35: =G35/VLOOKUP($D35,CPI!$P$16:$R$22,3,FALSE) -> 547030.57 | I35: 65710 | J35: =I35/VLOOKUP($D35,CPI!$P$16:$R$22,3,FALSE) -> 69824.782 | K35: =VLOOKUP(C35,Total!A:O,13,FALSE) -> 57240
A36: =IF(ISBLANK(A$2),"",$A$2) -> 2 | B36: =B35 -> North Carolina Wilmington | C36: 199218 | D36: =IF(D35=2023,2017,D35+1) -> 2023 | E36: 0 | F36: =E36/VLOOKUP($D36,CPI!$P$16:$R$22,3,FALSE) -> 0 | G36: 791926 | H36: =G36/VLOOKUP($D36,CPI!$P$16:$R$22,3,FALSE) -> 791926 | I36: 106227 | J36: =I36/VLOOKUP($D36,CPI!$P$16:$R$22,3,FALSE) -> 106227 | K36: =VLOOKUP(C36,Total!A:O,14,FALSE) -> 29648
A37: =IF(ISBLANK(A$2),"",$A$2) -> 2 | B37: Oregon State | C37: 209542 | D37: =IF(D36=2023,2017,D36+1) -> 2017 | E37: 946108 | F37: =E37/VLOOKUP($D37,CPI!$P$16:$R$22,3,FALSE) -> 1168461.8 | G37: 8884197 | H37: =G37/VLOOKUP($D37,CPI!$P$16:$R$22,3,FALSE) -> 10972156 | I37: 3023142 | J37: =I37/VLOOKUP($D37,CPI!$P$16:$R$22,3,FALSE) -> 3733639.2 | K37: =VLOOKUP(C37,Total!A:O,8,FALSE) -> 480132
A38: =IF(ISBLANK(A$2),"",$A$2) -> 2 | B38: =B37 -> Oregon State | C38: 209542 | D38: =IF(D37=2023,2017,D37+1) -> 2018 | E38: 1077705 | F38: =E38/VLOOKUP($D38,CPI!$P$16:$R$22,3,FALSE) -> 1301647.4 | G38: 7695860 | H38: =G38/VLOOKUP($D38,CPI!$P$16:$R$22,3,FALSE) -> 9295026.1 | I38: 1881904 | J38: =I38/VLOOKUP($D38,CPI!$P$16:$R$22,3,FALSE) -> 2272955.4 | K38: =VLOOKUP(C38,Total!A:O,9,FALSE) -> 424599
A39: =IF(ISBLANK(A$2),"",$A$2) -> 2 | B39: =B38 -> Oregon State | C39: 209542 | D39: =IF(D38=2023,2017,D38+1) -> 2019 | E39: 1439503 | F39: =E39/VLOOKUP($D39,CPI!$P$16:$R$22,3,FALSE) -> 1703323.5 | G39: 8203013 | H39: =G39/VLOOKUP($D39,CPI!$P$16:$R$22,3,FALSE) -> 9706394.8 | I39: 1862983 | J39: =I39/VLOOKUP($D39,CPI!$P$16:$R$22,3,FALSE) -> 2204415.4 | K39: =VLOOKUP(C39,Total!A:O,10,FALSE) -> 347403
A40: =IF(ISBLANK(A$2),"",$A$2) -> 2 | B40: =B39 -> Oregon State | C40: 209542 | D40: =IF(D39=2023,2017,D39+1) -> 2020 | E40: 1007113 | F40: =E40/VLOOKUP($D40,CPI!$P$16:$R$22,3,FALSE) -> 1173335.8 | G40: 7501576 | H40: =G40/VLOOKUP($D40,CPI!$P$16:$R$22,3,FALSE) -> 8739702 | I40: 1778519 | J40: =I40/VLOOKUP($D40,CPI!$P$16:$R$22,3,FALSE) -> 2072061.4 | K40: =VLOOKUP(C40,Total!A:O,11,FALSE) -> 324109
...

Sheet Sheet2
A1: RA6 | B1: Sex | C1: Code | D1: FY | E1: unitid | F1: University | G1: Gender | H1: Sport | I1: Concessions | J1: RealConcessions | K1: AdRev | L1: RealAdRev | M1: AdExp | N1: RealAdExp | O1: Attendance
A2: 2 | B2: =IF(ISBLANK(G2),"",IF(MID(G2,1,1)="M",0,1)) -> 0 | C2: =IF(ISBLANK(H2),"",VLOOKUP(H2,Code!B:C,2,FALSE)) -> 1 | D2: 2017 | E2: 104179 | F2: Arizona | G2: Male | H2: Baseball | I2: {=IF(B2=0,INDEX('Category 14'!F:F,MATCH(C2&E2&D2,'Category 14'!B:B&'Category 14'!C:C&'Category 14'!A:A,0)),INDEX('Category 14'!G:G,MATCH(C2&E2&D2,'Category 14'!B:B&'Category 14'!C:C&'Category 14'!A:A,0)))} -> 23795 | J2: =I2/VLOOKUP($D2,CPI!$P$16:$R$22,3,FALSE) -> 29387.288 | K2: {=IF(B2=0,INDEX('Category 15'!F:F,MATCH(C2&E2&D2,'Category 15'!B:B&'Category 15'!C:C&'Category 15'!A:A,0)),INDEX('Category 15'!G:G,MATCH(C2&E2&D2,'Category 15'!B:B&'Category 31'!C:C&'Category 15'!A:A,0)))} -> 0 | L2: =K2/VLOOKUP($D2,CPI!$P$16:$R$22,3,FALSE) -> 0 | M2: {=IF(B2=0,INDEX('Category 31'!F:F,MATCH(C2&E2&D2,'Category 31'!B:B&'Category 31'!C:C&'Category 31'!A:A,0)),INDEX('Category 31'!G:G,MATCH(C2&E2&D2,'Category 31'!B:B&'Category 31'!C:C&'Category 31'!A:A,0)))} -> 0 | N2: =M2/VLOOKUP($D2,CPI!$P$16:$R$22,3,FALSE) -> 0 | O2: =VLOOKUP(E2,MBaseball!C:O,6,FALSE) -> 103896
A3: 2 | B3: =IF(ISBLANK(G3),"",IF(MID(G3,1,1)="M",0,1)) -> 0 | C3: =IF(ISBLANK(H3),"",VLOOKUP(H3,Code!B:C,2,FALSE)) -> 2 | D3: 2017 | E3: 104179 | F3: Arizona | G3: Male | H3: Basketball | I3: {=IF(B3=0,INDEX('Category 14'!F:F,MATCH(C3&E3&D3,'Category 14'!B:B&'Category 14'!C:C&'Category 14'!A:A,0)),INDEX('Category 14'!G:G,MATCH(C3&E3&D3,'Category 14'!B:B&'Category 14'!C:C&'Category 14'!A:A,0)))} -> 353895 | J3: =I3/VLOOKUP($D3,CPI!$P$16:$R$22,3,FALSE) -> 437067.21 | K3: {=IF(B3=0,INDEX('Category 15'!F:F,MATCH(C3&E3&D3,'Category 15'!B:B&'Category 15'!C:C&'Category 15'!A:A,0)),INDEX('Category 15'!G:G,MATCH(C3&E3&D3,'Category 15'!B:B&'Category 31'!C:C&'Category 15'!A:A,0)))} -> 4950066 | L3: =K3/VLOOKUP($D3,CPI!$P$16:$R$22,3,FALSE) -> 6113427.8 | M3: 0 | N3: =M3/VLOOKUP($D3,CPI!$P$16:$R$22,3,FALSE) -> 0 | O3: =VLOOKUP(E3,MBasketball!C:P,6,FALSE) -> 230560
A4: 2 | B4: =IF(ISBLANK(G4),"",IF(MID(G4,1,1)="M",0,1)) -> 0 | C4: =IF(ISBLANK(H4),"",VLOOKUP(H4,Code!B:C,2,FALSE)) -> 8 | D4: 2017 | E4: 104179 | F4: Arizona | G4: Male | H4: Football | I4: {=IF(B4=0,INDEX('Category 14'!F:F,MATCH(C4&E4&D4,'Category 14'!B:B&'Category 14'!C:C&'Category 14'!A:A,0)),INDEX('Category 14'!G:G,MATCH(C4&E4&D4,'Category 14'!B:B&'Category 14'!C:C&'Category 14'!A:A,0)))} -> 659525 | J4: =I4/VLOOKUP($D4,CPI!$P$16:$R$22,3,FALSE) -> 814526.21 | K4: {=IF(B4=0,INDEX('Category 15'!F:F,MATCH(C4&E4&D4,'Category 15'!B:B&'Category 15'!C:C&'Category 15'!A:A,0)),INDEX('Category 15'!G:G,MATCH(C4&E4&D4,'Category 15'!B:B&'Category 31'!C:C&'Category 15'!A:A,0)))} -> 4950066 | L4: =K4/VLOOKUP($D4,CPI!$P$16:$R$22,3,FALSE) -> 6113427.8 | M4: {=IF(B4=0,INDEX('Category 31'!F:F,MATCH(C4&E4&D4,'Category 31'!B:B&'Category 31'!C:C&'Category 31'!A:A,0)),INDEX('Category 31'!G:G,MATCH(C4&E4&D4,'Category 31'!B:B&'Category 31'!C:C&'Category 31'!A:A,0)))} -> 0 | N4: =M4/VLOOKUP($D4,CPI!$P$16:$R$22,3,FALSE) -> 0 | O4: =VLOOKUP(E4,MFootball!C:P,6,FALSE) -> 338017
A5: 2 | B5: =IF(ISBLANK(G5),"",IF(MID(G5,1,1)="M",0,1)) -> 0 | C5: =IF(ISBLANK(H5),"",VLOOKUP(H5,Code!B:C,2,FALSE)) -> 9 | D5: 2017 | E5: 104179 | F5: Arizona | G5: Male | H5: Golf | I5: {=IF(B5=0,INDEX('Category 14'!F:F,MATCH(C5&E5&D5,'Category 14'!B:B&'Category 14'!C:C&'Category 14'!A:A,0)),INDEX('Category 14'!G:G,MATCH(C5&E5&D5,'Category 14'!B:B&'Category 14'!C:C&'Category 14'!A:A,0)))} -> 18513 | J5: =I5/VLOOKUP($D5,CPI!$P$16:$R$22,3,FALSE) -> 22863.915 | K5: {=IF(B5=0,INDEX('Category 15'!F:F,MATCH(C5&E5&D5,'Category 15'!B:B&'Category 15'!C:C&'Category 15'!A:A,0)),INDEX('Category 15'!G:G,MATCH(C5&E5&D5,'Category 15'!B:B&'Category 31'!C:C&'Category 15'!A:A,0)))} -> 0 | L5: =K5/VLOOKUP($D5,CPI!$P$16:$R$22,3,FALSE) -> 0 | M5: {=IF(B5=0,INDEX('Category 31'!F:F,MATCH(C5&E5&D5,'Category 31'!B:B&'Category 31'!C:C&'Category 31'!A:A,0)),INDEX('Category 31'!G:G,MATCH(C5&E5&D5,'Category 31'!B:B&'Category 31'!C:C&'Category 31'!A:A,0)))} -> 0 | N5: =M5/VLOOKUP($D5,CPI!$P$16:$R$22,3,FALSE) -> 0 | O5: 0
A6: 2 | B6: =IF(ISBLANK(G6),"",IF(MID(G6,1,1)="M",0,1)) -> 0 | C6: =IF(ISBLANK(H6),"",VLOOKUP(H6,Code!B:C,2,FALSE)) -> 19 | D6: 2017 | E6: 104179 | F6: Arizona | G6: Male | H6: Swimming and Diving | I6: {=IF(B6=0,INDEX('Category 14'!F:F,MATCH(C6&E6&D6,'Category 14'!B:B&'Category 14'!C:C&'Category 14'!A:A,0)),INDEX('Category 14'!G:G,MATCH(C6&E6&D6,'Category 14'!B:B&'Category 14'!C:C&'Category 14'!A:A,0)))} -> 5787 | J6: =I6/VLOOKUP($D6,CPI!$P$16:$R$22,3,FALSE) -> 7147.0576 | K6: {=IF(B6=0,INDEX('Category 15'!F:F,MATCH(C6&E6&D6,'Category 15'!B:B&'Category 15'!C:C&'Category 15'!A:A,0)),INDEX('Category 15'!G:G,MATCH(C6&E6&D6,'Category 15'!B:B&'Category 31'!C:C&'Category 15'!A:A,0)))} -> 0 | L6: =K6/VLOOKUP($D6,CPI!$P$16:$R$22,3,FALSE) -> 0 | M6: {=IF(B6=0,INDEX('Category 31'!F:F,MATCH(C6&E6&D6,'Category 31'!B:B&'Category 31'!C:C&'Category 31'!A:A,0)),INDEX('Category 31'!G:G,MATCH(C6&E6&D6,'Category 31'!B:B&'Category 31'!C:C&'Category 31'!A:A,0)))} -> 0 | N6: =M6/VLOOKUP($D6,CPI!$P$16:$R$22,3,FALSE) -> 0 | O6: 0
A7: 2 | B7: =IF(ISBLANK(G7),"",IF(MID(G7,1,1)="M",0,1)) -> 0 | C7: =IF(ISBLANK(H7),"",VLOOKUP(H7,Code!B:C,2,FALSE)) -> 20 | D7: 2017 | E7: 104179 | F7: Arizona | G7: Male | H7: Tennis | I7: {=IF(B7=0,INDEX('Category 14'!F:F,MATCH(C7&E7&D7,'Category 14'!B:B&'Category 14'!C:C&'Category 14'!A:A,0)),INDEX('Category 14'!G:G,MATCH(C7&E7&D7,'Category 14'!B:B&'Category 14'!C:C&'Category 14'!A:A,0)))} -> 0 | J7: =I7/VLOOKUP($D7,CPI!$P$16:$R$22,3,FALSE) -> 0 | K7: {=IF(B7=0,INDEX('Category 15'!F:F,MATCH(C7&E7&D7,'Category 15'!B:B&'Category 15'!C:C&'Category 15'!A:A,0)),INDEX('Category 15'!G:G,MATCH(C7&E7&D7,'Category 15'!B:B&'Category 31'!C:C&'Category 15'!A:A,0)))} -> 0 | L7: =K7/VLOOKUP($D7,CPI!$P$16:$R$22,3,FALSE) -> 0 | M7: {=IF(B7=0,INDEX('Category 31'!F:F,MATCH(C7&E7&D7,'Category 31'!B:B&'Category 31'!C:C&'Category 31'!A:A,0)),INDEX('Category 31'!G:G,MATCH(C7&E7&D7,'Category 31'!B:B&'Category 31'!C:C&'Category 31'!A:A,0)))} -> 0 | N7: =M7/VLOOKUP($D7,CPI!$P$16:$R$22,3,FALSE) -> 0 | O7: 0
A8: 2 | B8: =IF(ISBLANK(G8),"",IF(MID(G8,1,1)="M",0,1)) -> 0 | C8: =IF(ISBLANK(H8),"",VLOOKUP(H8,Code!B:C,2,FALSE)) -> 21 | D8: 2017 | E8: 104179 | F8: Arizona | G8: Male | H8: Track and Field, X-Country | I8: {=IF(B8=0,INDEX('Category 14'!F:F,MATCH(C8&E8&D8,'Category 14'!B:B&'Category 14'!C:C&'Category 14'!A:A,0)),INDEX('Category 14'!G:G,MATCH(C8&E8&D8,'Category 14'!B:B&'Category 14'!C:C&'Category 14'!A:A,0)))} -> 15915 | J8: =I8/VLOOKUP($D8,CPI!$P$16:$R$22,3,FALSE) -> 19655.335 | K8: {=IF(B8=0,INDEX('Category 15'!F:F,MATCH(C8&E8&D8,'Category 15'!B:B&'Category 15'!C:C&'Category 15'!A:A,0)),INDEX('Category 15'!G:G,MATCH(C8&E8&D8,'Category 15'!B:B&'Category 31'!C:C&'Category 15'!A:A,0)))} -> 0 | L8: =K8/VLOOKUP($D8,CPI!$P$16:$R$22,3,FALSE) -> 0 | M8: {=IF(B8=0,INDEX('Category 31'!F:F,MATCH(C8&E8&D8,'Category 31'!B:B&'Category 31'!C:C&'Category 31'!A:A,0)),INDEX('Category 31'!G:G,MATCH(C8&E8&D8,'Category 31'!B:B&'Category 31'!C:C&'Category 31'!A:A,0)))} -> 0 | N8: =M8/VLOOKUP($D8,CPI!$P$16:$R$22,3,FALSE) -> 0 | O8: 0
A9: 2 | B9: =IF(ISBLANK(G9),"",IF(MID(G9,1,1)="M",0,1)) -> 1 | C9: =IF(ISBLANK(H9),"",VLOOKUP(H9,Code!B:C,2,FALSE)) -> 2 | D9: 2017 | E9: 104179 | F9: Arizona | G9: Female | H9: Basketball | I9: {=IF(B9=0,INDEX('Category 14'!F:F,MATCH(C9&E9&D9,'Category 14'!B:B&'Category 14'!C:C&'Category 14'!A:A,0)),INDEX('Category 14'!G:G,MATCH(C9&E9&D9,'Category 14'!B:B&'Category 14'!C:C&'Category 14'!A:A,0)))} -> 0 | J9: =I9/VLOOKUP($D9,CPI!$P$16:$R$22,3,FALSE) -> 0 | K9: {=IF(B9=0,INDEX('Category 15'!F:F,MATCH(C9&E9&D9,'Category 15'!B:B&'Category 15'!C:C&'Category 15'!A:A,0)),INDEX('Category 15'!G:G,MATCH(C9&E9&D9,'Category 15'!B:B&'Category 31'!C:C&'Category 15'!A:A,0)))} -> 0 | L9: =K9/VLOOKUP($D9,CPI!$P$16:$R$22,3,FALSE) -> 0 | M9: 0 | N9: =M9/VLOOKUP($D9,CPI!$P$16:$R$22,3,FALSE) -> 0 | O9: =VLOOKUP(E9,WBasketball!C:P,6,FALSE) -> 29422
A10: 2 | B10: =IF(ISBLANK(G10),"",IF(MID(G10,1,1)="M",0,1)) -> 1 | C10: =IF(ISBLANK(H10),"",VLOOKUP(H10,Code!B:C,2,FALSE)) -> 3 | D10: 2017 | E10: 104179 | F10: Arizona | G10: Female | H10: Beach Volleyball | I10: {=IF(B10=0,INDEX('Category 14'!F:F,MATCH(C10&E10&D10,'Category 14'!B:B&'Category 14'!C:C&'Category 14'!A:A,0)),INDEX('Category 14'!G:G,MATCH(C10&E10&D10,'Category 14'!B:B&'Category 14'!C:C&'Category 14'!A:A,0)))} -> 328 | J10: =I10/VLOOKUP($D10,CPI!$P$16:$R$22,3,FALSE) -> 405.08638 | K10: {=IF(B10=0,INDEX('Category 15'!F:F,MATCH(C10&E10&D10,'Category 15'!B:B&'Category 15'!C:C&'Category 15'!A:A,0)),INDEX('Category 15'!G:G,MATCH(C10&E10&D10,'Category 15'!B:B&'Category 31'!C:C&'Category 15'!A:A,0)))} -> 0 | L10: =K10/VLOOKUP($D10,CPI!$P$16:$R$22,3,FALSE) -> 0 | M10: {=IF(B10=0,INDEX('Category 31'!F:F,MATCH(C10&E10&D10,'Category 31'!B:B&'Category 31'!C:C&'Category 31'!A:A,0)),INDEX('Category 31'!G:G,MATCH(C10&E10&D10,'Category 31'!B:B&'Category 31'!C:C&'Category 31'!A:A,0)))} -> 0 | N10: =M10/VLOOKUP($D10,CPI!$P$16:$R$22,3,FALSE) -> 0 | O10: 0
A11: 2 | B11: =IF(ISBLANK(G11),"",IF(MID(G11,1,1)="M",0,1)) -> 1 | C11: =IF(ISBLANK(H11),"",VLOOKUP(H11,Code!B:C,2,FALSE)) -> 9 | D11: 2017 | E11: 104179 | F11: Arizona | G11: Female | H11: Golf | I11: {=IF(B11=0,INDEX('Category 14'!F:F,MATCH(C11&E11&D11,'Category 14'!B:B&'Category 14'!C:C&'Category 14'!A:A,0)),INDEX('Category 14'!G:G,MATCH(C11&E11&D11,'Category 14'!B:B&'Category 14'!C:C&'Category 14'!A:A,0)))} -> 4680 | J11: =I11/VLOOKUP($D11,CPI!$P$16:$R$22,3,FALSE) -> 5779.8911 | K11: {=IF(B11=0,INDEX('Category 15'!F:F,MATCH(C11&E11&D11,'Category 15'!B:B&'Category 15'!C:C&'Category 15'!A:A,0)),INDEX('Category 15'!G:G,MATCH(C11&E11&D11,'Category 15'!B:B&'Category 31'!C:C&'Category 15'!A:A,0)))} -> 0 | L11: =K11/VLOOKUP($D11,CPI!$P$16:$R$22,3,FALSE) -> 0 | M11: {=IF(B11=0,INDEX('Category 31'!F:F,MATCH(C11&E11&D11,'Category 31'!B:B&'Category 31'!C:C&'Category 31'!A:A,0)),INDEX('Category 31'!G:G,MATCH(C11&E11&D11,'Category 31'!B:B&'Category 31'!C:C&'Category 31'!A:A,0)))} -> 0 | N11: =M11/VLOOKUP($D11,CPI!$P$16:$R$22,3,FALSE) -> 0 | O11: 0
A12: 2 | B12: =IF(ISBLANK(G12),"",IF(MID(G12,1,1)="M",0,1)) -> 1 | C12: =IF(ISBLANK(H12),"",VLOOKUP(H12,Code!B:C,2,FALSE)) -> 10 | D12: 2017 | E12: 104179 | F12: Arizona | G12: Female | H12: Gymnastics | I12: {=IF(B12=0,INDEX('Category 14'!F:F,MATCH(C12&E12&D12,'Category 14'!B:B&'Category 14'!C:C&'Category 14'!A:A,0)),INDEX('Category 14'!G:G,MATCH(C12&E12&D12,'Category 14'!B:B&'Category 14'!C:C&'Category 14'!A:A,0)))} -> 295 | J12: =I12/VLOOKUP($D12,CPI!$P$16:$R$22,3,FALSE) -> 364.33074 | K12: {=IF(B12=0,INDEX('Category 15'!F:F,MATCH(C12&E12&D12,'Category 15'!B:B&'Category 15'!C:C&'Category 15'!A:A,0)),INDEX('Category 15'!G:G,MATCH(C12&E12&D12,'Category 15'!B:B&'Category 31'!C:C&'Category 15'!A:A,0)))} -> 0 | L12: =K12/VLOOKUP($D12,CPI!$P$16:$R$22,3,FALSE) -> 0 | M12: {=IF(B12=0,INDEX('Category 31'!F:F,MATCH(C12&E12&D12,'Category 31'!B:B&'Category 31'!C:C&'Category 31'!A:A,0)),INDEX('Category 31'!G:G,MATCH(C12&E12&D12,'Category 31'!B:B&'Category 31'!C:C&'Category 31'!A:A,0)))} -> 0 | N12: =M12/VLOOKUP($D12,CPI!$P$16:$R$22,3,FALSE) -> 0 | O12: 0
A13: 2 | B13: =IF(ISBLANK(G13),"",IF(MID(G13,1,1)="M",0,1)) -> 1 | C13: =IF(ISBLANK(H13),"",VLOOKUP(H13,Code!B:C,2,FALSE)) -> 17 | D13: 2017 | E13: 104179 | F13: Arizona | G13: Female | H13: Soccer | I13: {=IF(B13=0,INDEX('Category 14'!F:F,MATCH(C13&E13&D13,'Category 14'!B:B&'Category 14'!C:C&'Category 14'!A:A,0)),INDEX('Category 14'!G:G,MATCH(C13&E13&D13,'Category 14'!B:B&'Category 14'!C:C&'Category 14'!A:A,0)))} -> 2346 | J13: =I13/VLOOKUP($D13,CPI!$P$16:$R$22,3,FALSE) -> 2897.3557 | K13: {=IF(B13=0,INDEX('Category 15'!F:F,MATCH(C13&E13&D13,'Category 15'!B:B&'Category 15'!C:C&'Category 15'!A:A,0)),INDEX('Category 15'!G:G,MATCH(C13&E13&D13,'Category 15'!B:B&'Category 31'!C:C&'Category 15'!A:A,0)))} -> 0 | L13: =K13/VLOOKUP($D13,CPI!$P$16:$R$22,3,FALSE) -> 0 | M13: {=IF(B13=0,INDEX('Category 31'!F:F,MATCH(C13&E13&D13,'Category 31'!B:B&'Category 31'!C:C&'Category 31'!A:A,0)),INDEX('Category 31'!G:G,MATCH(C13&E13&D13,'Category 31'!B:B&'Category 31'!C:C&'Category 31'!A:A,0)))} -> 0 | N13: =M13/VLOOKUP($D13,CPI!$P$16:$R$22,3,FALSE) -> 0 | O13: =VLOOKUP(E13,WSoccer!C:P,6,FALSE) -> 5822
A14: 2 | B14: =IF(ISBLANK(G14),"",IF(MID(G14,1,1)="M",0,1)) -> 1 | C14: =IF(ISBLANK(H14),"",VLOOKUP(H14,Code!B:C,2,FALSE)) -> 18 | D14: 2017 | E14: 104179 | F14: Arizona | G14: Female | H14: Softball | I14: {=IF(B14=0,INDEX('Category 14'!F:F,MATCH(C14&E14&D14,'Category 14'!B:B&'Category 14'!C:C&'Category 14'!A:A,0)),INDEX('Category 14'!G:G,MATCH(C14&E14&D14,'Category 14'!B:B&'Category 14'!C:C&'Category 14'!A:A,0)))} -> 30388 | J14: =I14/VLOOKUP($D14,CPI!$P$16:$R$22,3,FALSE) -> 37529.771 | K14: {=IF(B14=0,INDEX('Category 15'!F:F,MATCH(C14&E14&D14,'Category 15'!B:B&'Category 15'!C:C&'Category 15'!A:A,0)),INDEX('Category 15'!G:G,MATCH(C14&E14&D14,'Category 15'!B:B&'Category 31'!C:C&'Category 15'!A:A,0)))} -> 0 | L14: =K14/VLOOKUP($D14,CPI!$P$16:$R$22,3,FALSE) -> 0 | M14: {=IF(B14=0,INDEX('Category 31'!F:F,MATCH(C14&E14&D14,'Category 31'!B:B&'Category 31'!C:C&'Category 31'!A:A,0)),INDEX('Category 31'!G:G,MATCH(C14&E14&D14,'Category 31'!B:B&'Category 31'!C:C&'Category 31'!A:A,0)))} -> 0 | N14: =M14/VLOOKUP($D14,CPI!$P$16:$R$22,3,FALSE) -> 0 | O14: =VLOOKUP(E14,WSoftball!C:P,6,FALSE) -> 66402
A15: 2 | B15: =IF(ISBLANK(G15),"",IF(MID(G15,1,1)="M",0,1)) -> 1 | C15: =IF(ISBLANK(H15),"",VLOOKUP(H15,Code!B:C,2,FALSE)) -> 19 | D15: 2017 | E15: 104179 | F15: Arizona | G15: Female | H15: Swimming and Diving | I15: {=IF(B15=0,INDEX('Category 14'!F:F,MATCH(C15&E15&D15,'Category 14'!B:B&'Category 14'!C:C&'Category 14'!A:A,0)),INDEX('Category 14'!G:G,MATCH(C15&E15&D15,'Category 14'!B:B&'Category 14'!C:C&'Category 14'!A:A,0)))} -> 8180 | J15: =I15/VLOOKUP($D15,CPI!$P$16:$R$22,3,FALSE) -> 10102.459 | K15: {=IF(B15=0,INDEX('Category 15'!F:F,MATCH(C15&E15&D15,'Category 15'!B:B&'Category 15'!C:C&'Category 15'!A:A,0)),INDEX('Category 15'!G:G,MATCH(C15&E15&D15,'Category 15'!B:B&'Category 31'!C:C&'Category 15'!A:A,0)))} -> 0 | L15: =K15/VLOOKUP($D15,CPI!$P$16:$R$22,3,FALSE) -> 0 | M15: {=IF(B15=0,INDEX('Category 31'!F:F,MATCH(C15&E15&D15,'Category 31'!B:B&'Category 31'!C:C&'Category 31'!A:A,0)),INDEX('Category 31'!G:G,MATCH(C15&E15&D15,'Category 31'!B:B&'Category 31'!C:C&'Category 31'!A:A,0)))} -> 0 | N15: =M15/VLOOKUP($D15,CPI!$P$16:$R$22,3,FALSE) -> 0 | O15: 0
A16: 2 | B16: =IF(ISBLANK(G16),"",IF(MID(G16,1,1)="M",0,1)) -> 1 | C16: =IF(ISBLANK(H16),"",VLOOKUP(H16,Code!B:C,2,FALSE)) -> 20 | D16: 2017 | E16: 104179 | F16: Arizona | G16: Female | H16: Tennis | I16: {=IF(B16=0,INDEX('Category 14'!F:F,MATCH(C16&E16&D16,'Category 14'!B:B&'Category 14'!C:C&'Category 14'!A:A,0)),INDEX('Category 14'!G:G,MATCH(C16&E16&D16,'Category 14'!B:B&'Category 14'!C:C&'Category 14'!A:A,0)))} -> 12187 | J16: =I16/VLOOKUP($D16,CPI!$P$16:$R$22,3,FALSE) -> 15051.182 | K16: {=IF(B16=0,INDEX('Category 15'!F:F,MATCH(C16&E16&D16,'Category 15'!B:B&'Category 15'!C:C&'Category 15'!A:A,0)),INDEX('Category 15'!G:G,MATCH(C16&E16&D16,'Category 15'!B:B&'Category 31'!C:C&'Category 15'!A:A,0)))} -> 0 | L16: =K16/VLOOKUP($D16,CPI!$P$16:$R$22,3,FALSE) -> 0 | M16: {=IF(B16=0,INDEX('Category 31'!F:F,MATCH(C16&E16&D16,'Category 31'!B:B&'Category 31'!C:C&'Category 31'!A:A,0)),INDEX('Category 31'!G:G,MATCH(C16&E16&D16,'Category 31'!B:B&'Category 31'!C:C&'Category 31'!A:A,0)))} -> 0 | N16: =M16/VLOOKUP($D16,CPI!$P$16:$R$22,3,FALSE) -> 0 | O16: 0
A17: 2 | B17: =IF(ISBLANK(G17),"",IF(MID(G17,1,1)="M",0,1)) -> 1 | C17: =IF(ISBLANK(H17),"",VLOOKUP(H17,Code!B:C,2,FALSE)) -> 21 | D17: 2017 | E17: 104179 | F17: Arizona | G17: Female | H17: Track and Field, X-Country | I17: {=IF(B17=0,INDEX('Category 14'!F:F,MATCH(C17&E17&D17,'Category 14'!B:B&'Category 14'!C:C&'Category 14'!A:A,0)),INDEX('Category 14'!G:G,MATCH(C17&E17&D17,'Category 14'!B:B&'Category 14'!C:C&'Category 14'!A:A,0)))} -> 9702 | J17: =I17/VLOOKUP($D17,CPI!$P$16:$R$22,3,FALSE) -> 11982.159 | K17: {=IF(B17=0,INDEX('Category 15'!F:F,MATCH(C17&E17&D17,'Category 15'!B:B&'Category 15'!C:C&'Category 15'!A:A,0)),INDEX('Category 15'!G:G,MATCH(C17&E17&D17,'Category 15'!B:B&'Category 31'!C:C&'Category 15'!A:A,0)))} -> 0 | L17: =K17/VLOOKUP($D17,CPI!$P$16:$R$22,3,FALSE) -> 0 | M17: {=IF(B17=0,INDEX('Category 31'!F:F,MATCH(C17&E17&D17,'Category 31'!B:B&'Category 31'!C:C&'Category 31'!A:A,0)),INDEX('Category 31'!G:G,MATCH(C17&E17&D17,'Category 31'!B:B&'Category 31'!C:C&'Category 31'!A:A,0)))} -> 0 | N17: =M17/VLOOKUP($D17,CPI!$P$16:$R$22,3,FALSE) -> 0 | O17: 0
A18: 2 | B18: =IF(ISBLANK(G18),"",IF(MID(G18,1,1)="M",0,1)) -> 1 | C18: =IF(ISBLANK(H18),"",VLOOKUP(H18,Code!B:C,2,FALSE)) -> 23 | D18: 2017 | E18: 104179 | F18: Arizona | G18: Female | H18: Volleyball | I18: {=IF(B18=0,INDEX('Category 14'!F:F,MATCH(C18&E18&D18,'Category 14'!B:B&'Category 14'!C:C&'Category 14'!A:A,0)),INDEX('Category 14'!G:G,MATCH(C18&E18&D18,'Category 14'!B:B&'Category 14'!C:C&'Category 14'!A:A,0)))} -> 19455 | J18: =I18/VLOOKUP($D18,CPI!$P$16:$R$22,3,FALSE) -> 24027.304 | K18: {=IF(B18=0,INDEX('Category 15'!F:F,MATCH(C18&E18&D18,'Category 15'!B:B&'Category 15'!C:C&'Category 15'!A:A,0)),INDEX('Category 15'!G:G,MATCH(C18&E18&D18,'Category 15'!B:B&'Category 31'!C:C&'Category 15'!A:A,0)))} -> 0 | L18: =K18/VLOOKUP($D18,CPI!$P$16:$R$22,3,FALSE) -> 0 | M18: {=IF(B18=0,INDEX('Category 31'!F:F,MATCH(C18&E18&D18,'Category 31'!B:B&'Category 31'!C:C&'Category 31'!A:A,0)),INDEX('Category 31'!G:G,MATCH(C18&E18&D18,'Category 31'!B:B&'Category 31'!C:C&'Category 31'!A:A,0)))} -> 0 | N18: =M18/VLOOKUP($D18,CPI!$P$16:$R$22,3,FALSE) -> 0 | O18: =VLOOKUP(E18,WVolleyball!C:P,6,FALSE) -> 18595
A19: 2 | B19: =IF(ISBLANK(G19),"",IF(MID(G19,1,1)="M",0,1)) -> 0 | C19: =IF(ISBLANK(H19),"",VLOOKUP(H19,Code!B:C,2,FALSE)) -> 1 | D19: 2018 | E19: 104179 | F19: Arizona | G19: Male | H19: Baseball | I19: {=IF(B19=0,INDEX('Category 14'!F:F,MATCH(C19&E19&D19,'Category 14'!B:B&'Category 14'!C:C&'Category 14'!A:A,0)),INDEX('Category 14'!G:G,MATCH(C19&E19&D19,'Category 14'!B:B&'Category 14'!C:C&'Category 14'!A:A,0)))} -> 2150 | J19: =I19/VLOOKUP($D19,CPI!$P$16:$R$22,3,FALSE) -> 2596.7606 | K19: {=IF(B19=0,INDEX('Category 15'!F:F,MATCH(C19&E19&D19,'Category 15'!B:B&'Category 15'!C:C&'Category 15'!A:A,0)),INDEX('Category 15'!G:G,MATCH(C19&E19&D19,'Category 15'!B:B&'Category 31'!C:C&'Category 15'!A:A,0)))} -> 0 | L19: =K19/VLOOKUP($D19,CPI!$P$16:$R$22,3,FALSE) -> 0 | M19: {=IF(B19=0,INDEX('Category 31'!F:F,MATCH(C19&E19&D19,'Category 31'!B:B&'Category 31'!C:C&'Category 31'!A:A,0)),INDEX('Category 31'!G:G,MATCH(C19&E19&D19,'Category 31'!B:B&'Category 31'!C:C&'Category 31'!A:A,0)))} -> 0 | N19: =M19/VLOOKUP($D19,CPI!$P$16:$R$22,3,FALSE) -> 0 | O19: 93511
A20: 2 | B20: =IF(ISBLANK(G20),"",IF(MID(G20,1,1)="M",0,1)) -> 0 | C20: =IF(ISBLANK(H20),"",VLOOKUP(H20,Code!B:C,2,FALSE)) -> 2 | D20: 2018 | E20: 104179 | F20: Arizona | G20: Male | H20: Basketball | I20: {=IF(B20=0,INDEX('Category 14'!F:F,MATCH(C20&E20&D20,'Category 14'!B:B&'Category 14'!C:C&'Category 14'!A:A,0)),INDEX('Category 14'!G:G,MATCH(C20&E20&D20,'Category 14'!B:B&'Category 14'!C:C&'Category 14'!A:A,0)))} -> 166804 | J20: =I20/VLOOKUP($D20,CPI!$P$16:$R$22,3,FALSE) -> 201465.14 | K20: {=IF(B20=0,INDEX('Category 15'!F:F,MATCH(C20&E20&D20,'Category 15'!B:B&'Category 15'!C:C&'Category 15'!A:A,0)),INDEX('Category 15'!G:G,MATCH(C20&E20&D20,'Category 15'!B:B&'Category 31'!C:C&'Category 15'!A:A,0)))} -> 4432881 | L20: =K20/VLOOKUP($D20,CPI!$P$16:$R$22,3,FALSE) -> 5354014.3 | M20: {=IF(B20=0,INDEX('Category 31'!F:F,MATCH(C20&E20&D20,'Category 31'!B:B&'Category 31'!C:C&'Category 31'!A:A,0)),INDEX('Category 31'!G:G,MATCH(C20&E20&D20,'Category 31'!B:B&'Category 31'!C:C&'Category 31'!A:A,0)))} -> 0 | N20: =M20/VLOOKUP($D20,CPI!$P$16:$R$22,3,FALSE) -> 0 | O20: =VLOOKUP(E3,MBasketball!C:P,7,FALSE) -> 230947
A21: 2 | B21: =IF(ISBLANK(G21),"",IF(MID(G21,1,1)="M",0,1)) -> 0 | C21: =IF(ISBLANK(H21),"",VLOOKUP(H21,Code!B:C,2,FALSE)) -> 8 | D21: 2018 | E21: 104179 | F21: Arizona | G21: Male | H21: Football | I21: {=IF(B21=0,INDEX('Category 14'!F:F,MATCH(C21&E21&D21,'Category 14'!B:B&'Category 14'!C:C&'Category 14'!A:A,0)),INDEX('Category 14'!G:G,MATCH(C21&E21&D21,'Category 14'!B:B&'Category 14'!C:C&'Category 14'!A:A,0)))} -> 592731 | J21: =I21/VLOOKUP($D21,CPI!$P$16:$R$22,3,FALSE) -> 715897.92 | K21: {=IF(B21=0,INDEX('Category 15'!F:F,MATCH(C21&E21&D21,'Category 15'!B:B&'Category 15'!C:C&'Category 15'!A:A,0)),INDEX('Category 15'!G:G,MATCH(C21&E21&D21,'Category 15'!B:B&'Category 31'!C:C&'Category 15'!A:A,0)))} -> 4432880 | L21: =K21/VLOOKUP($D21,CPI!$P$16:$R$22,3,FALSE) -> 5354013.1 | M21: {=IF(B21=0,INDEX('Category 31'!F:F,MATCH(C21&E21&D21,'Category 31'!B:B&'Category 31'!C:C&'Category 31'!A:A,0)),INDEX('Category 31'!G:G,MATCH(C21&E21&D21,'Category 31'!B:B&'Category 31'!C:C&'Category 31'!A:A,0)))} -> 0 | N21: =M21/VLOOKUP($D21,CPI!$P$16:$R$22,3,FALSE) -> 0 | O21: =VLOOKUP(E4,MFootball!C:P,7,FALSE) -> 255791
A22: 2 | B22: =IF(ISBLANK(G22),"",IF(MID(G22,1,1)="M",0,1)) -> 0 | C22: =IF(ISBLANK(H22),"",VLOOKUP(H22,Code!B:C,2,FALSE)) -> 9 | D22: 2018 | E22: 104179 | F22: Arizona | G22: Male | H22: Golf | I22: {=IF(B22=0,INDEX('Category 14'!F:F,MATCH(C22&E22&D22,'Category 14'!B:B&'Category 14'!C:C&'Category 14'!A:A,0)),INDEX('Category 14'!G:G,MATCH(C22&E22&D22,'Category 14'!B:B&'Category 14'!C:C&'Category 14'!A:A,0)))} -> 32700 | J22: =I22/VLOOKUP($D22,CPI!$P$16:$R$22,3,FALSE) -> 39494.917 | K22: {=IF(B22=0,INDEX('Category 15'!F:F,MATCH(C22&E22&D22,'Category 15'!B:B&'Category 15'!C:C&'Category 15'!A:A,0)),INDEX('Category 15'!G:G,MATCH(C22&E22&D22,'Category 15'!B:B&'Category 31'!C:C&'Category 15'!A:A,0)))} -> 0 | L22: =K22/VLOOKUP($D22,CPI!$P$16:$R$22,3,FALSE) -> 0 | M22: {=IF(B22=0,INDEX('Category 31'!F:F,MATCH(C22&E22&D22,'Category 31'!B:B&'Category 31'!C:C&'Category 31'!A:A,0)),INDEX('Category 31'!G:G,MATCH(C22&E22&D22,'Category 31'!B:B&'Category 31'!C:C&'Category 31'!A:A,0)))} -> 0 | N22: =M22/VLOOKUP($D22,CPI!$P$16:$R$22,3,FALSE) -> 0 | O22: 0
A23: 2 | B23: =IF(ISBLANK(G23),"",IF(MID(G23,1,1)="M",0,1)) -> 0 | C23: =IF(ISBLANK(H23),"",VLOOKUP(H23,Code!B:C,2,FALSE)) -> 19 | D23: 2018 | E23: 104179 | F23: Arizona | G23: Male | H23: Swimming and Diving | I23: {=IF(B23=0,INDEX('Category 14'!F:F,MATCH(C23&E23&D23,'Category 14'!B:B&'Category 14'!C:C&'Category 14'!A:A,0)),INDEX('Category 14'!G:G,MATCH(C23&E23&D23,'Category 14'!B:B&'Category 14'!C:C&'Category 14'!A:A,0)))} -> 1296 | J23: =I23/VLOOKUP($D23,CPI!$P$16:$R$22,3,FALSE) -> 1565.3031 | K23: {=IF(B23=0,INDEX('Category 15'!F:F,MATCH(C23&E23&D23,'Category 15'!B:B&'Category 15'!C:C&'Category 15'!A:A,0)),INDEX('Category 15'!G:G,MATCH(C23&E23&D23,'Category 15'!B:B&'Category 31'!C:C&'Category 15'!A:A,0)))} -> 0 | L23: =K23/VLOOKUP($D23,CPI!$P$16:$R$22,3,FALSE) -> 0 | M23: {=IF(B23=0,INDEX('Category 31'!F:F,MATCH(C23&E23&D23,'Category 31'!B:B&'Category 31'!C:C&'Category 31'!A:A,0)),INDEX('Category 31'!G:G,MATCH(C23&E23&D23,'Category 31'!B:B&'Category 31'!C:C&'Category 31'!A:A,0)))} -> 0 | N23: =M23/VLOOKUP($D23,CPI!$P$16:$R$22,3,FALSE) -> 0 | O23: 0
A24: 2 | B24: =IF(ISBLANK(G24),"",IF(MID(G24,1,1)="M",0,1)) -> 0 | C24: =IF(ISBLANK(H24),"",VLOOKUP(H24,Code!B:C,2,FALSE)) -> 20 | D24: 2018 | E24: 104179 | F24: Arizona | G24: Male | H24: Tennis | I24: {=IF(B24=0,INDEX('Category 14'!F:F,MATCH(C24&E24&D24,'Category 14'!B:B&'Category 14'!C:C&'Category 14'!A:A,0)),INDEX('Category 14'!G:G,MATCH(C24&E24&D24,'Category 14'!B:B&'Category 14'!C:C&'Category 14'!A:A,0)))} -> 0 | J24: =I24/VLOOKUP($D24,CPI!$P$16:$R$22,3,FALSE) -> 0 | K24: {=IF(B24=0,INDEX('Category 15'!F:F,MATCH(C24&E24&D24,'Category 15'!B:B&'Category 15'!C:C&'Category 15'!A:A,0)),INDEX('Category 15'!G:G,MATCH(C24&E24&D24,'Category 15'!B:B&'Category 31'!C:C&'Category 15'!A:A,0)))} -> 0 | L24: =K24/VLOOKUP($D24,CPI!$P$16:$R$22,3,FALSE) -> 0 | M24: {=IF(B24=0,INDEX('Category 31'!F:F,MATCH(C24&E24&D24,'Category 31'!B:B&'Category 31'!C:C&'Category 31'!A:A,0)),INDEX('Category 31'!G:G,MATCH(C24&E24&D24,'Category 31'!B:B&'Category 31'!C:C&'Category 31'!A:A,0)))} -> 0 | N24: =M24/VLOOKUP($D24,CPI!$P$16:$R$22,3,FALSE) -> 0 | O24: 0
A25: 2 | B25: =IF(ISBLANK(G25),"",IF(MID(G25,1,1)="M",0,1)) -> 0 | C25: =IF(ISBLANK(H25),"",VLOOKUP(H25,Code!B:C,2,FALSE)) -> 21 | D25: 2018 | E25: 104179 | F25: Arizona | G25: Male | H25: Track and Field, X-Country | I25: {=IF(B25=0,INDEX('Category 14'!F:F,MATCH(C25&E25&D25,'Category 14'!B:B&'Category 14'!C:C&'Category 14'!A:A,0)),INDEX('Category 14'!G:G,MATCH(C25&E25&D25,'Category 14'!B:B&'Category 14'!C:C&'Category 14'!A:A,0)))} -> 11082 | J25: =I25/VLOOKUP($D25,CPI!$P$16:$R$22,3,FALSE) -> 13384.791 | K25: {=IF(B25=0,INDEX('Category 15'!F:F,MATCH(C25&E25&D25,'Category 15'!B:B&'Category 15'!C:C&'Category 15'!A:A,0)),INDEX('Category 15'!G:G,MATCH(C25&E25&D25,'Category 15'!B:B&'Category 31'!C:C&'Category 15'!A:A,0)))} -> 0 | L25: =K25/VLOOKUP($D25,CPI!$P$16:$R$22,3,FALSE) -> 0 | M25: {=IF(B25=0,INDEX('Category 31'!F:F,MATCH(C25&E25&D25,'Category 31'!B:B&'Category 31'!C:C&'Category 31'!A:A,0)),INDEX('Category 31'!G:G,MATCH(C25&E25&D25,'Category 31'!B:B&'Category 31'!C:C&'Category 31'!A:A,0)))} -> 0 | N25: =M25/VLOOKUP($D25,CPI!$P$16:$R$22,3,FALSE) -> 0 | O25: 0
A26: 2 | B26: =IF(ISBLANK(G26),"",IF(MID(G26,1,1)="M",0,1)) -> 1 | C26: =IF(ISBLANK(H26),"",VLOOKUP(H26,Code!B:C,2,FALSE)) -> 2 | D26: 2018 | E26: 104179 | F26: Arizona | G26: Female | H26: Basketball | I26: {=IF(B26=0,INDEX('Category 14'!F:F,MATCH(C26&E26&D26,'Category 14'!B:B&'Category 14'!C:C&'Category 14'!A:A,0)),INDEX('Category 14'!G:G,MATCH(C26&E26&D26,'Category 14'!B:B&'Category 14'!C:C&'Category 14'!A:A,0)))} -> 0 | J26: =I26/VLOOKUP($D26,CPI!$P$16:$R$22,3,FALSE) -> 0 | K26: {=IF(B26=0,INDEX('Category 15'!F:F,MATCH(C26&E26&D26,'Category 15'!B:B&'Category 15'!C:C&'Category 15'!A:A,0)),INDEX('Category 15'!G:G,MATCH(C26&E26&D26,'Category 15'!B:B&'Category 31'!C:C&'Category 15'!A:A,0)))} -> 0 | L26: =K26/VLOOKUP($D26,CPI!$P$16:$R$22,3,FALSE) -> 0 | M26: {=IF(B26=0,INDEX('Category 31'!F:F,MATCH(C26&E26&D26,'Category 31'!B:B&'Category 31'!C:C&'Category 31'!A:A,0)),INDEX('Category 31'!G:G,MATCH(C26&E26&D26,'Category 31'!B:B&'Category 31'!C:C&'Category 31'!A:A,0)))} -> 0 | N26: =M26/VLOOKUP($D26,CPI!$P$16:$R$22,3,FALSE) -> 0 | O26: =VLOOKUP(E26,WBasketball!C:P,7,FALSE) -> 28988
A27: 2 | B27: =IF(ISBLANK(G27),"",IF(MID(G27,1,1)="M",0,1)) -> 1 | C27: =IF(ISBLANK(H27),"",VLOOKUP(H27,Code!B:C,2,FALSE)) -> 3 | D27: 2018 | E27: 104179 | F27: Arizona | G27: Female | H27: Beach Volleyball | I27: {=IF(B27=0,INDEX('Category 14'!F:F,MATCH(C27&E27&D27,'Category 14'!B:B&'Category 14'!C:C&'Category 14'!A:A,0)),INDEX('Category 14'!G:G,MATCH(C27&E27&D27,'Category 14'!B:B&'Category 14'!C:C&'Category 14'!A:A,0)))} -> 0 | J27: =I27/VLOOKUP($D27,CPI!$P$16:$R$22,3,FALSE) -> 0 | K27: {=IF(B27=0,INDEX('Category 15'!F:F,MATCH(C27&E27&D27,'Category 15'!B:B&'Category 15'!C:C&'Category 15'!A:A,0)),INDEX('Category 15'!G:G,MATCH(C27&E27&D27,'Category 15'!B:B&'Category 31'!C:C&'Category 15'!A:A,0)))} -> 0 | L27: =K27/VLOOKUP($D27,CPI!$P$16:$R$22,3,FALSE) -> 0 | M27: {=IF(B27=0,INDEX('Category 31'!F:F,MATCH(C27&E27&D27,'Category 31'!B:B&'Category 31'!C:C&'Category 31'!A:A,0)),INDEX('Category 31'!G:G,MATCH(C27&E27&D27,'Category 31'!B:B&'Category 31'!C:C&'Category 31'!A:A,0)))} -> 0 | N27: =M27/VLOOKUP($D27,CPI!$P$16:$R$22,3,FALSE) -> 0 | O27: 0
A28: 2 | B28: =IF(ISBLANK(G28),"",IF(MID(G28,1,1)="M",0,1)) -> 1 | C28: =IF(ISBLANK(H28),"",VLOOKUP(H28,Code!B:C,2,FALSE)) -> 9 | D28: 2018 | E28: 104179 | F28: Arizona | G28: Female | H28: Golf | I28: {=IF(B28=0,INDEX('Category 14'!F:F,MATCH(C28&E28&D28,'Category 14'!B:B&'Category 14'!C:C&'Category 14'!A:A,0)),INDEX('Category 14'!G:G,MATCH(C28&E28&D28,'Category 14'!B:B&'Category 14'!C:C&'Category 14'!A:A,0)))} -> 11085 | J28: =I28/VLOOKUP($D28,CPI!$P$16:$R$22,3,FALSE) -> 13388.415 | K28: {=IF(B28=0,INDEX('Category 15'!F:F,MATCH(C28&E28&D28,'Category 15'!B:B&'Category 15'!C:C&'Category 15'!A:A,0)),INDEX('Category 15'!G:G,MATCH(C28&E28&D28,'Category 15'!B:B&'Category 31'!C:C&'Category 15'!A:A,0)))} -> 0 | L28: =K28/VLOOKUP($D28,CPI!$P$16:$R$22,3,FALSE) -> 0 | M28: {=IF(B28=0,INDEX('Category 31'!F:F,MATCH(C28&E28&D28,'Category 31'!B:B&'Category 31'!C:C&'Category 31'!A:A,0)),INDEX('Category 31'!G:G,MATCH(C28&E28&D28,'Category 31'!B:B&'Category 31'!C:C&'Category 31'!A:A,0)))} -> 0 | N28: =M28/VLOOKUP($D28,CPI!$P$16:$R$22,3,FALSE) -> 0 | O28: 0
A29: 2 | B29: =IF(ISBLANK(G29),"",IF(MID(G29,1,1)="M",0,1)) -> 1 | C29: =IF(ISBLANK(H29),"",VLOOKUP(H29,Code!B:C,2,FALSE)) -> 10 | D29: 2018 | E29: 104179 | F29: Arizona | G29: Female | H29: Gymnastics | I29: {=IF(B29=0,INDEX('Category 14'!F:F,MATCH(C29&E29&D29,'Category 14'!B:B&'Category 14'!C:C&'Category 14'!A:A,0)),INDEX('Category 14'!G:G,MATCH(C29&E29&D29,'Category 14'!B:B&'Category 14'!C:C&'Category 14'!A:A,0)))} -> 1937 | J29: =I29/VLOOKUP($D29,CPI!$P$16:$R$22,3,FALSE) -> 2339.5001 | K29: {=IF(B29=0,INDEX('Category 15'!F:F,MATCH(C29&E29&D29,'Category 15'!B:B&'Category 15'!C:C&'Category 15'!A:A,0)),INDEX('Category 15'!G:G,MATCH(C29&E29&D29,'Category 15'!B:B&'Category 31'!C:C&'Category 15'!A:A,0)))} -> 0 | L29: =K29/VLOOKUP($D29,CPI!$P$16:$R$22,3,FALSE) -> 0 | M29: {=IF(B29=0,INDEX('Category 31'!F:F,MATCH(C29&E29&D29,'Category 31'!B:B&'Category 31'!C:C&'Category 31'!A:A,0)),INDEX('Category 31'!G:G,MATCH(C29&E29&D29,'Category 31'!B:B&'Category 31'!C:C&'Category 31'!A:A,0)))} -> 0 | N29: =M29/VLOOKUP($D29,CPI!$P$16:$R$22,3,FALSE) -> 0 | O29: 0
A30: 2 | B30: =IF(ISBLANK(G30),"",IF(MID(G30,1,1)="M",0,1)) -> 1 | C30: =IF(ISBLANK(H30),"",VLOOKUP(H30,Code!B:C,2,FALSE)) -> 17 | D30: 2018 | E30: 104179 | F30: Arizona | G30: Female | H30: Soccer | I30: {=IF(B30=0,INDEX('Category 14'!F:F,MATCH(C30&E30&D30,'Category 14'!B:B&'Category 14'!C:C&'Category 14'!A:A,0)),INDEX('Category 14'!G:G,MATCH(C30&E30&D30,'Category 14'!B:B&'Category 14'!C:C&'Category 14'!A:A,0)))} -> 2300 | J30: =I30/VLOOKUP($D30,CPI!$P$16:$R$22,3,FALSE) -> 2777.93 | K30: {=IF(B30=0,INDEX('Category 15'!F:F,MATCH(C30&E30&D30,'Category 15'!B:B&'Category 15'!C:C&'Category 15'!A:A,0)),INDEX('Category 15'!G:G,MATCH(C30&E30&D30,'Category 15'!B:B&'Category 31'!C:C&'Category 15'!A:A,0)))} -> 0 | L30: =K30/VLOOKUP($D30,CPI!$P$16:$R$22,3,FALSE) -> 0 | M30: {=IF(B30=0,INDEX('Category 31'!F:F,MATCH(C30&E30&D30,'Category 31'!B:B&'Category 31'!C:C&'Category 31'!A:A,0)),INDEX('Category 31'!G:G,MATCH(C30&E30&D30,'Category 31'!B:B&'Category 31'!C:C&'Category 31'!A:A,0)))} -> 0 | N30: =M30/VLOOKUP($D30,CPI!$P$16:$R$22,3,FALSE) -> 0 | O30: =VLOOKUP(E30,WSoccer!C:P,7,FALSE) -> 7125
A31: 2 | B31: =IF(ISBLANK(G31),"",IF(MID(G31,1,1)="M",0,1)) -> 1 | C31: =IF(ISBLANK(H31),"",VLOOKUP(H31,Code!B:C,2,FALSE)) -> 18 | D31: 2018 | E31: 104179 | F31: Arizona | G31: Female | H31: Softball | I31: {=IF(B31=0,INDEX('Category 14'!F:F,MATCH(C31&E31&D31,'Category 14'!B:B&'Category 14'!C:C&'Category 14'!A:A,0)),INDEX('Category 14'!G:G,MATCH(C31&E31&D31,'Category 14'!B:B&'Category 14'!C:C&'Category 14'!A:A,0)))} -> 0 | J31: =I31/VLOOKUP($D31,CPI!$P$16:$R$22,3,FALSE) -> 0 | K31: {=IF(B31=0,INDEX('Category 15'!F:F,MATCH(C31&E31&D31,'Category 15'!B:B&'Category 15'!C:C&'Category 15'!A:A,0)),INDEX('Category 15'!G:G,MATCH(C31&E31&D31,'Category 15'!B:B&'Category 31'!C:C&'Category 15'!A:A,0)))} -> 0 | L31: =K31/VLOOKUP($D31,CPI!$P$16:$R$22,3,FALSE) -> 0 | M31: {=IF(B31=0,INDEX('Category 31'!F:F,MATCH(C31&E31&D31,'Category 31'!B:B&'Category 31'!C:C&'Category 31'!A:A,0)),INDEX('Category 31'!G:G,MATCH(C31&E31&D31,'Category 31'!B:B&'Category 31'!C:C&'Category 31'!A:A,0)))} -> 0 | N31: =M31/VLOOKUP($D31,CPI!$P$16:$R$22,3,FALSE) -> 0 | O31: =VLOOKUP(E31,WSoftball!C:P,7,FALSE) -> 57769
A32: 2 | B32: =IF(ISBLANK(G32),"",IF(MID(G32,1,1)="M",0,1)) -> 1 | C32: =IF(ISBLANK(H32),"",VLOOKUP(H32,Code!B:C,2,FALSE)) -> 19 | D32: 2018 | E32: 104179 | F32: Arizona | G32: Female | H32: Swimming and Diving | I32: {=IF(B32=0,INDEX('Category 14'!F:F,MATCH(C32&E32&D32,'Category 14'!B:B&'Category 14'!C:C&'Category 14'!A:A,0)),INDEX('Category 14'!G:G,MATCH(C32&E32&D32,'Category 14'!B:B&'Category 14'!C:C&'Category 14'!A:A,0)))} -> 1121 | J32: =I32/VLOOKUP($D32,CPI!$P$16:$R$22,3,FALSE) -> 1353.9389 | K32: {=IF(B32=0,INDEX('Category 15'!F:F,MATCH(C32&E32&D32,'Category 15'!B:B&'Category 15'!C:C&'Category 15'!A:A,0)),INDEX('Category 15'!G:G,MATCH(C32&E32&D32,'Category 15'!B:B&'Category 31'!C:C&'Category 15'!A:A,0)))} -> 0 | L32: =K32/VLOOKUP($D32,CPI!$P$16:$R$22,3,FALSE) -> 0 | M32: {=IF(B32=0,INDEX('Category 31'!F:F,MATCH(C32&E32&D32,'Category 31'!B:B&'Category 31'!C:C&'Category 31'!A:A,0)),INDEX('Category 31'!G:G,MATCH(C32&E32&D32,'Category 31'!B:B&'Category 31'!C:C&'Category 31'!A:A,0)))} -> 0 | N32: =M32/VLOOKUP($D32,CPI!$P$16:$R$22,3,FALSE) -> 0 | O32: 0
A33: 2 | B33: =IF(ISBLANK(G33),"",IF(MID(G33,1,1)="M",0,1)) -> 1 | C33: =IF(ISBLANK(H33),"",VLOOKUP(H33,Code!B:C,2,FALSE)) -> 20 | D33: 2018 | E33: 104179 | F33: Arizona | G33: Female | H33: Tennis | I33: {=IF(B33=0,INDEX('Category 14'!F:F,MATCH(C33&E33&D33,'Category 14'!B:B&'Category 14'!C:C&'Category 14'!A:A,0)),INDEX('Category 14'!G:G,MATCH(C33&E33&D33,'Category 14'!B:B&'Category 14'!C:C&'Category 14'!A:A,0)))} -> 870 | J33: =I33/VLOOKUP($D33,CPI!$P$16:$R$22,3,FALSE) -> 1050.7822 | K33: {=IF(B33=0,INDEX('Category 15'!F:F,MATCH(C33&E33&D33,'Category 15'!B:B&'Category 15'!C:C&'Category 15'!A:A,0)),INDEX('Category 15'!G:G,MATCH(C33&E33&D33,'Category 15'!B:B&'Category 31'!C:C&'Category 15'!A:A,0)))} -> 0 | L33: =K33/VLOOKUP($D33,CPI!$P$16:$R$22,3,FALSE) -> 0 | M33: {=IF(B33=0,INDEX('Category 31'!F:F,MATCH(C33&E33&D33,'Category 31'!B:B&'Category 31'!C:C&'Category 31'!A:A,0)),INDEX('Category 31'!G:G,MATCH(C33&E33&D33,'Category 31'!B:B&'Category 31'!C:C&'Category 31'!A:A,0)))} -> 0 | N33: =M33/VLOOKUP($D33,CPI!$P$16:$R$22,3,FALSE) -> 0 | O33: 0
A34: 2 | B34: =IF(ISBLANK(G34),"",IF(MID(G34,1,1)="M",0,1)) -> 1 | C34: =IF(ISBLANK(H34),"",VLOOKUP(H34,Code!B:C,2,FALSE)) -> 21 | D34: 2018 | E34: 104179 | F34: Arizona | G34: Female | H34: Track and Field, X-Country | I34: {=IF(B34=0,INDEX('Category 14'!F:F,MATCH(C34&E34&D34,'Category 14'!B:B&'Category 14'!C:C&'Category 14'!A:A,0)),INDEX('Category 14'!G:G,MATCH(C34&E34&D34,'Category 14'!B:B&'Category 14'!C:C&'Category 14'!A:A,0)))} -> 10223 | J34: =I34/VLOOKUP($D34,CPI!$P$16:$R$22,3,FALSE) -> 12347.295 | K34: {=IF(B34=0,INDEX('Category 15'!F:F,MATCH(C34&E34&D34,'Category 15'!B:B&'Category 15'!C:C&'Category 15'!A:A,0)),INDEX('Category 15'!G:G,MATCH(C34&E34&D34,'Category 15'!B:B&'Category 31'!C:C&'Category 15'!A:A,0)))} -> 0 | L34: =K34/VLOOKUP($D34,CPI!$P$16:$R$22,3,FALSE) -> 0 | M34: {=IF(B34=0,INDEX('Category 31'!F:F,MATCH(C34&E34&D34,'Category 31'!B:B&'Category 31'!C:C&'Category 31'!A:A,0)),INDEX('Category 31'!G:G,MATCH(C34&E34&D34,'Category 31'!B:B&'Category 31'!C:C&'Category 31'!A:A,0)))} -> 0 | N34: =M34/VLOOKUP($D34,CPI!$P$16:$R$22,3,FALSE) -> 0 | O34: 0
A35: 2 | B35: =IF(ISBLANK(G35),"",IF(MID(G35,1,1)="M",0,1)) -> 1 | C35: =IF(ISBLANK(H35),"",VLOOKUP(H35,Code!B:C,2,FALSE)) -> 23 | D35: 2018 | E35: 104179 | F35: Arizona | G35: Female | H35: Volleyball | I35: {=IF(B35=0,INDEX('Category 14'!F:F,MATCH(C35&E35&D35,'Category 14'!B:B&'Category 14'!C:C&'Category 14'!A:A,0)),INDEX('Category 14'!G:G,MATCH(C35&E35&D35,'Category 14'!B:B&'Category 14'!C:C&'Category 14'!A:A,0)))} -> 0 | J35: =I35/VLOOKUP($D35,CPI!$P$16:$R$22,3,FALSE) -> 0 | K35: {=IF(B35=0,INDEX('Category 15'!F:F,MATCH(C35&E35&D35,'Category 15'!B:B&'Category 15'!C:C&'Category 15'!A:A,0)),INDEX('Category 15'!G:G,MATCH(C35&E35&D35,'Category 15'!B:B&'Category 31'!C:C&'Category 15'!A:A,0)))} -> 0 | L35: =K35/VLOOKUP($D35,CPI!$P$16:$R$22,3,FALSE) -> 0 | M35: {=IF(B35=0,INDEX('Category 31'!F:F,MATCH(C35&E35&D35,'Category 31'!B:B&'Category 31'!C:C&'Category 31'!A:A,0)),INDEX('Category 31'!G:G,MATCH(C35&E35&D35,'Category 31'!B:B&'Category 31'!C:C&'Category 31'!A:A,0)))} -> 0 | N35: =M35/VLOOKUP($D35,CPI!$P$16:$R$22,3,FALSE) -> 0 | O35: =VLOOKUP(E35,WVolleyball!C:P,7,FALSE) -> 24356
A36: 2 | B36: =IF(ISBLANK(G36),"",IF(MID(G36,1,1)="M",0,1)) -> 0 | C36: =IF(ISBLANK(H36),"",VLOOKUP(H36,Code!B:C,2,FALSE)) -> 1 | D36: 2019 | E36: 104179 | F36: Arizona | G36: Male | H36: Baseball | I36: {=IF(B36=0,INDEX('Category 14'!F:F,MATCH(C36&E36&D36,'Category 14'!B:B&'Category 14'!C:C&'Category 14'!A:A,0)),INDEX('Category 14'!G:G,MATCH(C36&E36&D36,'Category 14'!B:B&'Category 14'!C:C&'Category 14'!A:A,0)))} -> 3435 | J36: =I36/VLOOKUP($D36,CPI!$P$16:$R$22,3,FALSE) -> 4064.539 | K36: {=IF(B36=0,INDEX('Category 15'!F:F,MATCH(C36&E36&D36,'Category 15'!B:B&'Category 15'!C:C&'Category 15'!A:A,0)),INDEX('Category 15'!G:G,MATCH(C36&E36&D36,'Category 15'!B:B&'Category 31'!C:C&'Category 15'!A:A,0)))} -> 0 | L36: =K36/VLOOKUP($D36,CPI!$P$16:$R$22,3,FALSE) -> 0 | M36: {=IF(B36=0,INDEX('Category 31'!F:F,MATCH(C36&E36&D36,'Category 31'!B:B&'Category 31'!C:C&'Category 31'!A:A,0)),INDEX('Category 31'!G:G,MATCH(C36&E36&D36,'Category 31'!B:B&'Category 31'!C:C&'Category 31'!A:A,0)))} -> 0 | N36: =M36/VLOOKUP($D36,CPI!$P$16:$R$22,3,FALSE) -> 0 | O36: 81394
A37: 2 | B37: =IF(ISBLANK(G37),"",IF(MID(G37,1,1)="M",0,1)) -> 0 | C37: =IF(ISBLANK(H37),"",VLOOKUP(H37,Code!B:C,2,FALSE)) -> 2 | D37: 2019 | E37: 104179 | F37: Arizona | G37: Male | H37: Basketball | I37: {=IF(B37=0,INDEX('Category 14'!F:F,MATCH(C37&E37&D37,'Category 14'!B:B&'Category 14'!C:C&'Category 14'!A:A,0)),INDEX('Category 14'!G:G,MATCH(C37&E37&D37,'Category 14'!B:B&'Category 14'!C:C&'Category 14'!A:A,0)))} -> 45770 | J37: =I37/VLOOKUP($D37,CPI!$P$16:$R$22,3,FALSE) -> 54158.355 | K37: {=IF(B37=0,INDEX('Category 15'!F:F,MATCH(C37&E37&D37,'Category 15'!B:B&'Category 15'!C:C&'Category 15'!A:A,0)),INDEX('Category 15'!G:G,MATCH(C37&E37&D37,'Category 15'!B:B&'Category 31'!C:C&'Category 15'!A:A,0)))} -> 4381518 | L37: =K37/VLOOKUP($D37,CPI!$P$16:$R$22,3,FALSE) -> 5184527.1 | M37: {=IF(B37=0,INDEX('Category 31'!F:F,MATCH(C37&E37&D37,'Category 31'!B:B&'Category 31'!C:C&'Category 31'!A:A,0)),INDEX('Category 31'!G:G,MATCH(C37&E37&D37,'Category 31'!B:B&'Category 31'!C:C&'Category 31'!A:A,0)))} -> 0 | N37: =M37/VLOOKUP($D37,CPI!$P$16:$R$22,3,FALSE) -> 0 | O37: =VLOOKUP(E37,MBasketball!C:P,8,FALSE) -> 233645
A38: 2 | B38: =IF(ISBLANK(G38),"",IF(MID(G38,1,1)="M",0,1)) -> 0 | C38: =IF(ISBLANK(H38),"",VLOOKUP(H38,Code!B:C,2,FALSE)) -> 8 | D38: 2019 | E38: 104179 | F38: Arizona | G38: Male | H38: Football | I38: {=IF(B38=0,INDEX('Category 14'!F:F,MATCH(C38&E38&D38,'Category 14'!B:B&'Category 14'!C:C&'Category 14'!A:A,0)),INDEX('Category 14'!G:G,MATCH(C38&E38&D38,'Category 14'!B:B&'Category 14'!C:C&'Category 14'!A:A,0)))} -> 471041 | J38: =I38/VLOOKUP($D38,CPI!$P$16:$R$22,3,FALSE) -> 557369.58 | K38: {=IF(B38=0,INDEX('Category 15'!F:F,MATCH(C38&E38&D38,'Category 15'!B:B&'Category 15'!C:C&'Category 15'!A:A,0)),INDEX('Category 15'!G:G,MATCH(C38&E38&D38,'Category 15'!B:B&'Category 31'!C:C&'Category 15'!A:A,0)))} -> 4381518 | L38: =K38/VLOOKUP($D38,CPI!$P$16:$R$22,3,FALSE) -> 5184527.1 | M38: {=IF(B38=0,INDEX('Category 31'!F:F,MATCH(C38&E38&D38,'Category 31'!B:B&'Category 31'!C:C&'Category 31'!A:A,0)),INDEX('Category 31'!G:G,MATCH(C38&E38&D38,'Category 31'!B:B&'Category 31'!C:C&'Category 31'!A:A,0)))} -> 0 | N38: =M38/VLOOKUP($D38,CPI!$P$16:$R$22,3,FALSE) -> 0 | O38: =VLOOKUP(E38,MFootball!C:P,8,FALSE) -> 318051
A39: 2 | B39: =IF(ISBLANK(G39),"",IF(MID(G39,1,1)="M",0,1)) -> 0 | C39: =IF(ISBLANK(H39),"",VLOOKUP(H39,Code!B:C,2,FALSE)) -> 9 | D39: 2019 | E39: 104179 | F39: Arizona | G39: Male | H39: Golf | I39: {=IF(B39=0,INDEX('Category 14'!F:F,MATCH(C39&E39&D39,'Category 14'!B:B&'Category 14'!C:C&'Category 14'!A:A,0)),INDEX('Category 14'!G:G,MATCH(C39&E39&D39,'Category 14'!B:B&'Category 14'!C:C&'Category 14'!A:A,0)))} -> 0 | J39: =I39/VLOOKUP($D39,CPI!$P$16:$R$22,3,FALSE) -> 0 | K39: {=IF(B39=0,INDEX('Category 15'!F:F,MATCH(C39&E39&D39,'Category 15'!B:B&'Category 15'!C:C&'Category 15'!A:A,0)),INDEX('Category 15'!G:G,MATCH(C39&E39&D39,'Category 15'!B:B&'Category 31'!C:C&'Category 15'!A:A,0)))} -> 0 | L39: =K39/VLOOKUP($D39,CPI!$P$16:$R$22,3,FALSE) -> 0 | M39: {=IF(B39=0,INDEX('Category 31'!F:F,MATCH(C39&E39&D39,'Category 31'!B:B&'Category 31'!C:C&'Category 31'!A:A,0)),INDEX('Category 31'!G:G,MATCH(C39&E39&D39,'Category 31'!B:B&'Category 31'!C:C&'Category 31'!A:A,0)))} -> 0 | N39: =M39/VLOOKUP($D39,CPI!$P$16:$R$22,3,FALSE) -> 0 | O39: 0
A40: 2 | B40: =IF(ISBLANK(G40),"",IF(MID(G40,1,1)="M",0,1)) -> 0 | C40: =IF(ISBLANK(H40),"",VLOOKUP(H40,Code!B:C,2,FALSE)) -> 19 | D40: 2019 | E40: 104179 | F40: Arizona | G40: Male | H40: Swimming and Diving | I40: {=IF(B40=0,INDEX('Category 14'!F:F,MATCH(C40&E40&D40,'Category 14'!B:B&'Category 14'!C:C&'Category 14'!A:A,0)),INDEX('Category 14'!G:G,MATCH(C40&E40&D40,'Category 14'!B:B&'Category 14'!C:C&'Category 14'!A:A,0)))} -> 0 | J40: =I40/VLOOKUP($D40,CPI!$P$16:$R$22,3,FALSE) -> 0 | K40: {=IF(B40=0,INDEX('Category 15'!F:F,MATCH(C40&E40&D40,'Category 15'!B:B&'Category 15'!C:C&'Category 15'!A:A,0)),INDEX('Category 15'!G:G,MATCH(C40&E40&D40,'Category 15'!B:B&'Category 31'!C:C&'Category 15'!A:A,0)))} -> 0 | L40: =K40/VLOOKUP($D40,CPI!$P$16:$R$22,3,FALSE) -> 0 | M40: {=IF(B40=0,INDEX('Category 31'!F:F,MATCH(C40&E40&D40,'Category 31'!B:B&'Category 31'!C:C&'Category 31'!A:A,0)),INDEX('Category 31'!G:G,MATCH(C40&E40&D40,'Category 31'!B:B&'Category 31'!C:C&'Category 31'!A:A,0)))} -> 0 | N40: =M40/VLOOKUP($D40,CPI!$P$16:$R$22,3,FALSE) -> 0 | O40: 0
...

Sheet Category 14
A1: FY | B1: Code | C1: unitid | D1: University | E1: Sport | F1: Mens | G1: Womens | H1: NAG
A2: 2017 | B2: =IF(ISBLANK(E2),"",VLOOKUP(E2,Code!B:C,2,FALSE)) -> 1 | C2: 104179 | D2: Arizona | E2: Baseball | F2: 23795
A3: 2017 | B3: =IF(ISBLANK(E3),"",VLOOKUP(E3,Code!B:C,2,FALSE)) -> 2 | C3: 104179 | D3: Arizona | E3: Basketball | F3: 353895
A4: 2017 | B4: =IF(ISBLANK(E4),"",VLOOKUP(E4,Code!B:C,2,FALSE)) -> 3 | C4: 104179 | D4: Arizona | E4: Beach Volleyball | G4: 328
A5: 2017 | B5: 8 | C5: 104179 | D5: Arizona | E5: Football | F5: 659525
A6: 2017 | B6: =IF(ISBLANK(E6),"",VLOOKUP(E6,Code!B:C,2,FALSE)) -> 9 | C6: 104179 | D6: Arizona | E6: Golf | F6: 18513 | G6: 4680
A7: 2017 | B7: =IF(ISBLANK(E7),"",VLOOKUP(E7,Code!B:C,2,FALSE)) -> 10 | C7: 104179 | D7: Arizona | E7: Gymnastics | G7: 295
A8: 2017 | B8: =IF(ISBLANK(E8),"",VLOOKUP(E8,Code!B:C,2,FALSE)) -> 17 | C8: 104179 | D8: Arizona | E8: Soccer | G8: 2346
A9: 2017 | B9: =IF(ISBLANK(E9),"",VLOOKUP(E9,Code!B:C,2,FALSE)) -> 18 | C9: 104179 | D9: Arizona | E9: Softball | G9: 30388
A10: 2017 | B10: =IF(ISBLANK(E10),"",VLOOKUP(E10,Code!B:C,2,FALSE)) -> 19 | C10: 104179 | D10: Arizona | E10: Swimming and Diving | F10: 5787 | G10: 8180
A11: 2017 | B11: =IF(ISBLANK(E11),"",VLOOKUP(E11,Code!B:C,2,FALSE)) -> 20 | C11: 104179 | D11: Arizona | E11: Tennis | G11: 12187
A12: 2017 | B12: =IF(ISBLANK(E12),"",VLOOKUP(E12,Code!B:C,2,FALSE)) -> 21 | C12: 104179 | D12: Arizona | E12: Track and Field, X-Country | F12: 15915 | G12: 9702
A13: 2017 | B13: =IF(ISBLANK(E13),"",VLOOKUP(E13,Code!B:C,2,FALSE)) -> 23 | C13: 104179 | D13: Arizona | E13: Volleyball | G13: 19455
A14: 2018 | B14: =IF(ISBLANK(E14),"",VLOOKUP(E14,Code!B:C,2,FALSE)) -> 1 | C14: 104179 | D14: Arizona | E14: Baseball | F14: 2150
A15: 2018 | B15: =IF(ISBLANK(E15),"",VLOOKUP(E15,Code!B:C,2,FALSE)) -> 2 | C15: 104179 | D15: Arizona | E15: Basketball | F15: 166804
A16: 2018 | B16: =IF(ISBLANK(E16),"",VLOOKUP(E16,Code!B:C,2,FALSE)) -> 8 | C16: 104179 | D16: Arizona | E16: Football | F16: 592731
A17: 2018 | B17: =IF(ISBLANK(E17),"",VLOOKUP(E17,Code!B:C,2,FALSE)) -> 21 | C17: 104179 | D17: Arizona | E17: Track and Field, X-Country | F17: 11082 | G17: 10223
A18: 2018 | B18: =IF(ISBLANK(E18),"",VLOOKUP(E18,Code!B:C,2,FALSE)) -> 3 | C18: 104179 | D18: Arizona | E18: Beach Volleyball
A19: 2018 | B19: =IF(ISBLANK(E19),"",VLOOKUP(E19,Code!B:C,2,FALSE)) -> 9 | C19: 104179 | D19: Arizona | E19: Golf | F19: 32700 | G19: 11085
A20: 2018 | B20: =IF(ISBLANK(E20),"",VLOOKUP(E20,Code!B:C,2,FALSE)) -> 10 | C20: 104179 | D20: Arizona | E20: Gymnastics | G20: 1937
A21: 2018 | B21: =IF(ISBLANK(E21),"",VLOOKUP(E21,Code!B:C,2,FALSE)) -> 17 | C21: 104179 | D21: Arizona | E21: Soccer | G21: 2300
A22: 2018 | B22: =IF(ISBLANK(E22),"",VLOOKUP(E22,Code!B:C,2,FALSE)) -> 18 | C22: 104179 | D22: Arizona | E22: Softball
A23: 2018 | B23: =IF(ISBLANK(E23),"",VLOOKUP(E23,Code!B:C,2,FALSE)) -> 19 | C23: 104179 | D23: Arizona | E23: Swimming and Diving | F23: 1296 | G23: 1121
