Workbook

Sheet Sheet1
A1: RA6 | B1: University | C1: unitid | D1: FY | E1: WinningPercentage | F1: HeadCoachSalary | G1: RealHeadCoachSalary | H1: LnRealHeadCoachSalary | I1: AssistantCoachSalaryFTE | J1: AssistantCoachSalaryPositions | K1: Variable Revenue | L1: RealVariableRevenue | M1: TotalRevenue | N1: RealTotalRevenue
A2: 2 | B2: Arizona | C2: =VLOOKUP(B2,unitid!A:B,2,FALSE) -> 104179 | D2: 2017 | E2: 0.571 | F2: 204778 | G2: =F2/VLOOKUP($D2,CPI!$P$16:$R$22,3,FALSE) -> 252904.82 | H2: =LN(G2) -> 12.440768 | I2: =196452/2 -> 98226 | J2: =196452/2 -> 98226 | K2: 37645754 | L2: =K2/VLOOKUP($D2,CPI!$P$16:$R$22,3,FALSE) -> 46493239 | M2: =IFERROR(IF(VLOOKUP(C2,'2017'!A:C,3,FALSE)="","",VLOOKUP(C2,'2017'!A:C,3,FALSE)),"") -> 580596 | N2: =M2/VLOOKUP($D2,CPI!$P$16:$R$22,3,FALSE) -> 717047.36
A3: =IF(ISBLANK(A$2),"",$A$2) -> 2 | B3: =B2 -> Arizona | C3: =VLOOKUP(B3,unitid!A:B,2,FALSE) -> 104179 | D3: =IF(D2=2023,2017,D2+1) -> 2018 | E3: 0.379 | F3: 199320 | G3: =F3/VLOOKUP($D3,CPI!$P$16:$R$22,3,FALSE) -> 240737.83 | H3: =LN(G3) -> 12.391464 | I3: =200376/2 -> 100188 | J3: =200376/2 -> 100188 | K3: 39962452 | L3: =K3/VLOOKUP($D3,CPI!$P$16:$R$22,3,FALSE) -> 48266475 | M3: =IFERROR(IF(VLOOKUP(C3,'2018'!A:C,3,FALSE)="","",VLOOKUP(C3,'2018'!A:C,3,FALSE)),"") -> 574321 | N3: =M3/VLOOKUP($D3,CPI!$P$16:$R$22,3,FALSE) -> 693662.4
A4: =IF(ISBLANK(A$2),"",$A$2) -> 2 | B4: =B3 -> Arizona | C4: =VLOOKUP(B4,unitid!A:B,2,FALSE) -> 104179 | D4: =IF(D3=2023,2017,D3+1) -> 2019 | E4: 0.667 | F4: 200474 | G4: =F4/VLOOKUP($D4,CPI!$P$16:$R$22,3,FALSE) -> 237215.25 | H4: =LN(G4) -> 12.376723 | I4: =201786/2 -> 100893 | J4: =201786/2 -> 100893 | K4: 37930861 | L4: =K4/VLOOKUP($D4,CPI!$P$16:$R$22,3,FALSE) -> 44882522 | M4: =IFERROR(IF(VLOOKUP(C4,'2019'!A:C,3,FALSE)="","",VLOOKUP(C4,'2019'!A:C,3,FALSE)),"") -> 564020 | N4: =M4/VLOOKUP($D4,CPI!$P$16:$R$22,3,FALSE) -> 667389.02
A5: =IF(ISBLANK(A$2),"",$A$2) -> 2 | B5: =B4 -> Arizona | C5: =VLOOKUP(B5,unitid!A:B,2,FALSE) -> 104179 | D5: =IF(D4=2023,2017,D4+1) -> 2020 | E5: 0.469 | F5: 237177 | G5: =F5/VLOOKUP($D5,CPI!$P$16:$R$22,3,FALSE) -> 276322.78 | H5: =LN(G5) -> 12.529325 | I5: =191055/2 -> 95527.5 | J5: =191055/2 -> 95527.5 | K5: 38935371 | L5: =K5/VLOOKUP($D5,CPI!$P$16:$R$22,3,FALSE) -> 45361607 | M5: =IFERROR(IF(VLOOKUP(C5,'2020'!A:C,3,FALSE)="","",VLOOKUP(C5,'2020'!A:C,3,FALSE)),"") -> 515627 | N5: =M5/VLOOKUP($D5,CPI!$P$16:$R$22,3,FALSE) -> 600730.61
A6: =IF(ISBLANK(A$2),"",$A$2) -> 2 | B6: =B5 -> Arizona | C6: =VLOOKUP(B6,unitid!A:B,2,FALSE) -> 104179 | D6: =IF(D5=2023,2017,D5+1) -> 2021 | E6: 0.476 | F6: 214998 | G6: =F6/VLOOKUP($D6,CPI!$P$16:$R$22,3,FALSE) -> 244847.66 | H6: =LN(G6) -> 12.408391 | I6: =170898/2 -> 85449 | J6: =170898/2 -> 85449 | K6: 15156873 | L6: =K6/VLOOKUP($D6,CPI!$P$16:$R$22,3,FALSE) -> 17261206 | M6: =IFERROR(IF(VLOOKUP(C6,'2021'!A:C,3,FALSE)="","",VLOOKUP(C6,'2021'!A:C,3,FALSE)),"") -> 440705 | N6: =M6/VLOOKUP($D6,CPI!$P$16:$R$22,3,FALSE) -> 501891.12
A7: =IF(ISBLANK(A$2),"",$A$2) -> 2 | B7: =B6 -> Arizona | C7: =VLOOKUP(B7,unitid!A:B,2,FALSE) -> 104179 | D7: =IF(D6=2023,2017,D6+1) -> 2022 | E7: 0.515 | F7: 238342 | G7: =F7/VLOOKUP($D7,CPI!$P$16:$R$22,3,FALSE) -> 253267.06 | H7: =LN(G7) -> 12.4422 | I7: =195155/2 -> 97577.5 | J7: =195155/2 -> 97577.5 | K7: 43066175 | L7: =K7/VLOOKUP($D7,CPI!$P$16:$R$22,3,FALSE) -> 45762993 | M7: =IFERROR(IF(VLOOKUP(C7,'2022'!A:C,3,FALSE)="","",VLOOKUP(C7,'2022'!A:C,3,FALSE)),"") -> 602965 | N7: =M7/VLOOKUP($D7,CPI!$P$16:$R$22,3,FALSE) -> 640722.87
A8: =IF(ISBLANK(A$2),"",$A$2) -> 2 | B8: =B7 -> Arizona | C8: =VLOOKUP(B8,unitid!A:B,2,FALSE) -> 104179 | D8: =IF(D7=2023,2017,D7+1) -> 2023 | E8: 0.516 | F8: 269428 | G8: =F8/VLOOKUP($D8,CPI!$P$16:$R$22,3,FALSE) -> 269428 | H8: =LN(G8) -> 12.504056 | I8: =248402/2 -> 124201 | J8: =248402/2 -> 124201 | K8: 46328302 | L8: =K8/VLOOKUP($D8,CPI!$P$16:$R$22,3,FALSE) -> 46328302 | M8: =IFERROR(IF(VLOOKUP(C8,'2023'!A:C,3,FALSE)="","",VLOOKUP(C8,'2023'!A:C,3,FALSE)),"") -> 606900 | N8: =M8/VLOOKUP($D8,CPI!$P$16:$R$22,3,FALSE) -> 606900
A9: =IF(ISBLANK(A$2),"",$A$2) -> 2 | B9: California | C9: =VLOOKUP(B9,unitid!A:B,2,FALSE) -> 110635 | D9: =IF(D8=2023,2017,D8+1) -> 2017 | E9: 0.3 | F9: 246530 | G9: =F9/VLOOKUP($D9,CPI!$P$16:$R$22,3,FALSE) -> 304469.35 | H9: =LN(G9) -> 12.626326 | I9: =273439/2 -> 136719.5 | J9: =273439/2 -> 136719.5 | K9: 36974162 | L9: =K9/VLOOKUP($D9,CPI!$P$16:$R$22,3,FALSE) -> 45663810 | M9: =IFERROR(IF(VLOOKUP(C9,'2017'!A:C,3,FALSE)="","",VLOOKUP(C9,'2017'!A:C,3,FALSE)),"") -> 106601 | N9: =M9/VLOOKUP($D9,CPI!$P$16:$R$22,3,FALSE) -> 131654.31
A10: =IF(ISBLANK(A$2),"",$A$2) -> 2 | B10: =B9 -> California | C10: =VLOOKUP(B10,unitid!A:B,2,FALSE) -> 110635 | D10: =IF(D9=2023,2017,D9+1) -> 2018 | E10: 0.419 | F10: 232227 | G10: =F10/VLOOKUP($D10,CPI!$P$16:$R$22,3,FALSE) -> 280482.76 | H10: =LN(G10) -> 12.544268 | I10: =245718/2 -> 122859 | J10: =245718/2 -> 122859 | K10: 29520440 | L10: =K10/VLOOKUP($D10,CPI!$P$16:$R$22,3,FALSE) -> 35654659 | M10: =IFERROR(IF(VLOOKUP(C10,'2018'!A:C,3,FALSE)="","",VLOOKUP(C10,'2018'!A:C,3,FALSE)),"") -> 111908 | N10: =M10/VLOOKUP($D10,CPI!$P$16:$R$22,3,FALSE) -> 135161.99
A11: =IF(ISBLANK(A$2),"",$A$2) -> 2 | B11: =B10 -> California | C11: =VLOOKUP(B11,unitid!A:B,2,FALSE) -> 110635 | D11: =IF(D10=2023,2017,D10+1) -> 2019 | E11: 0.484 | F11: 267689 | G11: =F11/VLOOKUP($D11,CPI!$P$16:$R$22,3,FALSE) -> 316748.87 | H11: =LN(G11) -> 12.665865 | I11: =243823/2 -> 121911.5 | J11: =243823/2 -> 121911.5 | K11: 27923976 | L11: =K11/VLOOKUP($D11,CPI!$P$16:$R$22,3,FALSE) -> 33041656 | M11: =IFERROR(IF(VLOOKUP(C11,'2019'!A:C,3,FALSE)="","",VLOOKUP(C11,'2019'!A:C,3,FALSE)),"") -> 115320 | N11: =M11/VLOOKUP($D11,CPI!$P$16:$R$22,3,FALSE) -> 136454.92
A12: =IF(ISBLANK(A$2),"",$A$2) -> 2 | B12: =B11 -> California | C12: =VLOOKUP(B12,unitid!A:B,2,FALSE) -> 110635 | D12: =IF(D11=2023,2017,D11+1) -> 2020 | E12: 0.667 | F12: 268737 | G12: =F12/VLOOKUP($D12,CPI!$P$16:$R$22,3,FALSE) -> 313091.72 | H12: =LN(G12) -> 12.654251 | I12: =252969/2 -> 126484.5 | J12: =252969/2 -> 126484.5 | K12: 23019539 | L12: =K12/VLOOKUP($D12,CPI!$P$16:$R$22,3,FALSE) -> 26818886 | M12: =IFERROR(IF(VLOOKUP(C12,'2020'!A:C,3,FALSE)="","",VLOOKUP(C12,'2020'!A:C,3,FALSE)),"") -> 103205 | N12: =M12/VLOOKUP($D12,CPI!$P$16:$R$22,3,FALSE) -> 120238.86
A13: =IF(ISBLANK(A$2),"",$A$2) -> 2 | B13: =B12 -> California | C13: =VLOOKUP(B13,unitid!A:B,2,FALSE) -> 110635 | D13: =IF(D12=2023,2017,D12+1) -> 2021 | E13: 0.045 | F13: 261096 | G13: =F13/VLOOKUP($D13,CPI!$P$16:$R$22,3,FALSE) -> 297345.76 | H13: =LN(G13) -> 12.602651 | I13: =254159/2 -> 127079.5 | J13: =254159/2 -> 127079.5 | K13: 12204906 | L13: =K13/VLOOKUP($D13,CPI!$P$16:$R$22,3,FALSE) -> 13899397 | M13: =IFERROR(IF(VLOOKUP(C13,'2021'!A:C,3,FALSE)="","",VLOOKUP(C13,'2021'!A:C,3,FALSE)),"") -> 104836 | N13: =M13/VLOOKUP($D13,CPI!$P$16:$R$22,3,FALSE) -> 119391.11
A14: =IF(ISBLANK(A$2),"",$A$2) -> 2 | B14: =B13 -> California | C14: =VLOOKUP(B14,unitid!A:B,2,FALSE) -> 110635 | D14: =IF(D13=2023,2017,D13+1) -> 2022 | E14: 0.226 | F14: 271797 | G14: =F14/VLOOKUP($D14,CPI!$P$16:$R$22,3,FALSE) -> 288817.02 | H14: =LN(G14) -> 12.573549 | I14: =255397/2 -> 127698.5 | J14: =255397/2 -> 127698.5 | K14: 24851053 | L14: =K14/VLOOKUP($D14,CPI!$P$16:$R$22,3,FALSE) -> 26407234 | M14: =IFERROR(IF(VLOOKUP(C14,'2022'!A:C,3,FALSE)="","",VLOOKUP(C14,'2022'!A:C,3,FALSE)),"") -> 129740 | N14: =M14/VLOOKUP($D14,CPI!$P$16:$R$22,3,FALSE) -> 137864.36
A15: =IF(ISBLANK(A$2),"",$A$2) -> 2 | B15: =B14 -> California | C15: =VLOOKUP(B15,unitid!A:B,2,FALSE) -> 110635 | D15: =IF(D14=2023,2017,D14+1) -> 2023 | E15: 0.233 | F15: 273923 | G15: =F15/VLOOKUP($D15,CPI!$P$16:$R$22,3,FALSE) -> 273923 | H15: =LN(G15) -> 12.520602 | I15: =253981/2 -> 126990.5 | J15: =253981/2 -> 126990.5 | K15: 27598334 | L15: =K15/VLOOKUP($D15,CPI!$P$16:$R$22,3,FALSE) -> 27598334 | M15: =IFERROR(IF(VLOOKUP(C15,'2023'!A:C,3,FALSE)="","",VLOOKUP(C15,'2023'!A:C,3,FALSE)),"") -> 97083 | N15: =M15/VLOOKUP($D15,CPI!$P$16:$R$22,3,FALSE) -> 97083
A16: =IF(ISBLANK(A$2),"",$A$2) -> 2 | B16: Colorado | C16: =VLOOKUP(B16,unitid!A:B,2,FALSE) -> 126614 | D16: =IF(D15=2023,2017,D15+1) -> 2017 | E16: 0.467 | F16: =VLOOKUP(C16,'2017 (2)'!$A:$L,7,FALSE) -> 247268 | G16: =F16/VLOOKUP($D16,CPI!$P$16:$R$22,3,FALSE) -> 305380.79 | H16: =LN(G16) -> 12.629315 | I16: =VLOOKUP($C16,'2017 (2)'!$A:$L,11,FALSE)/VLOOKUP($C16,'2017 (2)'!$A:$L,10,FALSE) -> 123751 | J16: =VLOOKUP($C16,'2017 (2)'!$A:$L,11,FALSE)/VLOOKUP($C16,'2017 (2)'!$A:$L,9,FALSE) -> 123751 | K16: 31470663 | L16: =K16/VLOOKUP($D16,CPI!$P$16:$R$22,3,FALSE) -> 38866881 | M16: =IFERROR(IF(VLOOKUP(C16,'2017'!A:C,3,FALSE)="","",VLOOKUP(C16,'2017'!A:C,3,FALSE)),"") -> 596075 | N16: =M16/VLOOKUP($D16,CPI!$P$16:$R$22,3,FALSE) -> 736164.23
A17: =IF(ISBLANK(A$2),"",$A$2) -> 2 | B17: =B16 -> Colorado | C17: =VLOOKUP(B17,unitid!A:B,2,FALSE) -> 126614 | D17: =IF(D16=2023,2017,D16+1) -> 2018 | E17: 0.706 | F17: =VLOOKUP(C17,'2018 (2)'!$A:$L,7,FALSE) -> 288410 | G17: =F17/VLOOKUP($D17,CPI!$P$16:$R$22,3,FALSE) -> 348340.34 | H17: =LN(G17) -> 12.760935 | I17: =VLOOKUP($C17,'2018 (2)'!$A:$L,11,FALSE)/VLOOKUP($C17,'2018 (2)'!$A:$L,10,FALSE) -> 134990.5 | J17: =VLOOKUP($C17,'2018 (2)'!$A:$L,11,FALSE)/VLOOKUP($C17,'2018 (2)'!$A:$L,9,FALSE) -> 134990.5 | K17: 32665544 | L17: =K17/VLOOKUP($D17,CPI!$P$16:$R$22,3,FALSE) -> 39453301 | M17: =IFERROR(IF(VLOOKUP(C17,'2018'!A:C,3,FALSE)="","",VLOOKUP(C17,'2018'!A:C,3,FALSE)),"") -> 634684 | N17: =M17/VLOOKUP($D17,CPI!$P$16:$R$22,3,FALSE) -> 766568.57
A18: =IF(ISBLANK(A$2),"",$A$2) -> 2 | B18: =B17 -> Colorado | C18: =VLOOKUP(B18,unitid!A:B,2,FALSE) -> 126614 | D18: =IF(D17=2023,2017,D17+1) -> 2019 | E18: 0.563 | F18: =VLOOKUP(C18,'2019 (2)'!$A:$L,7,FALSE) -> 270392 | G18: =F18/VLOOKUP($D18,CPI!$P$16:$R$22,3,FALSE) -> 319947.26 | H18: =LN(G18) -> 12.675911 | I18: =VLOOKUP($C18,'2019 (2)'!$A:$L,11,FALSE)/VLOOKUP($C18,'2019 (2)'!$A:$L,10,FALSE) -> 141908.5 | J18: =VLOOKUP($C18,'2019 (2)'!$A:$L,11,FALSE)/VLOOKUP($C18,'2019 (2)'!$A:$L,9,FALSE) -> 141908.5 | K18: 32772249 | L18: =K18/VLOOKUP($D18,CPI!$P$16:$R$22,3,FALSE) -> 38778481 | M18: =IFERROR(IF(VLOOKUP(C18,'2019'!A:C,3,FALSE)="","",VLOOKUP(C18,'2019'!A:C,3,FALSE)),"") -> 484746 | N18: =M18/VLOOKUP($D18,CPI!$P$16:$R$22,3,FALSE) -> 573586.32
A19: =IF(ISBLANK(A$2),"",$A$2) -> 2 | B19: =B18 -> Colorado | C19: =VLOOKUP(B19,unitid!A:B,2,FALSE) -> 126614 | D19: =IF(D18=2023,2017,D18+1) -> 2020 | E19: 0.433 | F19: =VLOOKUP(C19,'2020 (2)'!$A:$L,7,FALSE) -> 230216 | G19: =F19/VLOOKUP($D19,CPI!$P$16:$R$22,3,FALSE) -> 268212.87 | H19: =LN(G19) -> 12.499536 | I19: =VLOOKUP($C19,'2020 (2)'!$A:$L,11,FALSE)/VLOOKUP($C19,'2020 (2)'!$A:$L,10,FALSE) -> 118607.5 | J19: =VLOOKUP($C19,'2020 (2)'!$A:$L,11,FALSE)/VLOOKUP($C19,'2020 (2)'!$A:$L,9,FALSE) -> 118607.5 | K19: 34898028 | L19: =K19/VLOOKUP($D19,CPI!$P$16:$R$22,3,FALSE) -> 40657905 | M19: =IFERROR(IF(VLOOKUP(C19,'2020'!A:C,3,FALSE)="","",VLOOKUP(C19,'2020'!A:C,3,FALSE)),"") -> 266383 | N19: =M19/VLOOKUP($D19,CPI!$P$16:$R$22,3,FALSE) -> 310349.19
A20: =IF(ISBLANK(A$2),"",$A$2) -> 2 | B20: =B19 -> Colorado | C20: =VLOOKUP(B20,unitid!A:B,2,FALSE) -> 126614 | D20: =IF(D19=2023,2017,D19+1) -> 2021 | E20: 0.4 | F20: =VLOOKUP(C20,'2021 (2)'!$A:$L,7,FALSE) -> 212461 | G20: =F20/VLOOKUP($D20,CPI!$P$16:$R$22,3,FALSE) -> 241958.43 | H20: =LN(G20) -> 12.396521 | I20: =VLOOKUP($C20,'2021 (2)'!$A:$L,11,FALSE)/VLOOKUP($C20,'2021 (2)'!$A:$L,10,FALSE) -> 95072 | J20: =VLOOKUP($C20,'2021 (2)'!$A:$L,11,FALSE)/VLOOKUP($C20,'2021 (2)'!$A:$L,9,FALSE) -> 95072 | K20: 3894319 | L20: =K20/VLOOKUP($D20,CPI!$P$16:$R$22,3,FALSE) -> 4434994.2 | M20: =IFERROR(IF(VLOOKUP(C20,'2021'!A:C,3,FALSE)="","",VLOOKUP(C20,'2021'!A:C,3,FALSE)),"") -> 423569 | N20: =M20/VLOOKUP($D20,CPI!$P$16:$R$22,3,FALSE) -> 482376.01
A21: =IF(ISBLANK(A$2),"",$A$2) -> 2 | B21: =B20 -> Colorado | C21: =VLOOKUP(B21,unitid!A:B,2,FALSE) -> 126614 | D21: =IF(D20=2023,2017,D20+1) -> 2022 | E21: 0.517 | F21: =VLOOKUP(C21,'2022 (2)'!$A:$L,7,FALSE) -> 256687 | G21: =F21/VLOOKUP($D21,CPI!$P$16:$R$22,3,FALSE) -> 272760.83 | H21: =LN(G21) -> 12.516351 | I21: =VLOOKUP($C21,'2022 (2)'!$A:$L,11,FALSE)/VLOOKUP($C21,'2022 (2)'!$A:$L,10,FALSE) -> 128169 | J21: =VLOOKUP($C21,'2022 (2)'!$A:$L,11,FALSE)/VLOOKUP($C21,'2022 (2)'!$A:$L,9,FALSE) -> 128169 | K21: 24851053 | L21: =K21/VLOOKUP($D21,CPI!$P$16:$R$22,3,FALSE) -> 26407234 | M21: =IFERROR(IF(VLOOKUP(C21,'2022'!A:C,3,FALSE)="","",VLOOKUP(C21,'2022'!A:C,3,FALSE)),"") -> 530417 | N21: =M21/VLOOKUP($D21,CPI!$P$16:$R$22,3,FALSE) -> 563631.89
A22: =IF(ISBLANK(A$2),"",$A$2) -> 2 | B22: =B21 -> Colorado | C22: =VLOOKUP(B22,unitid!A:B,2,FALSE) -> 126614 | D22: =IF(D21=2023,2017,D21+1) -> 2023 | E22: 0.645 | F22: =VLOOKUP(C22,'2023 (2)'!$A:$L,7,FALSE) -> 269756 | G22: =F22/VLOOKUP($D22,CPI!$P$16:$R$22,3,FALSE) -> 269756 | H22: =LN(G22) -> 12.505273 | I22: =VLOOKUP($C22,'2023 (2)'!$A:$L,11,FALSE)/VLOOKUP($C22,'2023 (2)'!$A:$L,10,FALSE) -> 136923 | J22: =VLOOKUP($C22,'2023 (2)'!$A:$L,11,FALSE)/VLOOKUP($C22,'2023 (2)'!$A:$L,9,FALSE) -> 136923 | K22: 47905550 | L22: =K22/VLOOKUP($D22,CPI!$P$16:$R$22,3,FALSE) -> 47905550 | M22: =IFERROR(IF(VLOOKUP(C22,'2023'!A:C,3,FALSE)="","",VLOOKUP(C22,'2023'!A:C,3,FALSE)),"") -> 747988 | N22: =M22/VLOOKUP($D22,CPI!$P$16:$R$22,3,FALSE) -> 747988
A23: =IF(ISBLANK(A$2),"",$A$2) -> 2 | B23: Maryland Baltimore County | C23: =VLOOKUP(B23,unitid!A:B,2,FALSE) -> 163268 | D23: =IF(D22=2023,2017,D22+1) -> 2017 | E23: 0.654 | F23: =VLOOKUP(C23,'2017 (2)'!$A:$L,7,FALSE) -> 98917 | G23: =F23/VLOOKUP($D23,CPI!$P$16:$R$22,3,FALSE) -> 122164.42 | H23: =LN(G23) -> 11.713123 | I23: =VLOOKUP($C23,'2017 (2)'!$A:$L,11,FALSE)/VLOOKUP($C23,'2017 (2)'!$A:$L,10,FALSE) -> 56162.5 | J23: =VLOOKUP($C23,'2017 (2)'!$A:$L,11,FALSE)/VLOOKUP($C23,'2017 (2)'!$A:$L,9,FALSE) -> 22465 | K23: 596978 | L23: =K23/VLOOKUP($D23,CPI!$P$16:$R$22,3,FALSE) -> 737279.45 | M23: =IFERROR(IF(VLOOKUP(C23,'2017'!A:C,3,FALSE)="","",VLOOKUP(C23,'2017'!A:C,3,FALSE)),"") -> 139065 | N23: =M23/VLOOKUP($D23,CPI!$P$16:$R$22,3,FALSE) -> 171747.98
A24: =IF(ISBLANK(A$2),"",$A$2) -> 2 | B24: =B23 -> Maryland Baltimore County | C24: =VLOOKUP(B24,unitid!A:B,2,FALSE) -> 163268 | D24: =IF(D23=2023,2017,D23+1) -> 2018 | E24: 0.538 | F24: =VLOOKUP(C24,'2018 (2)'!$A:$L,7,FALSE) -> 83140 | G24: =F24/VLOOKUP($D24,CPI!$P$16:$R$22,3,FALSE) -> 100416.13 | H24: =LN(G24) -> 11.517078 | I24: =VLOOKUP($C24,'2018 (2)'!$A:$L,11,FALSE)/VLOOKUP($C24,'2018 (2)'!$A:$L,10,FALSE) -> 46358 | J24: =VLOOKUP($C24,'2018 (2)'!$A:$L,11,FALSE)/VLOOKUP($C24,'2018 (2)'!$A:$L,9,FALSE) -> 23179 | K24: 362973 | L24: =K24/VLOOKUP($D24,CPI!$P$16:$R$22,3,FALSE) -> 438397.21 | M24: =IFERROR(IF(VLOOKUP(C24,'2018'!A:C,3,FALSE)="","",VLOOKUP(C24,'2018'!A:C,3,FALSE)),"") -> 12630 | N24: =M24/VLOOKUP($D24,CPI!$P$16:$R$22,3,FALSE) -> 15254.459
A25: =IF(ISBLANK(A$2),"",$A$2) -> 2 | B25: =B24 -> Maryland Baltimore County | C25: =VLOOKUP(B25,unitid!A:B,2,FALSE) -> 163268 | D25: =IF(D24=2023,2017,D24+1) -> 2019 | E25: 0.269 | F25: =VLOOKUP(C25,'2019 (2)'!$A:$L,7,FALSE) -> 141877 | G25: =F25/VLOOKUP($D25,CPI!$P$16:$R$22,3,FALSE) -> 167879.07 | H25: =LN(G25) -> 12.030999 | I25: =VLOOKUP($C25,'2019 (2)'!$A:$L,11,FALSE)/VLOOKUP($C25,'2019 (2)'!$A:$L,10,FALSE) -> 35469 | J25: =VLOOKUP($C25,'2019 (2)'!$A:$L,11,FALSE)/VLOOKUP($C25,'2019 (2)'!$A:$L,9,FALSE) -> 35469 | K25: 468798 | L25: =K25/VLOOKUP($D25,CPI!$P$16:$R$22,3,FALSE) -> 554715.5 | M25: =IFERROR(IF(VLOOKUP(C25,'2019'!A:C,3,FALSE)="","",VLOOKUP(C25,'2019'!A:C,3,FALSE)),"") | N25: =IFERROR(M25/VLOOKUP($D25,CPI!$P$16:$R$22,3,FALSE),"")
A26: =IF(ISBLANK(A$2),"",$A$2) -> 2 | B26: =B25 -> Maryland Baltimore County | C26: =VLOOKUP(B26,unitid!A:B,2,FALSE) -> 163268 | D26: =IF(D25=2023,2017,D25+1) -> 2020 | E26: 0.304 | F26: =VLOOKUP(C26,'2020 (2)'!$A:$L,7,FALSE) -> 118188 | G26: =F26/VLOOKUP($D26,CPI!$P$16:$R$22,3,FALSE) -> 137694.79 | H26: =LN(G26) -> 11.832795 | I26: =VLOOKUP($C26,'2020 (2)'!$A:$L,11,FALSE)/VLOOKUP($C26,'2020 (2)'!$A:$L,10,FALSE) -> 24346.667 | J26: =VLOOKUP($C26,'2020 (2)'!$A:$L,11,FALSE)/VLOOKUP($C26,'2020 (2)'!$A:$L,9,FALSE) -> 18260 | K26: 490141 | L26: =K26/VLOOKUP($D26,CPI!$P$16:$R$22,3,FALSE) -> 571038.18 | M26: =IFERROR(IF(VLOOKUP(C26,'2020'!A:C,3,FALSE)="","",VLOOKUP(C26,'2020'!A:C,3,FALSE)),"") -> 8161 | N26: =M26/VLOOKUP($D26,CPI!$P$16:$R$22,3,FALSE) -> 9507.9632
A27: =IF(ISBLANK(A$2),"",$A$2) -> 2 | B27: =B26 -> Maryland Baltimore County | C27: =VLOOKUP(B27,unitid!A:B,2,FALSE) -> 163268 | D27: =IF(D26=2023,2017,D26+1) -> 2021 | E27: 0.733 | F27: =VLOOKUP(C27,'2021 (2)'!$A:$L,7,FALSE) -> 149123 | G27: =F27/VLOOKUP($D27,CPI!$P$16:$R$22,3,FALSE) -> 169826.78 | H27: =LN(G27) -> 12.042534 | I27: =VLOOKUP($C27,'2021 (2)'!$A:$L,11,FALSE)/VLOOKUP($C27,'2021 (2)'!$A:$L,10,FALSE) -> 43578 | J27: =VLOOKUP($C27,'2021 (2)'!$A:$L,11,FALSE)/VLOOKUP($C27,'2021 (2)'!$A:$L,9,FALSE) -> 21789 | K27: 137148 | L27: =K27/VLOOKUP($D27,CPI!$P$16:$R$22,3,FALSE) -> 156189.2 | M27: =IFERROR(IF(VLOOKUP(C27,'2021'!A:C,3,FALSE)="","",VLOOKUP(C27,'2021'!A:C,3,FALSE)),"") -> 180245 | N27: =M27/VLOOKUP($D27,CPI!$P$16:$R$22,3,FALSE) -> 205269.66
A28: =IF(ISBLANK(A$2),"",$A$2) -> 2 | B28: =B27 -> Maryland Baltimore County | C28: =VLOOKUP(B28,unitid!A:B,2,FALSE) -> 163268 | D28: =IF(D27=2023,2017,D27+1) -> 2022 | E28: 0.613 | F28: =VLOOKUP(C28,'2022 (2)'!$A:$L,7,FALSE) -> 96637 | G28: =F28/VLOOKUP($D28,CPI!$P$16:$R$22,3,FALSE) -> 102688.44 | H28: =LN(G28) -> 11.539455 | I28: =VLOOKUP($C28,'2022 (2)'!$A:$L,11,FALSE)/VLOOKUP($C28,'2022 (2)'!$A:$L,10,FALSE) -> 41124 | J28: =VLOOKUP($C28,'2022 (2)'!$A:$L,11,FALSE)/VLOOKUP($C28,'2022 (2)'!$A:$L,9,FALSE) -> 41124 | K28: 697115 | L28: =K28/VLOOKUP($D28,CPI!$P$16:$R$22,3,FALSE) -> 740768.57 | M28: =IFERROR(IF(VLOOKUP(C28,'2022'!A:C,3,FALSE)="","",VLOOKUP(C28,'2022'!A:C,3,FALSE)),"") -> 233454 | N28: =M28/VLOOKUP($D28,CPI!$P$16:$R$22,3,FALSE) -> 248072.97
A29: =IF(ISBLANK(A$2),"",$A$2) -> 2 | B29: =B28 -> Maryland Baltimore County | C29: =VLOOKUP(B29,unitid!A:B,2,FALSE) -> 163268 | D29: =IF(D28=2023,2017,D28+1) -> 2023 | E29: 0.654 | F29: =VLOOKUP(C29,'2023 (2)'!$A:$L,7,FALSE) -> 107432 | G29: =F29/VLOOKUP($D29,CPI!$P$16:$R$22,3,FALSE) -> 107432 | H29: =LN(G29) -> 11.584613 | I29: =VLOOKUP($C29,'2023 (2)'!$A:$L,11,FALSE)/VLOOKUP($C29,'2023 (2)'!$A:$L,10,FALSE) -> 47130.4 | J29: =VLOOKUP($C29,'2023 (2)'!$A:$L,11,FALSE)/VLOOKUP($C29,'2023 (2)'!$A:$L,9,FALSE) -> 29456.5 | K29: 841249 | L29: =K29/VLOOKUP($D29,CPI!$P$16:$R$22,3,FALSE) -> 841249 | M29: =IFERROR(IF(VLOOKUP(C29,'2023'!A:C,3,FALSE)="","",VLOOKUP(C29,'2023'!A:C,3,FALSE)),"") -> 182358 | N29: =M29/VLOOKUP($D29,CPI!$P$16:$R$22,3,FALSE) -> 182358
A30: =IF(ISBLANK(A$2),"",$A$2) -> 2 | B30: North Carolina Wilmington | C30: =VLOOKUP(B30,unitid!A:B,2,FALSE) -> 199218 | D30: 2017 | E30: 0.607 | F30: =VLOOKUP(C30,'2017 (2)'!$A:$L,7,FALSE) -> 48668 | G30: =F30/VLOOKUP($D30,CPI!$P$16:$R$22,3,FALSE) -> 60105.927 | H30: =LN(G30) -> 11.003864 | I30: =VLOOKUP($C30,'2017 (2)'!$A:$L,11,FALSE)/VLOOKUP($C30,'2017 (2)'!$A:$L,10,FALSE) -> 71935 | J30: =VLOOKUP($C30,'2017 (2)'!$A:$L,11,FALSE)/VLOOKUP($C30,'2017 (2)'!$A:$L,9,FALSE) -> 33569.667 | K30: 2711525 | L30: =K30/VLOOKUP($D30,CPI!$P$16:$R$22,3,FALSE) -> 3348786.1 | M30: =IFERROR(IF(VLOOKUP(C30,'2017'!A:C,3,FALSE)="","",VLOOKUP(C30,'2017'!A:C,3,FALSE)),"") -> 43343 | N30: =M30/VLOOKUP($D30,CPI!$P$16:$R$22,3,FALSE) -> 53529.449
A31: =IF(ISBLANK(A$2),"",$A$2) -> 2 | B31: =B30 -> North Carolina Wilmington | C31: =VLOOKUP(B31,unitid!A:B,2,FALSE) -> 199218 | D31: =IF(D30=2023,2017,D30+1) -> 2018 | E31: 0.393 | F31: =VLOOKUP(C31,'2018 (2)'!$A:$L,7,FALSE) -> 49303 | G31: =F31/VLOOKUP($D31,CPI!$P$16:$R$22,3,FALSE) -> 59547.948 | H31: =LN(G31) -> 10.994537 | I31: =VLOOKUP($C31,'2018 (2)'!$A:$L,11,FALSE)/VLOOKUP($C31,'2018 (2)'!$A:$L,10,FALSE) -> 61156.923 | J31: =VLOOKUP($C31,'2018 (2)'!$A:$L,11,FALSE)/VLOOKUP($C31,'2018 (2)'!$A:$L,9,FALSE) -> 26501.333 | K31: 4503599 | L31: =K31/VLOOKUP($D31,CPI!$P$16:$R$22,3,FALSE) -> 5439427.2 | M31: =IFERROR(IF(VLOOKUP(C31,'2018'!A:C,3,FALSE)="","",VLOOKUP(C31,'2018'!A:C,3,FALSE)),"") -> 50517 | N31: =M31/VLOOKUP($D31,CPI!$P$16:$R$22,3,FALSE) -> 61014.212
A32: =IF(ISBLANK(A$2),"",$A$2) -> 2 | B32: =B31 -> North Carolina Wilmington | C32: =VLOOKUP(B32,unitid!A:B,2,FALSE) -> 199218 | D32: =IF(D31=2023,2017,D31+1) -> 2019 | E32: 0.556 | F32: =VLOOKUP(C32,'2019 (2)'!$A:$L,7,FALSE) -> 51679 | G32: =F32/VLOOKUP($D32,CPI!$P$16:$R$22,3,FALSE) -> 61150.309 | H32: =LN(G32) -> 11.02109 | I32: =VLOOKUP($C32,'2019 (2)'!$A:$L,11,FALSE)/VLOOKUP($C32,'2019 (2)'!$A:$L,10,FALSE) -> 56187.857 | J32: =VLOOKUP($C32,'2019 (2)'!$A:$L,11,FALSE)/VLOOKUP($C32,'2019 (2)'!$A:$L,9,FALSE) -> 39331.5 | K32: 2467733 | L32: =K32/VLOOKUP($D32,CPI!$P$16:$R$22,3,FALSE) -> 2919999.1 | M32: =IFERROR(IF(VLOOKUP(C32,'2019'!A:C,3,FALSE)="","",VLOOKUP(C32,'2019'!A:C,3,FALSE)),"") -> 38890 | N32: =M32/VLOOKUP($D32,CPI!$P$16:$R$22,3,FALSE) -> 46017.444
A33: =IF(ISBLANK(A$2),"",$A$2) -> 2 | B33: =B32 -> North Carolina Wilmington | C33: =VLOOKUP(B33,unitid!A:B,2,FALSE) -> 199218 | D33: =IF(D32=2023,2017,D32+1) -> 2020 | E33: 0.483 | F33: =VLOOKUP(C33,'2020 (2)'!$A:$L,7,FALSE) -> 40967 | G33: =F33/VLOOKUP($D33,CPI!$P$16:$R$22,3,FALSE) -> 47728.554 | H33: =LN(G33) -> 10.773285 | I33: =VLOOKUP($C33,'2020 (2)'!$A:$L,11,FALSE)/VLOOKUP($C33,'2020 (2)'!$A:$L,10,FALSE) -> 41187.429 | J33: =VLOOKUP($C33,'2020 (2)'!$A:$L,11,FALSE)/VLOOKUP($C33,'2020 (2)'!$A:$L,9,FALSE) -> 36039 | K33: 2224148 | L33: =K33/VLOOKUP($D33,CPI!$P$16:$R$22,3,FALSE) -> 2591240.9 | M33: =IFERROR(IF(VLOOKUP(C33,'2020'!A:C,3,FALSE)="","",VLOOKUP(C33,'2020'!A:C,3,FALSE)),"") -> 7433 | N33: =M33/VLOOKUP($D33,CPI!$P$16:$R$22,3,FALSE) -> 8659.8076
A34: =IF(ISBLANK(A$2),"",$A$2) -> 2 | B34: =B33 -> North Carolina Wilmington | C34: =VLOOKUP(B34,unitid!A:B,2,FALSE) -> 199218 | D34: =IF(D33=2023,2017,D33+1) -> 2021 | E34: 0.25 | F34: =VLOOKUP(C34,'2021 (2)'!$A:$L,7,FALSE) -> 46967 | G34: =F34/VLOOKUP($D34,CPI!$P$16:$R$22,3,FALSE) -> 53487.753 | H34: =LN(G34) -> 10.887208 | I34: =VLOOKUP($C34,'2021 (2)'!$A:$L,11,FALSE)/VLOOKUP($C34,'2021 (2)'!$A:$L,10,FALSE) -> 44628.571 | J34: =VLOOKUP($C34,'2021 (2)'!$A:$L,11,FALSE)/VLOOKUP($C34,'2021 (2)'!$A:$L,9,FALSE) -> 39050 | K34: 1550308 | L34: =K34/VLOOKUP($D34,CPI!$P$16:$R$22,3,FALSE) -> 1765548 | M34: =IFERROR(IF(VLOOKUP(C34,'2021'!A:C,3,FALSE)="","",VLOOKUP(C34,'2021'!A:C,3,FALSE)),"") -> 3912 | N34: =M34/VLOOKUP($D34,CPI!$P$16:$R$22,3,FALSE) -> 4455.13
A35: =IF(ISBLANK(A$2),"",$A$2) -> 2 | B35: =B34 -> North Carolina Wilmington | C35: =VLOOKUP(B35,unitid!A:B,2,FALSE) -> 199218 | D35: =IF(D34=2023,2017,D34+1) -> 2022 | E35: 0.148 | F35: =VLOOKUP(C35,'2022 (2)'!$A:$L,7,FALSE) -> 48503 | G35: =F35/VLOOKUP($D35,CPI!$P$16:$R$22,3,FALSE) -> 51540.274 | H35: =LN(G35) -> 10.850119 | I35: =VLOOKUP($C35,'2022 (2)'!$A:$L,11,FALSE)/VLOOKUP($C35,'2022 (2)'!$A:$L,10,FALSE) -> 48683.429 | J35: =VLOOKUP($C35,'2022 (2)'!$A:$L,11,FALSE)/VLOOKUP($C35,'2022 (2)'!$A:$L,9,FALSE) -> 42598 | K35: 2342879 | L35: =K35/VLOOKUP($D35,CPI!$P$16:$R$22,3,FALSE) -> 2489590.9 | M35: =IFERROR(IF(VLOOKUP(C35,'2022'!A:C,3,FALSE)="","",VLOOKUP(C35,'2022'!A:C,3,FALSE)),"") -> 5017 | N35: =M35/VLOOKUP($D35,CPI!$P$16:$R$22,3,FALSE) -> 5331.1662
A36: =IF(ISBLANK(A$2),"",$A$2) -> 2 | B36: =B35 -> North Carolina Wilmington | C36: =VLOOKUP(B36,unitid!A:B,2,FALSE) -> 199218 | D36: =IF(D35=2023,2017,D35+1) -> 2023 | E36: 0.24 | F36: =VLOOKUP(C36,'2023 (2)'!$A:$L,7,FALSE) -> 49572 | G36: =F36/VLOOKUP($D36,CPI!$P$16:$R$22,3,FALSE) -> 49572 | H36: =LN(G36) -> 10.811181 | I36: =VLOOKUP($C36,'2023 (2)'!$A:$L,11,FALSE)/VLOOKUP($C36,'2023 (2)'!$A:$L,10,FALSE) -> 60407 | J36: =VLOOKUP($C36,'2023 (2)'!$A:$L,11,FALSE)/VLOOKUP($C36,'2023 (2)'!$A:$L,9,FALSE) -> 60407 | K36: 3297691 | L36: =K36/VLOOKUP($D36,CPI!$P$16:$R$22,3,FALSE) -> 3297691 | M36: =IFERROR(IF(VLOOKUP(C36,'2023'!A:C,3,FALSE)="","",VLOOKUP(C36,'2023'!A:C,3,FALSE)),"") -> 21818 | N36: =M36/VLOOKUP($D36,CPI!$P$16:$R$22,3,FALSE) -> 21818
A37: =IF(ISBLANK(A$2),"",$A$2) -> 2 | B37: Oregon State | C37: =VLOOKUP(B37,unitid!A:B,2,FALSE) -> 209542 | D37: =IF(D36=2023,2017,D36+1) -> 2017 | E37: 0.586 | F37: =VLOOKUP(C37,'2017 (2)'!$A:$L,7,FALSE) -> 266767 | G37: =F37/VLOOKUP($D37,CPI!$P$16:$R$22,3,FALSE) -> 329462.44 | H37: =LN(G37) -> 12.705218 | I37: =VLOOKUP($C37,'2017 (2)'!$A:$L,11,FALSE)/VLOOKUP($C37,'2017 (2)'!$A:$L,10,FALSE) -> 97690 | J37: =VLOOKUP($C37,'2017 (2)'!$A:$L,11,FALSE)/VLOOKUP($C37,'2017 (2)'!$A:$L,9,FALSE) -> 97690 | K37: 24140635 | L37: =K37/VLOOKUP($D37,CPI!$P$16:$R$22,3,FALSE) -> 29814154 | M37: =IFERROR(IF(VLOOKUP(C37,'2017'!A:C,3,FALSE)="","",VLOOKUP(C37,'2017'!A:C,3,FALSE)),"") -> 327500 | N37: =M37/VLOOKUP($D37,CPI!$P$16:$R$22,3,FALSE) -> 404468.87
A38: =IF(ISBLANK(A$2),"",$A$2) -> 2 | B38: =B37 -> Oregon State | C38: =VLOOKUP(B38,unitid!A:B,2,FALSE) -> 209542 | D38: =IF(D37=2023,2017,D37+1) -> 2018 | E38: 0.7 | F38: =VLOOKUP(C38,'2018 (2)'!$A:$L,7,FALSE) -> 240513 | G38: =F38/VLOOKUP($D38,CPI!$P$16:$R$22,3,FALSE) -> 290490.55 | H38: =LN(G38) -> 12.579326 | I38: =VLOOKUP($C38,'2018 (2)'!$A:$L,11,FALSE)/VLOOKUP($C38,'2018 (2)'!$A:$L,10,FALSE) -> 101745 | J38: =VLOOKUP($C38,'2018 (2)'!$A:$L,11,FALSE)/VLOOKUP($C38,'2018 (2)'!$A:$L,9,FALSE) -> 101745 | K38: 22399517 | L38: =K38/VLOOKUP($D38,CPI!$P$16:$R$22,3,FALSE) -> 27054039 | M38: =IFERROR(IF(VLOOKUP(C38,'2018'!A:C,3,FALSE)="","",VLOOKUP(C38,'2018'!A:C,3,FALSE)),"") -> 330601 | N38: =IFERROR(M38/VLOOKUP($D38,CPI!$P$16:$R$22,3,FALSE),"") -> 399298.45
A39: =IF(ISBLANK(A$2),"",$A$2) -> 2 | B39: =B38 -> Oregon State | C39: =VLOOKUP(B39,unitid!A:B,2,FALSE) -> 209542 | D39: =IF(D38=2023,2017,D38+1) -> 2019 | E39: 0.167 | F39: =VLOOKUP(C39,'2019 (2)'!$A:$L,7,FALSE) -> 257681 | G39: =F39/VLOOKUP($D39,CPI!$P$16:$R$22,3,FALSE) -> 304906.69 | H39: =LN(G39) -> 12.627761 | I39: =VLOOKUP($C39,'2019 (2)'!$A:$L,11,FALSE)/VLOOKUP($C39,'2019 (2)'!$A:$L,10,FALSE) -> 117843.5 | J39: =VLOOKUP($C39,'2019 (2)'!$A:$L,11,FALSE)/VLOOKUP($C39,'2019 (2)'!$A:$L,9,FALSE) -> 78562.333 | K39: 24042567 | L39: =K39/VLOOKUP($D39,CPI!$P$16:$R$22,3,FALSE) -> 28448894 | M39: =IFERROR(IF(VLOOKUP(C39,'2019'!A:C,3,FALSE)="","",VLOOKUP(C39,'2019'!A:C,3,FALSE)),"") -> 265053 | N39: =M39/VLOOKUP($D39,CPI!$P$16:$R$22,3,FALSE) -> 313629.77
A40: =IF(ISBLANK(A$2),"",$A$2) -> 2 | B40: =B39 -> Oregon State | C40: =VLOOKUP(B40,unitid!A:B,2,FALSE) -> 209542 | D40: =IF(D39=2023,2017,D39+1) -> 2020 | E40: 0.345 | F40: =VLOOKUP(C40,'2020 (2)'!$A:$L,7,FALSE) -> 267364 | G40: =F40/VLOOKUP($D40,CPI!$P$16:$R$22,3,FALSE) -> 311492.1 | H40: =LN(G40) -> 12.649129 | I40: =VLOOKUP($C40,'2020 (2)'!$A:$L,11,FALSE)/VLOOKUP($C40,'2020 (2)'!$A:$L,10,FALSE) -> 85230 | J40: =VLOOKUP($C40,'2020 (2)'!$A:$L,11,FALSE)/VLOOKUP($C40,'2020 (2)'!$A:$L,9,FALSE) -> 85230 | K40: 16130695 | L40: =K40/VLOOKUP($D40,CPI!$P$16:$R$22,3,FALSE) -> 18793047 | M40: =IFERROR(IF(VLOOKUP(C40,'2020'!A:C,3,FALSE)="","",VLOOKUP(C40,'2020'!A:C,3,FALSE)),"") -> 177140 | N40: =M40/VLOOKUP($D40,CPI!$P$16:$R$22,3,FALSE) -> 206376.74
...

Sheet Variable Revenue
A1: University | B1: FY | C1: Ticket Sales | D1: Guarantee | E1: Contributions | F1: Concessions | G1: Variable Revenue
A2: =Sheet1!B2 -> Arizona | B2: 2017 | C2: 15490786 | D2: 1051403 | E2: 18169527 | F2: 2934038 | G2: =SUM(C2:F2) -> 37645754
A3: =Sheet1!B3 -> Arizona | B3: 2018 | C3: 13768437 | D3: 534500 | E3: 23226028 | F3: 2433487 | G3: =SUM(C3:F3) -> 39962452
A4: =Sheet1!B4 -> Arizona | B4: 2019 | C4: 14584292 | D4: 321320 | E4: 20914842 | F4: 2110407 | G4: =SUM(C4:F4) -> 37930861
A5: =Sheet1!B5 -> Arizona | B5: 2020 | C5: 13031253 | D5: 533900 | E5: 23493464 | F5: 1876754 | G5: =SUM(C5:F5) -> 38935371
A6: =Sheet1!B6 -> Arizona | B6: 2021 | C6: 772925 | D6: 41400 | E6: 13779297 | F6: 563251 | G6: =SUM(C6:F6) -> 15156873
A7: =Sheet1!B7 -> Arizona | B7: 2022 | C7: 19164426 | D7: 1578936 | E7: 19865817 | F7: 2456996 | G7: =SUM(C7:F7) -> 43066175
A8: =Sheet1!B8 -> Arizona | B8: 2023 | C8: 17553528 | D8: 586813 | E8: 24531439 | F8: 3656522 | G8: =SUM(C8:F8) -> 46328302
A9: =Sheet1!B9 -> California | B9: 2017 | C9: 13483996 | D9: 2168848 | E9: 20486038 | F9: 835280 | G9: =SUM(C9:F9) -> 36974162
A10: =Sheet1!B10 -> California | B10: 2018 | C10: 10528294 | D10: 231510 | E10: 18098032 | F10: 662604 | G10: =SUM(C10:F10) -> 29520440
A11: =Sheet1!B11 -> California | B11: 2019 | C11: 11430872 | D11: 390000 | E11: 15235663 | F11: 867441 | G11: =SUM(C11:F11) -> 27923976
A12: =Sheet1!B12 -> California | B12: 2020 | C12: 8533447 | D12: 388500 | E12: 13285517 | F12: 812075 | G12: =SUM(C12:F12) -> 23019539
A13: =Sheet1!B13 -> California | B13: 2021 | C13: 121832 | D13: 0 | E13: 12009049 | F13: 74025 | G13: =SUM(C13:F13) -> 12204906
... A57: =Sheet1!B57 -> Weber State | B57: 2023 | C57: 701967 | D57: 757500 | E57: 1251171 | F57: 19175 | G57: =SUM(C57:F57) -> 2729813

Sheet CPI
A1: Consumer Price Index for All Urban Consumers (CPI-U)
A2: Original Data Value
A4: Series Id: | B4: CUUR0000SA0
A5: Not Seasonally Adjusted
A6: Series Title: | B6: All items in U.S. city average, all urban consumers, not seasonally adjusted
A7: Area: | B7: U.S. city average
A8: Item: | B8: All items
A9: Base Period: | B9: 1982-84=100
A10: Years: | B10: 2014 to 2024
A12: Year | B12: Jan | C12: Feb | D12: Mar | E12: Apr | F12: May | G12: Jun | H12: Jul | I12: Aug | J12: Sep | K12: Oct | L12: Nov | M12: Dec | N12: HALF1 | O12: HALF2
A13: 2014 | B13: 233.916 | C13: 234.781 | D13: 236.293 | E13: 237.072 | F13: 237.9 | G13: 238.343 | H13: 238.25 | I13: 237.852 | J13: 238.031 | K13: 237.433 | L13: 236.151 | M13: 234.812 | N13: 236.384 | O13: 237.088
A14: 2015 | B14: 233.707 | C14: 234.722 | D14: 236.119 | E14: 236.599 | F14: 237.805 | G14: 238.638 | H14: 238.654 | I14: 238.316 | J14: 237.945 | K14: 237.838 | L14: 237.336 | M14: 236.525 | N14: 236.265 | O14: 237.769
A15: 2016 | B15: 236.916 | C15: 237.111 | D15: 238.132 | E15: 239.261 | F15: 240.229 | G15: 241.018 | H15: 240.628 | I15: 240.849 | J15: 241.428 | K15: 241.729 | L15: 241.353 | M15: 241.432 | N15: 238.778 | O15: 241.237
A16: 2017 | B16: 242.839 | C16: 243.603 | D16: 243.801 | E16: 244.524 | F16: 244.733 | G16: 244.955 | H16: 244.786 | I16: 245.519 | J16: 246.819 | K16: 246.663 | L16: 246.669 | M16: 246.524 | N16: 244.076 | O16: 246.163 | P16: 2017 | Q16: =AVERAGE(N16,O15) -> 242.6565 | R16: =Q16/Q$22 -> 0.80970384
A17: 2018 | B17: 247.867 | C17: 248.991 | D17: 249.554 | E17: 250.546 | F17: 251.588 | G17: 251.989 | H17: 252.006 | I17: 252.146 | J17: 252.439 | K17: 252.885 | L17: 252.038 | M17: 251.233 | N17: 250.089 | O17: 252.125 | P17: =P16+1 -> 2018 | Q17: =AVERAGE(N17,O16) -> 248.126 | R17: =Q17/Q$22 -> 0.82795464
A18: 2019 | B18: 251.712 | C18: 252.776 | D18: 254.202 | E18: 255.548 | F18: 256.092 | G18: 256.143 | H18: 256.571 | I18: 256.558 | J18: 256.759 | K18: 257.346 | L18: 257.208 | M18: 256.974 | N18: 254.412 | O18: 256.903 | P18: =P17+1 -> 2019 | Q18: =AVERAGE(N18,O17) -> 253.2685 | R18: =Q18/Q$22 -> 0.84511429
A19: 2020 | B19: 257.971 | C19: 258.678 | D19: 258.115 | E19: 256.389 | F19: 256.394 | G19: 257.797 | H19: 259.101 | I19: 259.918 | J19: 260.28 | K19: 260.388 | L19: 260.229 | M19: 260.474 | N19: 257.557 | O19: 260.065 | P19: =P18+1 -> 2020 | Q19: =AVERAGE(N19,O18) -> 257.23 | R19: =Q19/Q$22 -> 0.85833315
A20: 2021 | B20: 261.582 | C20: 263.014 | D20: 264.877 | E20: 267.054 | F20: 269.195 | G20: 271.696 | H20: 273.003 | I20: 273.567 | J20: 274.31 | K20: 276.589 | L20: 277.948 | M20: 278.802 | N20: 266.236 | O20: 275.703 | P20: =P19+1 -> 2021 | Q20: =AVERAGE(N20,O19) -> 263.1505 | R20: =Q20/Q$22 -> 0.87808886
A21: 2022 | B21: 281.148 | C21: 283.716 | D21: 287.504 | E21: 289.109 | F21: 292.296 | G21: 296.311 | H21: 296.276 | I21: 296.171 | J21: 296.808 | K21: 298.012 | L21: 297.711 | M21: 296.797 | N21: 288.347 | O21: 296.963 | P21: =P20+1 -> 2022 | Q21: =AVERAGE(N21,O20) -> 282.025 | R21: =Q21/Q$22 -> 0.94106989
A22: 2023 | B22: 299.17 | C22: 300.84 | D22: 301.836 | E22: 303.363 | F22: 304.127 | G22: 305.109 | H22: 305.691 | I22: 307.026 | J22: 307.789 | K22: 307.671 | L22: 307.051 | M22: 306.746 | N22: 302.408 | O22: 306.996 | P22: =P21+1 -> 2023 | Q22: =AVERAGE(N22,O21) -> 299.6855 | R22: =Q22/Q$22 -> 1
A23: 2024 | B23: 308.417 | C23: 310.326 | D23: 312.332 | E23: 313.548 | F23: 314.069 | G23: 314.175 | H23: 314.54 | I23: 314.796 | J23: 315.301 | N23: 312.145

Sheet unitid
A1: Univeristy | B1: unitid
A2: Akron | B2: 200800
A3: Alabama | B3: 100751
A4: Alabama A&M | B4: 100654
A5: Alabama State | B5: 100724
A6: Albany | B6: 196060
A7: Alcorn State | B7: 175342
A8: Appalachian State | B8: 197869
A9: Arizona | B9: 104179
A10: Arizona State | B10: 104151
A11: Arkansas | B11: 106397
A12: Arkansas Little Rock | B12: 106245
A13: Arkansas Pine Bluff | B13: 106412
... A229: Youngstown State | B229: 206695

Sheet 2017
A1: unitid | B1: University | C1: Total Revenue
A2: 200800 | B2: Akron | C2: 28308
A3: 100751 | B3: Alabama | C3: 685786
A4: 196060 | B4: Albany | C4: 163500
A5: 197869 | B5: Appalachian State | C5: 23268
A6: 104179 | B6: Arizona | C6: 580596
A7: 104151 | B7: Arizona State | C7: 282820
A8: 106397 | B8: Arkansas | C8: 98004
A9: 106245 | B9: Arkansas Little Rock | C9: 201888
A10: 106412 | B10: Arkansas Pine Bluff
A11: 106458 | B11: Arkansas State | C11: 288783
A12: 500001 | B12: Army | C12: 280704
A13: 100858 | B13: Auburn | C13: 119703
A14: 219602 | B14: Austin Peay State | C14: 8578
A15: 150136 | B15: Ball State | C15: 103674
A16: 196079 | B16: Binghamton | C16: 634408
A17: 142115 | B17: Boise State | C17: 439989
A18: 142115 | B18: Boise State
A19: 201441 | B19: Bowling Green | C19: 29614
A20: 196088 | B20: Buffalo | C20: 783529
A21: 110422 | B21: Cal Poly | C21: 66081
A22: 110486 | B22: Cal State Bakersfield | C22: 93169
A23: 110565 | B23: Cal State Fullerton | C23: 696791
A24: 110608 | B24: Cal State Northridge | C24: 52093
A25: 110635 | B25: California | C25: 106601
A26: 106704 | B26: Central Arkansas | C26: 434084
A27: 128771 | B27: Central Connecticut State | C27: 775853
A28: 169248 | B28: Central Michigan | C28: 24012
A29: 199139 | B29: Charlotte | C29: 821089
A30: 144005 | B30: Chicago State | C30: 18000
... A210: 206695 | B210: Youngstown State | C210: 101494

Sheet 2018
A1: unitid | B1: University | C1: Total Revenue
A2: 200800 | B2: Akron | C2: 39575
A3: 100751 | B3: Alabama | C3: 696957
A4: 196060 | B4: Albany | C4: 163592
A5: 197869 | B5: Appalachian State | C5: 20359
A6: 104179 | B6: Arizona | C6: 574321
A7: 104151 | B7: Arizona State | C7: 265602
A8: 106397 | B8: Arkansas | C8: 116915
A9: 106245 | B9: Arkansas Little Rock | C9: 150262
A10: 106412 | B10: Arkansas Pine Bluff
A11: 106458 | B11: Arkansas State | C11: 314732
A12: 500001 | B12: Army | C12: 515232
A13: 100858 | B13: Auburn | C13: 112977
A14: 219602 | B14: Austin Peay State | C14: 22251
A15: 150136 | B15: Ball State | C15: 146004
A16: 196079 | B16: Binghamton | C16: 600733
A17: 142115 | B17: Boise State | C17: 584155
A18: 201441 | B18: Bowling Green | C18: 33453
A19: 196088 | B19: Buffalo | C19: 948949
A20: 110422 | B20: Cal Poly | C20: 107438
A21: 110486 | B21: Cal State Bakersfield | C21: 60221
A22: 110565 | B22: Cal State Fullerton | C22: 746763
... A47: 433660 | B47: Florida Gulf Coast | C47: 155997
A48: 133951 | B48: Florida International
A49: 134097 | B49: Florida State | C49: 1471982
A50: 110556 | B50: Fresno State | C50: 458562
A51: 139959 | B51: Georgia | C51: 76111
A52: 139931 | B52: Georgia Southern | C52: 105572
A53: 139940 | B53: Georgia State | C53: 245794
A54: 139755 | B54: Georgia Tech | C54: 273832
A55: 159009 | B55: Grambling State | C55: 3000
A56: 141574 | B56: Hawaii | C56: 1529511
A57: 225511 | B57: Houston | C57: 14485
A58: 142285 | B58: Idaho | C58: 773743
A59: 142276 | B59: Idaho State | C59: 394228
A60: 145637 | B60: Illinois | C60: 587156
... A133: 214777 | B133: Penn State | C133: 964378
A134: 209807 | B134: Portland State
A135: 227526 | B135: Prairie View A&M | C135: 412927
A136: 243780 | B136: Purdue | C136: 693543
...

Sheet 2019
A1: unitid | B1: University | C1: Total Revenue
A2: 200800 | B2: Akron | C2: 43396
A3: 100751 | B3: Alabama | C3: 766423
A4: 196060 | B4: Albany | C4: 368635
A5: 175342 | B5: Alcorn State | C5: 0
A6: 197869 | B6: Appalachian State | C6: 15026
A7: 104179 | B7: Arizona | C7: 564020
A8: 104151 | B8: Arizona State | C8: 434483
A9: 106397 | B9: Arkansas | C9: 89709
A10: 106245 | B10: Arkansas Little Rock | C10: 210413
A11: 106245 | B11: Arkansas Little Rock | C11: 210413
A12: 106412 | B12: Arkansas Pine Bluff | C12: 895
A13: 106458 | B13: Arkansas State | C13: 277231
... A84: 163286 | B84: Maryland | C84: 226606
A85: 163268 | B85: Maryland Baltimore County
A86: 163338 | B86: Maryland Eastern Shore | C86: 22450
A87: 166513 | B87: Massachusetts Lowell | C87: 739861
A88: 159717 | B88: McNeese State | C88: 548852
A89: 220862 | B89: Memphis | C89: 3150
A90: 204024 | B90: Miami (Ohio) | C90: 1131824
A91: 170976 | B91: Michigan | C91: 235969
A92: 171100 | B92: Michigan State | C92: 598491
A93: 220978 | B93: Middle Tennessee State | C93: 1081763
A94: 174066 | B94: Minnesota | C94: 737064
A95: 176017 | B95: Mississippi | C95: 301534
A96: 176080 | B96: Mississippi State | C96: 86518
A97: 178396 | B97: Missouri | C97: 300174
... A210: 206695 | B210: Youngstown State | C210: 14915

Sheet 2020
A1: unitid | B1: University | C1: Total Revenue
A2: 200800 | B2: Akron | C2: 58266
A3: 100751 | B3: Alabama | C3: 712212
A4: 196060 | B4: Albany | C4: 297632
A5: 197869 | B5: Appalachian State | C5: 22549
A6: 104179 | B6: Arizona | C6: 515627
A7: 104151 | B7: Arizona State | C7: 365008
A8: 106397 | B8: Arkansas | C8: 217133
A9: 106245 | B9: Arkansas Little Rock | C9: 175084
A10: 106412 | B10: Arkansas Pine Bluff | C10: 2000
A11: 106458 | B11: Arkansas State | C11: 300668
A12: 500001 | B12: Army | C12: 632937
A13: 100858 | B13: Auburn | C13: 126690
... A207: 206695 | B207: Youngstown State | C207: 16820

Sheet 2021
A1: unitid | B1: University | C1: Total Revenue
A2: 200800 | B2: Akron | C2: 12644
A3: 100751 | B3: Alabama | C3: 751737
A4: 100654 | B4: Alabama A&M | C4: 0
A5: 196060 | B5: Albany | C5: 151505
A6: 197869 | B6: Appalachian State | C6: 4827
A7: 104179 | B7: Arizona | C7: 440705
A8: 104151 | B8: Arizona State | C8: 272165
A9: 106397 | B9: Arkansas | C9: 171704
A10: 106245 | B10: Arkansas Little Rock | C10: 267793
A11: 106412 | B11: Arkansas Pine Bluff
A12: 106458 | B12: Arkansas State | C12: 361704
A13: 500001 | B13: Army | C13: 360972
A14: 100858 | B14: Auburn | C14: 140287
A15: 219602 | B15: Austin Peay State | C15: 126105
A16: 150136 | B16: Ball State
A17: 196079 | B17: Binghamton | C17: 670402
A18: 142115 | B18: Boise State | C18: 471399
A19: 201441 | B19: Bowling Green | C19: 23564
A20: 196088 | B20: Buffalo | C20: 978293
A21: 110422 | B21: Cal Poly | C21: 107521
A22: 110486 | B22: Cal State Bakersfield | C22: 13641
A23: 110565 | B23: Cal State Fullerton | C23: 714829
A24: 110608 | B24: Cal State Northridge | C24: 419606
A25: 110635 | B25: California | C25: 104836
A26: 106704 | B26: Central Arkansas | C26: 405696
A27: 128771 | B27: Central Connecticut State | C27: 709545
A28: 169248 | B28: Central Michigan | C28: 54511
... A88: 159717 | B88: McNeese State | C88: 400170
A89: 220862 | B89: Memphis
A90: 204024 | B90: Miami (Ohio) | C90: 906374
A91: 170976 | B91: Michigan | C91: 77495
A92: 171100 | B92: Michigan State | C92: 270733
A93: 220978 | B93: Middle Tennessee State | C93: 968751
A94: 174066 | B94: Minnesota | C94: 178579
A95: 176017 | B95: Mississippi | C95: 374475
A96: 176080 | B96: Mississippi State | C96: 9629
A97: 176044 | B97: Mississippi Valley State
A98: 178396 | B98: Missouri | C98: 121988
A99: 178402 | B99: Missouri Kansas City | C99: 655408
...

Sheet 2022
A1: unitid | B1: University | C1: Total Revenue
A2: 500002 | B2: Air Force | C2: 454549
A3: 200800 | B3: Akron | C3: 10009
A4: 100751 | B4: Alabama | C4: 772219
A5: 196060 | B5: Albany | C5: 305327
A6: 175342 | B6: Alcorn State
A7: 197869 | B7: Appalachian State | C7: 49822
A8: 104179 | B8: Arizona | C8: 602965
A9: 104151 | B9: Arizona State | C9: 351425
A10: 106397 | B10: Arkansas | C10: 37727
A11: 106245 | B11: Arkansas Little Rock | C11: 165686
A12: 106412 | B12: Arkansas Pine Bluff | C12: 8
A13: 106458 | B13: Arkansas State | C13: 417047
A14: 500001 | B14: Army | C14: 467272
A15: 100858 | B15: Auburn | C15: 260056
A16: 219602 | B16: Austin Peay State | C16: 518807
A17: 150136 | B17: Ball State | C17: 43793
A18: 196079 | B18: Binghamton | C18: 692182
... A30: 199139 | B30: Charlotte | C30: 809947
A31: 144005 | B31: Chicago State
A32: 201885 | B32: Cincinnati | C32: 329790
A33: 217882 | B33: Clemson | C33: 947058
A34: 202134 | B34: Cleveland State | C34: 609463
A35: 218724 | B35: Coastal Carolina | C35: 1152880
A36: 217819 | B36: College of Charleston | C36: 76188
A37: 126614 | B37: Colorado | C37: 530417
A38: 126818 | B38: Colorado State | C38: 1187997
A39: 129020 | B39: Connecticut | C39: 198881
A40: 162283 | B40: Coppin State | C40: 100989
A41: 198464 | B41: East Carolina | C41: 32508
A42: 220075 | B42: East Tennessee State | C42: 8387
A43: 144892 | B43: Eastern Illinois | C43: 223400
... A212: 206695 | B212: Youngstown State | C212: 4795

Sheet 2023
A1: unitid | B1: University | C1: Total Revenue
A2: 500002 | B2: Air Force | C2: 435509
A3: 200800 | B3: Akron | C3: 6649
A4: 100751 | B4: Alabama | C4: 920161
A5: 196060 | B5: Albany | C5: 307155
A6: 197869 | B6: Appalachian State | C6: 35560
A7: 104179 | B7: Arizona | C7: 606900
A8: 104151 | B8: Arizona State | C8: 779128
A9: 106397 | B9: Arkansas | C9: 83968
A10: 106245 | B10: Arkansas Little Rock | C10: 119588
A11: 106412 | B11: Arkansas Pine Bluff | C11: 9451
A12: 106458 | B12: Arkansas State | C12: 481626
A13: 100858 | B13: Auburn | C13: 414405
... A38: 129020 | B38: Connecticut | C38: 199348
A39: 162283 | B39: Coppin State
A40: 198464 | B40: East Carolina | C40: 36751
A41: 220075 | B41: East Tennessee State | C41: 22813
A42: 144892 | B42: Eastern Illinois | C42: 304685
A43: 156620 | B43: Eastern Kentucky | C43: 723165
A44: 169798 | B44: Eastern Michigan | C44: 808689
A45: 235097 | B45: Eastern Washington | C45: 621815
A46: 134130 | B46: Florida | C46: 929104
A47: 133669 | B47: Florida Atlantic | C47: 473073
A48: 433660 | B48: Florida Gulf Coast | C48: 422983
A49: 133951 | B49: Florida International | C49: 232385
A50: 134097 | B50: Florida State | C50: 610394
A51: 110556 | B51: Fresno State | C51: 276850
... A183: 230764 | B183: Utah | C183: 644263
A184: 230728 | B184: Utah State
A185: 230737 | B185: Utah Valley
A186: 228796 | B186: UTEP | C186: 383224
A187: 227368 | B187: UTRGV | C187: 71481
A188: 229027 | B188: UTSA | C188: 182763
A189: 234030 | B189: VCU | C189: 38399
A190: 234076 | B190: Virginia | C190: 1217867
A191: 233921 | B191: Virginia Tech | C191: 94246
A192: 236948 | B192: Washington | C192: 1257148
A193: 236939 | B193: Washington State | C193: 1858962
A194: 230782 | B194: Weber State | C194: 496824
A195: 238032 | B195: West Virginia | C195: 213295
...

Sheet 2017 (2)
A1: unitid | B1: University | C1: Gender | D1: Sport | E1: Number of Positions | F1: FTE | G1: Coaching Salaries | H1: Coaching Other Comp | I1: Number of Positions | J1: FTE | K1: Coaching Salaries | L1: Coaching Other Comp
A2: 200800 | B2: Akron | C2: Female | D2: Volleyball | E2: 1 | F2: 1 | G2: 126210 | H2: 0 | I2: 2 | J2: 2 | K2: 103723 | L2: 0
A3: 100751 | B3: Alabama | C3: Female | D3: Volleyball | E3: 1 | F3: 1 | G3: 220770 | H3: 0 | I3: 2 | J3: 2 | K3: 191378 | L3: 0
A4: 196060 | B4: Albany | C4: Female | D4: Volleyball | E4: 1 | F4: 1 | G4: 67310 | H4: 0 | I4: 2 | J4: 2 | K4: 91020 | L4: 0
A5: 197869 | B5: Appalachian State | C5: Female | D5: Volleyball | E5: 1 | F5: 1 | G5: 110123 | H5: 0 | I5: 2 | J5: 2 | K5: 100730 | L5: 0
A6: 104179 | B6: Arizona | C6: Female | D6: Volleyball | E6: 1 | F6: 1 | G6: 204778 | H6: 25700 | I6: 2 | J6: 2 | K6: 196452 | L6: 0
A7: 104151 | B7: Arizona State | C7: Female | D7: Volleyball | E7: 1 | F7: 1 | G7: 211449 | H7: 8465 | I7: 2 | J7: 2 | K7: 102177 | L7: 3300
A8: 106397 | B8: Arkansas | C8: Female | D8: Volleyball | E8: 1 | F8: 1 | G8: 260247 | H8: 0 | I8: 2 | J8: 2 | K8: 177511 | L8: 0
A9: 106245 | B9: Arkansas Little Rock | C9: Female | D9: Volleyball | E9: 1 | F9: 1 | G9: 83629 | H9: 17183 | I9: 1 | J9: 1.5 | K9: 48114 | L9: 12282
A10: 106412 | B10: Arkansas Pine Bluff | C10: Female | D10: Volleyball | E10: 1 | F10: 1 | G10: 56784 | H10: 0 | I10: 0 | J10: 0 | K10: 0 | L10: 0
A11: 106458 | B11: Arkansas State | C11: Female | D11: Volleyball | E11: 1 | F11: 1 | G11: 94997 | H11: 0 | I11: 2 | J11: 2 | K11: 46813 | L11: 1936
A12: 100858 | B12: Auburn | C12: Female | D12: Volleyball | E12: 1 | F12: 1 | G12: 164878 | H12: 0 | I12: 2 | J12: 2 | K12: 161150 | L12: 0
A13: 219602 | B13: Austin Peay State | C13: Female | D13: Volleyball | E13: 1 | F13: 0.5 | G13: 36760 | H13: 0 | I13: 1 | J13: 0.5 | K13: 23643 | L13: 0
... A204: 206695 | B204: Youngstown State | C204: Female | D204: Volleyball | E204: 1 | F204: 1 | G204: 87618 | H204: 0 | I204: 2 | J204: 1 | K204: 65229 | L204: 0

Sheet 2018 (2)
A1: unitid | B1: University | C1: Gender | D1: Sport | E1: Number of Positions | F1: FTE | G1: Coaching Salaries | H1: Coaching Other Comp | I1: Number of Positions | J1: FTE | K1: Coaching Salaries | L1: Coaching Other Comp
A2: 200800 | B2: Akron | C2: Female | D2: Volleyball | E2: 1 | F2: 1 | G2: 126680 | H2: 0 | I2: 2 | J2: 2 | K2: 108446 | L2: 0
A3: 100751 | B3: Alabama | C3: Female | D3: Volleyball | E3: 1 | F3: 1 | G3: 209697 | H3: 0 | I3: 2 | J3: 2 | K3: 222885 | L3: 0
A4: 196060 | B4: Albany | C4: Female | D4: Volleyball | E4: 1 | F4: 1 | G4: 65689 | H4: 0 | I4: 2 | J4: 2 | K4: 91022 | L4: 0
A5: 197869 | B5: Appalachian State | C5: Female | D5: Volleyball | E5: 1 | F5: 1 | G5: 110134 | H5: 0 | I5: 2 | J5: 2 | K5: 103670 | L5: 0
A6: 104179 | B6: Arizona | C6: Female | D6: Volleyball | E6: 1 | F6: 1 | G6: 199320 | H6: 25700 | I6: 2 | J6: 2 | K6: 200376 | L6: 0
A7: 104151 | B7: Arizona State | C7: Female | D7: Volleyball | E7: 1 | F7: 1 | G7: 164267 | H7: 0 | I7: 2 | J7: 2 | K7: 159794 | L7: 0
A8: 106397 | B8: Arkansas | C8: Female | D8: Volleyball | E8: 1 | F8: 1 | G8: 244496 | H8: 0 | I8: 2 | J8: 2 | K8: 190183 | L8: 0
A9: 106245 | B9: Arkansas Little Rock | C9: Female | D9: Volleyball | E9: 1 | F9: 1 | G9: 83714 | H9: 17660 | I9: 2 | J9: 1.5 | K9: 61941 | L9: 13850
A10: 106412 | B10: Arkansas Pine Bluff | C10: Female | D10: Volleyball | E10: 1 | F10: 1 | G10: 55186 | H10: 0 | I10: 0 | J10: 0 | K10: 0 | L10: 0
A11: 106458 | B11: Arkansas State | C11: Female | D11: Volleyball | E11: 1 | F11: 1 | G11: 96023 | H11: 0 | I11: 1 | J11: 1 | K11: 47332 | L11: 3600
A12: 100858 | B12: Auburn | C12: Female | D12: Volleyball | E12: 1 | F12: 1 | G12: 175143 | H12: 0 | I12: 2 | J12: 2 | K12: 177408 | L12: 0
A13: 219602 | B13: Austin Peay State | C13: Female | D13: Volleyball | E13: 1 | F13: 0.5 | G13: 93196 | H13: 0 | I13: 2 | J13: 0.5 | K13: 33979 | L13: 0
... A200: 206695 | B200: Youngstown State | C200: Female | D200: Volleyball | E200: 1 | F200: 1 | G200: 100780 | H200: 0 | I200: 2 | J200: 1 | K200: 61890 | L200: 0

Sheet 2019 (2)
A1: unitid | B1: University | C1: Gender | D1: Sport | E1: Number of Positions | F1: FTE | G1: Coaching Salaries | H1: Coaching Other Comp | I1: Number of Positions | J1: FTE | K1: Coaching Salaries | L1: Coaching Other Comp
A2: 200800 | B2: Akron | C2: Female | D2: Volleyball | E2: 1 | F2: 1 | G2: 131435 | H2: 0 | I2: 2 | J2: 2 | K2: 99715 | L2: 0
A3: 100751 | B3: Alabama | C3: Female | D3: Volleyball | E3: 1 | F3: 1 | G3: 241839 | H3: 0 | I3: 2 | J3: 2 | K3: 219860 | L3: 0
A4: 196060 | B4: Albany | C4: Female | D4: Volleyball | E4: 1 | F4: 0.92 | G4: 104330 | H4: 0 | I4: 2 | J4: 1.5 | K4: 125056 | L4: 0
A5: 197869 | B5: Appalachian State | C5: Female | D5: Volleyball | E5: 1 | F5: 1 | G5: 113798 | H5: 0 | I5: 2 | J5: 2 | K5: 121554 | L5: 0
A6: 104179 | B6: Arizona | C6: Female | D6: Volleyball | E6: 1 | F6: 1 | G6: 200474 | H6: 26700 | I6: 2 | J6: 2 | K6: 201786 | L6: 0
A7: 104151 | B7: Arizona State | C7: Female | D7: Volleyball | E7: 1 | F7: 1 | G7: 170136 | H7: 0 | I7: 2 | J7: 2 | K7: 165590 | L7: 0
A8: 106397 | B8: Arkansas | C8: Female | D8: Volleyball | E8: 1 | F8: 1 | G8: 245671 | H8: 0 | I8: 2 | J8: 2 | K8: 166899 | L8: 0
A9: 106245 | B9: Arkansas Little Rock | C9: Female | D9: Volleyball | E9: 1 | F9: 1 | G9: 83688 | H9: 8656 | I9: 2 | J9: 1.5 | K9: 74723 | L9: 1062
A10: 106412 | B10: Arkansas Pine Bluff | C10: Female | D10: Volleyball | E10: 1 | F10: 1 | G10: 57713 | H10: 0 | I10: 0 | J10: 0 | K10: 0 | L10: 0
A11: 106458 | B11: Arkansas State | C11: Female | D11: Volleyball | E11: 1 | F11: 1 | G11: 93305 | H11: 3083 | I11: 1 | J11: 1 | K11: 47697 | L11: 3750
A12: 100858 | B12: Auburn | C12: Female | D12: Volleyball | E12: 1 | F12: 1 | G12: 179782 | H12: 0 | I12: 2 | J12: 2 | K12: 191080 | L12: 0
A13: 219602 | B13: Austin Peay State | C13: Female | D13: Volleyball | E13: 1 | F13: 0.75 | G13: 84718 | H13: 0 | I13: 2 | J13: 1.5 | K13: 60961 | L13: 0
... A194: 206695 | B194: Youngstown State | C194: Female | D194: Volleyball | E194: 1 | F194: 1 | G194: 95420 | H194: 0 | I194: 2 | J194: 1 | K194: 61207 | L194: 0

Sheet 2020 (2)
A1: unitid | B1: University | C1: Gender | D1: Sport | E1: Number of Positions | F1: FTE | G1: Coaching Salaries | H1: Coaching Other Comp | I1: Number of Positions | J1: FTE | K1: Coaching Salaries | L1: Coaching Other Comp
A2: 200800 | B2: Akron | C2: Female | D2: Volleyball | E2: 1 | F2: 1 | G2: 133145 | H2: 0 | I2: 2 | J2: 2 | K2: 80082 | L2: 0
A3: 100751 | B3: Alabama | C3: Female | D3: Volleyball | E3: 1 | F3: 1 | G3: 263106 | H3: 0 | I3: 2 | J3: 2 | K3: 222807 | L3: 0
A4: 196060 | B4: Albany | C4: Female | D4: Volleyball | E4: 1 | F4: 1 | G4: 118350 | H4: 0 | I4: 2 | J4: 2 | K4: 154805 | L4: 0
A5: 197869 | B5: Appalachian State | C5: Female | D5: Volleyball | E5: 1 | F5: 1 | G5: 115290 | H5: 0 | I5: 2 | J5: 2 | K5: 104298 | L5: 0
A6: 104179 | B6: Arizona | C6: Female | D6: Volleyball | E6: 1 | F6: 1 | G6: 237177 | H6: 19500 | I6: 2 | J6: 2 | K6: 191055 | L6: 0
A7: 104151 | B7: Arizona State | C7: Female | D7: Volleyball | E7: 1 | F7: 1 | G7: 194724 | H7: 0 | I7: 2 | J7: 2 | K7: 185502 | L7: 0
A8: 106397 | B8: Arkansas | C8: Female | D8: Volleyball | E8: 1 | F8: 1 | G8: 241719 | H8: 0 | I8: 2 | J8: 2 | K8: 186829 | L8: 0
A9: 106245 | B9: Arkansas Little Rock | C9: Female | D9: Volleyball | E9: 1 | F9: 1 | G9: 83833 | H9: 500 | I9: 2 | J9: 1.5 | K9: 55942 | L9: 0
A10: 106412 | B10: Arkansas Pine Bluff | C10: Female | D10: Volleyball | E10: 1 | F10: 1 | G10: 62835 | H10: 0 | I10: 0 | J10: 0 | K10: 0 | L10: 0
A11: 106458 | B11: Arkansas State | C11: Female | D11: Volleyball | E11: 1 | F11: 1 | G11: 94980 | H11: 13225 | I11: 1 | J11: 1 | K11: 48159 | L11: 3600
A12: 100858 | B12: Auburn | C12: Female | D12: Volleyball | E12: 1 | F12: 1 | G12: 233637 | H12: 0 | I12: 2 | J12: 2 | K12: 210325 | L12: 0
A13: 219602 | B13: Austin Peay State | C13: Female | D13: Volleyball | E13: 1 | F13: 0.5 | G13: 56452 | H13: 0 | I13: 2 | J13: 1.5 | K13: 66588 | L13: 0
... A193: 206695 | B193: Youngstown State | C193: Female | D193: Volleyball | E193: 1 | F193: 1 | G193: 101827 | H193: 0 | I193: 2 | J193: 1 | K193: 95401 | L193: 0

Sheet 2021 (2)
A1: unitid | B1: University | C1: Gender | D1: Sport | E1: Number of Positions | F1: FTE | G1: Coaching Salaries | H1: Coaching Other Comp | I1: Number of Positions | J1: FTE | K1: Coaching Salaries | L1: Coaching Other Comp
A2: 200800 | B2: Akron | C2: Female | D2: Volleyball | E2: 1 | F2: 1 | G2: 112894 | H2: 0 | I2: 1 | J2: 1 | K2: 39270 | L2: 0
A3: 100751 | B3: Alabama | C3: Female | D3: Volleyball | E3: 1 | F3: 1 | G3: 236368 | H3: 0 | I3: 2 | J3: 2 | K3: 203052 | L3: 0
A4: 196060 | B4: Albany | C4: Female | D4: Volleyball | E4: 1 | F4: 1 | G4: 116213 | H4: 0 | I4: 2 | J4: 2 | K4: 107163 | L4: 0
A5: 197869 | B5: Appalachian State | C5: Female | D5: Volleyball | E5: 1 | F5: 1 | G5: 114925 | H5: 0 | I5: 2 | J5: 2 | K5: 103489 | L5: 0
A6: 104179 | B6: Arizona | C6: Female | D6: Volleyball | E6: 1 | F6: 1 | G6: 214998 | H6: 22200 | I6: 2 | J6: 2 | K6: 170898 | L6: 0
A7: 104151 | B7: Arizona State | C7: Female | D7: Volleyball | E7: 1 | F7: 1 | G7: 217395 | H7: 0 | I7: 2 | J7: 2 | K7: 217291 | L7: 0
A8: 106397 | B8: Arkansas | C8: Female | D8: Volleyball | E8: 1 | F8: 1 | G8: 231769 | H8: 0 | I8: 2 | J8: 2 | K8: 180856 | L8: 0
A9: 106245 | B9: Arkansas Little Rock | C9: Female | D9: Volleyball | E9: 1 | F9: 1 | G9: 86476 | H9: 9600 | I9: 2 | J9: 1.5 | K9: 76866 | L9: 0
A10: 106412 | B10: Arkansas Pine Bluff | C10: Female | D10: Volleyball | E10: 1 | F10: 1 | G10: 64487 | H10: 0 | I10: 1 | J10: 1 | K10: 35603 | L10: 0
A11: 106458 | B11: Arkansas State | C11: Female | D11: Volleyball | E11: 1 | F11: 1 | G11: 98648 | H11: 11567 | I11: 1 | J11: 1 | K11: 49011 | L11: 3600
A12: 100858 | B12: Auburn | C12: Female | D12: Volleyball | E12: 1 | F12: 1 | G12: 285080 | H12: 0 | I12: 2 | J12: 2 | K12: 211482 | L12: 0
A13: 219602 | B13: Austin Peay State | C13: Female | D13: Volleyball | E13: 1 | F13: 0.5 | G13: 59957 | H13: 0 | I13: 2 | J13: 1.5 | K13: 54142 | L13: 0
... A107: 199218 | B107: North Carolina Wilmington | C107: Female | D107: Volleyball | E107: 1 | F107: 0.5 | G107: 46967 | H107: 0 | I107: 2 | J107: 1.75 | K107: 78100 | L107: 0
A108: 200280 | B108: North Dakota | C108: Female | D108: Volleyball | E108: 1 | F108: 1 | G108: 131313 | H108: 0 | K108: 130384 | L108: 0
A109: 200332 | B109: North Dakota State | C109: Female | D109: Volleyball | E109: 1 | F109: 1 | G109: 120972 | H109: 0 | I109: 2 | J109: 2 | K109: 147999 | L109: 0
A110: 136172 | B110: North Florida | C110: Female | D110: Volleyball | E110: 1 | F110: 0.5 | G110: 65517 | H110: 0 | I110: 2 | J110: 2 | K110: 102615 | L110: 0
A111: 227216 | B111: North Texas | C111: Female | D111: Volleyball | E111: 1 | F111: 1 | G111: 127474 | H111: 0 | I111: 2 | J111: 2 | K111: 86785 | L111: 0
A112: 105330 | B112: Northern Arizona | C112: Female | D112: Volleyball | E112: 1 | F112: 1 | G112: 142805 | H112: 0 | I112: 2 | J112: 1.8 | K112: 96193 | L112: 0
A113: 127741 | B113: Northern Colorado | C113: Female | D113: Volleyball | E113: 1 | F113: 1 | G113: 155428 | H113: 0 | I113: 2 | J113: 2 | K113: 139478 | L113: 0
A114: 154095 | B114: Northern Iowa | C114: Female | D114: Volleyball | E114: 1 | F114: 1 | G114: 177379 | H114: 0 | I114: 2 | J114: 2 | K114: 151749 | L114: 0
A115: 160038 | B115: Northwestern State | C115: Female | D115: Volleyball | E115: 1 | F115: 1 | G115: 76310 | H115: 0 | I115: 1 | J115: 1 | K115: 50860 | L115: 0
A116: 171571 | B116: Oakland | C116: Female | D116: Volleyball | E116: 1 | F116: 1 | G116: 101960 | H116: 0 | I116: 1 | J116: 0.97 | K116: 59787 | L116: 0
A117: 204857 | B117: Ohio | C117: Female | D117: Volleyball | E117: 1 | F117: 1 | G117: 178223 | H117: 0 | I117: 2 | J117: 2 | K117: 135397 | L117: 0
A118: 204796 | B118: Ohio State | C118: Female | D118: Volleyball | E118: 1 | F118: 1 | G118: 384518 | H118: 0 | I118: 2 | J118: 2 | K118: 271661 | L118: 0
A119: 207500 | B119: Oklahoma | C119: Female | D119: Volleyball | E119: 1 | F119: 1 | G119: 274273 | H119: 0 | I119: 2 | J119: 2 | K119: 205540 | L119: 0
A120: 232982 | B120: Old Dominion | C120: Female | D120: Volleyball | E120: 1 | F120: 1 | G120: 145381 | H120: 0 | I120: 2 | J120: 2 | K120: 121770 | L120: 0
... A192: 206695 | B192: Youngstown State | C192: Female | D192: Volleyball | E192: 1 | F192: 1 | G192: 99319 | H192: 0 | I192: 2 | J192: 1 | K192: 57724 | L192: 0

Sheet 2022 (2)
A1: unitid | B1: University | C1: Gender | D1: Sport | E1: Number of Positions | F1: FTE | G1: Coaching Salaries | H1: Coaching Other Comp | I1: Number of Positions | J1: FTE | K1: Coaching Salaries | L1: Coaching Other Comp
A2: 200800 | B2: Akron | C2: Female | D2: Volleyball | E2: 1 | F2: 1 | G2: 105443 | H2: 0 | I2: 1 | J2: 1 | K2: 26876 | L2: 0
A3: 100751 | B3: Alabama | C3: Female | D3: Volleyball | E3: 1 | F3: 1 | G3: 455972 | H3: 0 | I3: 2 | J3: 2 | K3: 365141 | L3: 0
A4: 196060 | B4: Albany | C4: Female | D4: Volleyball | E4: 1 | F4: 1 | G4: 124545 | H4: 0 | I4: 2 | J4: 2 | K4: 162585 | L4: 0
A5: 197869 | B5: Appalachian State | C5: Female | D5: Volleyball | E5: 1 | F5: 1 | G5: 141080 | H5: 0 | I5: 2 | J5: 2 | K5: 143033 | L5: 0
A6: 104179 | B6: Arizona | C6: Female | D6: Volleyball | E6: 1 | F6: 1 | G6: 238342 | H6: 22200 | I6: 2 | J6: 2 | K6: 195155 | L6: 0
A7: 104151 | B7: Arizona State | C7: Female | D7: Volleyball | E7: 1 | F7: 1 | G7: 219406 | H7: 0 | I7: 2 | J7: 2 | K7: 208161 | L7: 0
A8: 106397 | B8: Arkansas | C8: Female | D8: Volleyball | E8: 1 | F8: 1 | G8: 247610 | H8: 0 | I8: 2 | J8: 2 | K8: 184356 | L8: 0
A9: 106245 | B9: Arkansas Little Rock | C9: Female | D9: Volleyball | E9: 1 | F9: 1 | G9: 86150 | H9: 9600 | I9: 2 | J9: 1.5 | K9: 39455 | L9: 0
A10: 106458 | B10: Arkansas State | C10: Female | D10: Volleyball | E10: 1 | F10: 1 | G10: 83426 | H10: 12612 | I10: 2 | J10: 1.17 | K10: 44154 | L10: 2780
A11: 100858 | B11: Auburn | C11: Female | D11: Volleyball | E11: 1 | F11: 1 | G11: 281285 | H11: 0 | I11: 2 | J11: 2 | K11: 183619 | L11: 0
A12: 219602 | B12: Austin Peay State | C12: Female | D12: Volleyball | E12: 1 | F12: 0.5 | G12: 118839 | H12: 0 | I12: 2 | J12: 1.5 | K12: 101035 | L12: 0
A13: 150136 | B13: Ball State | C13: Female | D13: Volleyball | E13: 1 | F13: 1 | G13: 156786 | H13: 0 | I13: 2 | J13: 2 | K13: 135528 | L13: 0
... A192: 206695 | B192: Youngstown State | C192: Female | D192: Volleyball | E192: 1 | F192: 1 | G192: 103281 | H192: 0 | I192: 2 | J192: 2 | K192: 97609 | L192: 0

Sheet 2023 (2)
A1: unitid | B1: University | C1: Gender | D1: Sport | E1: Number of Positions | F1: FTE | G1: Coaching Salaries | H1: Coaching Other Comp | I1: Number of Positions | J1: FTE | K1: Coaching Salaries | L1: Coaching Other Comp
A2: 200800 | B2: Akron | C2: Female | D2: Volleyball | E2: 1 | F2: 1 | G2: 128303 | H2: 0 | I2: 2 | J2: 2 | K2: 100581 | L2: 0
A3: 100751 | B3: Alabama | C3: Female | D3: Volleyball | E3: 1 | F3: 1 | G3: 284922 | H3: 0 | I3: 2 | J3: 2 | K3: 261596 | L3: 0
A4: 196060 | B4: Albany | C4: Female | D4: Volleyball | E4: 1 | F4: 1 | G4: 124825 | H4: 0 | I4: 2 | J4: 2 | K4: 166404 | L4: 0
A5: 197869 | B5: Appalachian State | C5: Female | D5: Volleyball | E5: 1 | F5: 1 | G5: 132500 | H5: 0 | I5: 2 | J5: 2 | K5: 147924 | L5: 0
A6: 104179 | B6: Arizona | C6: Female | D6: Volleyball | E6: 1 | F6: 1 | G6: 269428 | H6: 22200 | I6: 2 | J6: 2 | K6: 248402 | L6: 0
A7: 104151 | B7: Arizona State | C7: Female | D7: Volleyball | E7: 1 | F7: 1 | G7: 260927 | H7: 0 | I7: 2 | J7: 2 | K7: 227815 | L7: 0
A8: 106397 | B8: Arkansas | C8: Female | D8: Volleyball | E8: 1 | F8: 1 | G8: 292119 | H8: 0 | I8: 3 | J8: 2.5 | K8: 195888 | L8: 0
A9: 106245 | B9: Arkansas Little Rock | C9: Female | D9: Volleyball | E9: 1 | F9: 1 | G9: 85474 | H9: 9600 | I9: 1 | J9: 1 | K9: 41380 | L9: 0
A10: 106412 | B10: Arkansas Pine Bluff | C10: Female | D10: Volleyball | E10: 1 | F10: 1 | G10: 66711 | H10: 0 | I10: 0 | J10: 0 | K10: 0 | L10: 0
A11: 106458 | B11: Arkansas State | C11: Female | D11: Volleyball | E11: 1 | F11: 1 | G11: 101034 | H11: 14800 | I11: 2 | J11: 2 | K11: 101981 | L11: 3600
A12: 100858 | B12: Auburn | C12: Female | D12: Volleyball | E12: 1 | F12: 1 | G12: 343463 | H12: 0 | I12: 2 | J12: 2 | K12: 219100 | L12: 0
A13: 219602 | B13: Austin Peay State | C13: Female | D13: Volleyball | E13: 1 | F13: 0.5 | G13: 124858 | H13: 0 | I13: 2 | J13: 1.5 | K13: 80263 | L13: 0
... A192: 206695 | B192: Youngstown State | C192: Female | D192: Volleyball | E192: 1 | F192: 1 | G192: 105571 | H192: 0 | I192: 1 | J192: 1 | K192: 80202 | L192: 0
